Workbook

Sheet Dashboard
B1: VXI GLOBAL · CAIRO · REPAIR
B2: AICR Dashboard — 1-Day vs 7-Day, day over day
B3: 22 Sep – 06 Oct 2026 · 15 days · every number on this sheet is a live formula · see Day Picker for one-day detail and Heatmap for the calendar view
B5: 1-DAY AICR | F5: 7-DAY AICR | J5: GAP 1-DAY → 7-DAY | N5: LATE REPEATS (DAY 2-7) | R5: LATE SHARE
B6: ='Daily Data'!H20 -> 0.71111876 | F6: ='Daily Data'!L20 -> 0.59786492 | J6: ='Daily Data'!M20 -> 11.325384 | N6: ='Daily Data'!N20 -> 2631 | R6: ='Daily Data'!O20 -> 0.28163134
B8: repeats within 1 day | F8: repeats within 7 days | J8: hidden from a 1-day view | N8: share of 7-Day repeats → | R8: of all 7-Day repeats
B10: CONTACTS RECEIVED | F10: AVG RECEIVED / DAY | J10: BEST 1-DAY DAY | N10: WORST 1-DAY DAY | R10: WK2 VS WK1 (1-DAY)
B11: ='Daily Data'!D20 -> 23231 | F11: =ROUND('Daily Data'!D20/15,0) -> 1549 | J11: ='Daily Data'!C24 -> 0.73850032 | N11: ='Daily Data'!C25 -> 0.67523923 | R11: ='Weekly & Weekday'!F9 -> -2.7563003
B13: avg per day → | F13: 15 days | J13: =TEXT('Daily Data'!D24,"ddd dd mmm") -> Tue 22 Sep | N13: =TEXT('Daily Data'!D25,"ddd dd mmm") -> Thu 01 Oct | R13: ="7-Day: "&TEXT('Weekly & Weekday'!H9,"+0.00;-0.00")&" pp" -> 7-Day: -1.74 pp
B15: Status board — targets are inputs on the Targets & Notes sheet
B16: Measure | C16: Actual | D16: Target | E16: Gap (pp) | G16: Status | J16: Trend first→last (pp)
B17: 1-Day AICR | C17: ='Daily Data'!H20 -> 0.71111876 | D17: ='Targets & Notes'!C5 -> 0.75 | E17: =(C17-D17)*100 -> -3.8881236 | G17: =IF(E17>=0,"On / above target","Below target by "&TEXT(-E17,"0.00")&" pp") -> Below target by 3.89 pp | J17: ='Daily Data'!R20 -> -3.0947445
B18: 7-Day AICR | C18: ='Daily Data'!L20 -> 0.59786492 | D18: ='Targets & Notes'!C6 -> 0.65 | E18: =(C18-D18)*100 -> -5.2135078 | G18: =IF(E18>=0,"On / above target","Below target by "&TEXT(-E18,"0.00")&" pp") -> Below target by 5.21 pp | J18: ='Daily Data'!S20 -> -2.9515493
B20: Day strip — 1-Day and 7-Day AICR per day (darker teal = better; arrows = day-over-day)
B21: Date | C21: ='Daily Data'!A5 -> 46287 | D21: ='Daily Data'!A6 -> 46288 | E21: ='Daily Data'!A7 -> 46289 | F21: ='Daily Data'!A8 -> 46290 | G21: ='Daily Data'!A9 -> 46291 | H21: ='Daily Data'!A10 -> 46292 | I21: ='Daily Data'!A11 -> 46293 | J21: ='Daily Data'!A12 -> 46294 | K21: ='Daily Data'!A13 -> 46295 | L21: ='Daily Data'!A14 -> 46296 | M21: ='Daily Data'!A15 -> 46297 | N21: ='Daily Data'!A16 -> 46298 | O21: ='Daily Data'!A17 -> 46299 | P21: ='Daily Data'!A18 -> 46300 | Q21: ='Daily Data'!A19 -> 46301
B22: 1-Day | C22: ='Daily Data'!H5 -> 0.73850032 | D22: ='Daily Data'!H6 -> 0.70957514 | E22: ='Daily Data'!H7 -> 0.72667035 | F22: ='Daily Data'!H8 -> 0.71413043 | G22: ='Daily Data'!H9 -> 0.72503962 | H22: ='Daily Data'!H10 -> 0.72766885 | I22: ='Daily Data'!H11 -> 0.73558758 | J22: ='Daily Data'!H12 -> 0.70694259 | K22: ='Daily Data'!H13 -> 0.70813679 | L22: ='Daily Data'!H14 -> 0.67523923 | M22: ='Daily Data'!H15 -> 0.68989959 | N22: ='Daily Data'!H16 -> 0.71643036 | O22: ='Daily Data'!H17 -> 0.69126819 | P22: ='Daily Data'!H18 -> 0.69859018 | Q22: ='Daily Data'!H19 -> 0.70755287
B23: DoD | D23: ='Daily Data'!R6 -> -2.8925172 | E23: ='Daily Data'!R7 -> 1.7095205 | F23: ='Daily Data'!R8 -> -1.2539913 | G23: ='Daily Data'!R9 -> 1.0909185 | H23: ='Daily Data'!R10 -> 0.26292257 | I23: ='Daily Data'!R11 -> 0.79187378 | J23: ='Daily Data'!R12 -> -2.8644993 | K23: ='Daily Data'!R13 -> 0.11942023 | L23: ='Daily Data'!R14 -> -3.2897558 | M23: ='Daily Data'!R15 -> 1.4660352 | N23: ='Daily Data'!R16 -> 2.6530772 | O23: ='Daily Data'!R17 -> -2.5162167 | P23: ='Daily Data'!R18 -> 0.73219886 | Q23: ='Daily Data'!R19 -> 0.89626902
B24: 7-Day | C24: ='Daily Data'!L5 -> 0.63011972 | D24: ='Daily Data'!L6 -> 0.58211795 | E24: ='Daily Data'!L7 -> 0.61457758 | F24: ='Daily Data'!L8 -> 0.5875 | G24: ='Daily Data'!L9 -> 0.61568938 | H24: ='Daily Data'!L10 -> 0.59694989 | I24: ='Daily Data'!L11 -> 0.61585366 | J24: ='Daily Data'!L12 -> 0.60547397 | K24: ='Daily Data'!L13 -> 0.60318396 | L24: ='Daily Data'!L14 -> 0.57117225 | M24: ='Daily Data'!L15 -> 0.56940343 | N24: ='Daily Data'!L16 -> 0.59049208 | O24: ='Daily Data'!L17 -> 0.59043659 | P24: ='Daily Data'!L18 -> 0.59406903 | Q24: ='Daily Data'!L19 -> 0.60060423
B25: DoD | D25: ='Daily Data'!S6 -> -4.8001777 | E25: ='Daily Data'!S7 -> 3.2459636 | F25: ='Daily Data'!S8 -> -2.7077581 | G25: ='Daily Data'!S9 -> 2.8189382 | H25: ='Daily Data'!S10 -> -1.8739491 | I25: ='Daily Data'!S11 -> 1.8903767 | J25: ='Daily Data'!S12 -> -1.0379693 | K25: ='Daily Data'!S13 -> -0.2290003 | L25: ='Daily Data'!S14 -> -3.2011713 | M25: ='Daily Data'!S15 -> -0.17688229 | N25: ='Daily Data'!S16 -> 2.1088651 | O25: ='Daily Data'!S17 -> -0.0055486294 | P25: ='Daily Data'!S18 -> 0.36324421 | Q25: ='Daily Data'!S19 -> 0.6535197
B26: Received | C26: ='Daily Data'!D5 -> 1587 | D26: ='Daily Data'!D6 -> 1577 | E26: ='Daily Data'!D7 -> 1811 | F26: ='Daily Data'!D8 -> 1840 | G26: ='Daily Data'!D9 -> 1262 | H26: ='Daily Data'!D10 -> 918 | I26: ='Daily Data'!D11 -> 1804 | J26: ='Daily Data'!D12 -> 1498 | K26: ='Daily Data'!D13 -> 1696 | L26: ='Daily Data'!D14 -> 1672 | M26: ='Daily Data'!D15 -> 1693 | N26: ='Daily Data'!D16 -> 1199 | O26: ='Daily Data'!D17 -> 962 | P26: ='Daily Data'!D18 -> 2057 | Q26: ='Daily Data'!D19 -> 1655

Sheet Day Picker
B1: DAY PICKER — one day in detail
B2: Choose a date in the yellow cell (drop-down). Everything below recalculates for that day, the previous day and the period average.
B4: Selected date | C4: 46301 | F4: Row in Daily Data | G4: =MATCH($C$4,'Daily Data'!$A$5:$A$19,0) -> 15 | J4: Previous day | K4: =IF($G$4=1,"—",INDEX('Daily Data'!$A$5:$A$19,$G$4-1)) -> 46300
B6: 1-DAY AICR | F6: 7-DAY AICR | J6: GAP (PP) | N6: RANK (1-DAY) OF 15
B7: =INDEX('Daily Data'!$H$5:$H$19,$G$4) -> 0.70755287 | F7: =INDEX('Daily Data'!$L$5:$L$19,$G$4) -> 0.60060423 | J7: =INDEX('Daily Data'!$M$5:$M$19,$G$4) -> 10.694864 | N7: =RANK(INDEX('Daily Data'!$H$5:$H$19,$G$4),'Daily Data'!$H$5:$H$19) -> 10
B9: =IF($G$4=1,"first day",TEXT((INDEX('Daily Data'!$H$5:$H$19,$G$4)-IF($G$4=1,NA(),INDEX('Daily Data'!$H$5:$H$19,$G$4-1)))*100,"+0.00;-0.00")&" pp vs previous day") -> +0.90 pp vs previous day | F9: =IF($G$4=1,"first day",TEXT((INDEX('Daily Data'!$L$5:$L$19,$G$4)-IF($G$4=1,NA(),INDEX('Daily Data'!$L$5:$L$19,$G$4-1)))*100,"+0.00;-0.00")&" pp vs previous day") -> +0.65 pp vs previous day | J9: ="period avg "&TEXT('Daily Data'!M20,"0.00")&" pp" -> period avg 11.33 pp | N9: ="7-Day rank #"&RANK(INDEX('Daily Data'!$L$5:$L$19,$G$4),'Daily Data'!$L$5:$L$19) -> 7-Day rank #7
B11: CONTACTS RECEIVED | F11: REPEATS WITHIN 1 DAY | J11: REPEATS WITHIN 7 DAYS | N11: LATE REPEATS (DAY 2-7)
B12: =INDEX('Daily Data'!$D$5:$D$19,$G$4) -> 1655 | F12: =INDEX('Daily Data'!$E$5:$E$19,$G$4) -> 484 | J12: =INDEX('Daily Data'!$I$5:$I$19,$G$4) -> 661 | N12: =INDEX('Daily Data'!$N$5:$N$19,$G$4) -> 177
B14: =IF($G$4=1,"first day",TEXT(INDEX('Daily Data'!$D$5:$D$19,$G$4)-IF($G$4=1,NA(),INDEX('Daily Data'!$D$5:$D$19,$G$4-1)),"+#,##0;-#,##0")&" vs previous day") -> -402 vs previous day | F14: ="call "&INDEX('Daily Data'!$F$5:$F$19,$G$4)&" · chat "&INDEX('Daily Data'!$G$5:$G$19,$G$4) -> call 459 · chat 25 | J14: ="call "&INDEX('Daily Data'!$J$5:$J$19,$G$4)&" · chat "&INDEX('Daily Data'!$K$5:$K$19,$G$4) -> call 622 · chat 39 | N14: ="late share "&TEXT(INDEX('Daily Data'!$O$5:$O$19,$G$4),"0.0%") -> late share 26.8%
B16: Selected day vs previous day vs period average
B17: Measure | C17: Selected day | D17: Previous day | E17: Period avg | I17: Δ vs period avg (pp / contacts) | K17: Verdict
B18: 1-Day AICR | C18: =INDEX('Daily Data'!$H$5:$H$19,$G$4) -> 0.70755287 | D18: =IF($G$4=1,"—",IF($G$4=1,NA(),INDEX('Daily Data'!$H$5:$H$19,$G$4-1))) -> 0.69859018 | E18: ='Daily Data'!H20 -> 0.71111876 | F18: =IF($G$4=1,"—",(C18-D18)*100) -> 0.89626902 | I18: =(C18-E18)*100 -> -0.35658936 | K18: =IF(I18>=0,"▲ above period average","▼ below period average")&IF($G$4=1,""," · "&IF(F18>=0,"improved vs previous day","declined vs previous day")) -> ▼ below period average · improved vs previous day
B19: 7-Day AICR | C19: =INDEX('Daily Data'!$L$5:$L$19,$G$4) -> 0.60060423 | D19: =IF($G$4=1,"—",IF($G$4=1,NA(),INDEX('Daily Data'!$L$5:$L$19,$G$4-1))) -> 0.59406903 | E19: ='Daily Data'!L20 -> 0.59786492 | F19: =IF($G$4=1,"—",(C19-D19)*100) -> 0.6535197 | I19: =(C19-E19)*100 -> 0.27393077 | K19: =IF(I19>=0,"▲ above period average","▼ below period average")&IF($G$4=1,""," · "&IF(F19>=0,"improved vs previous day","declined vs previous day")) -> ▲ above period average · improved vs previous day
B20: Late share | C20: =INDEX('Daily Data'!$O$5:$O$19,$G$4) -> 0.2677761 | D20: =IF($G$4=1,"—",IF($G$4=1,NA(),INDEX('Daily Data'!$O$5:$O$19,$G$4-1))) -> 0.25748503 | E20: ='Daily Data'!O20 -> 0.28163134 | F20: =IF($G$4=1,"—",(C20-D20)*100) -> 1.0291067 | I20: =(C20-E20)*100 -> -1.3855246 | K20: =IF(I20<=0,"▲ better (lower) than period average","▼ worse (higher) than period average") -> ▲ better (lower) than period average
B21: Gap (pp) | C21: =INDEX('Daily Data'!$M$5:$M$19,$G$4) -> 10.694864 | D21: =IF($G$4=1,"—",IF($G$4=1,NA(),INDEX('Daily Data'!$M$5:$M$19,$G$4-1))) -> 10.452115 | E21: ='Daily Data'!M20 -> 11.325384 | F21: =IF($G$4=1,"—",(C21-D21)) -> 0.24274932 | I21: =(C21-E21) -> -0.63052014 | K21: =IF(I21<=0,"▲ better (lower) than period average","▼ worse (higher) than period average") -> ▲ better (lower) than period average
B22: Contacts received | C22: =INDEX('Daily Data'!$D$5:$D$19,$G$4) -> 1655 | D22: =IF($G$4=1,"—",IF($G$4=1,NA(),INDEX('Daily Data'!$D$5:$D$19,$G$4-1))) -> 2057 | E22: ='Daily Data'!D20/15 -> 1548.7333 | F22: =IF($G$4=1,"—",(C22-D22)) -> -402 | I22: =(C22-E22) -> 106.26667 | K22: =IF(I22>=0,"above period average","below period average") -> above period average
B23: Repeats within 1 day | C23: =INDEX('Daily Data'!$E$5:$E$19,$G$4) -> 484 | D23: =IF($G$4=1,"—",IF($G$4=1,NA(),INDEX('Daily Data'!$E$5:$E$19,$G$4-1))) -> 620 | E23: ='Daily Data'!E20 -> 6711 | F23: =IF($G$4=1,"—",(C23-D23)) -> -136 | I23: =(C23-E23) -> -6227 | K23: =IF(I23>=0,"above period average","below period average") -> below period average
B24: Repeats within 7 days | C24: =INDEX('Daily Data'!$I$5:$I$19,$G$4) -> 661 | D24: =IF($G$4=1,"—",IF($G$4=1,NA(),INDEX('Daily Data'!$I$5:$I$19,$G$4-1))) -> 835 | E24: ='Daily Data'!I20 -> 9342 | F24: =IF($G$4=1,"—",(C24-D24)) -> -174 | I24: =(C24-E24) -> -8681 | K24: =IF(I24>=0,"above period average","below period average") -> below period average
B26: Note: the drop-down lists the 15 dates in the data. Typing a date outside the period shows a not-available error.

Sheet Heatmap
B1: HEATMAP — calendar view and metric matrix
B2: Calendar grids: darker teal = higher AICR (better). Matrix: each column has its own scale; red = worse end, teal = better end.
B4: 1-Day AICR by calendar day | K4: 7-Day AICR by calendar day
B5: Week | C5: Mon | D5: Tue | E5: Wed | F5: Thu | G5: Fri | H5: Sat | I5: Sun | K5: Week | L5: Mon | M5: Tue | N5: Wed | O5: Thu | P5: Fri | Q5: Sat | R5: Sun
B6: w/c 21 Sep | C6: 46286 | D6: 46287 | E6: 46288 | F6: 46289 | G6: 46290 | H6: 46291 | I6: 46292 | K6: w/c 21 Sep | L6: 46286 | M6: 46287 | N6: 46288 | O6: 46289 | P6: 46290 | Q6: 46291 | R6: 46292
C7: =IFERROR(INDEX('Daily Data'!$H$5:$H$19,MATCH(C6,'Daily Data'!$A$5:$A$19,0)),"") | D7: =IFERROR(INDEX('Daily Data'!$H$5:$H$19,MATCH(D6,'Daily Data'!$A$5:$A$19,0)),"") -> 0.73850032 | E7: =IFERROR(INDEX('Daily Data'!$H$5:$H$19,MATCH(E6,'Daily Data'!$A$5:$A$19,0)),"") -> 0.70957514 | F7: =IFERROR(INDEX('Daily Data'!$H$5:$H$19,MATCH(F6,'Daily Data'!$A$5:$A$19,0)),"") -> 0.72667035 | G7: =IFERROR(INDEX('Daily Data'!$H$5:$H$19,MATCH(G6,'Daily Data'!$A$5:$A$19,0)),"") -> 0.71413043 | H7: =IFERROR(INDEX('Daily Data'!$H$5:$H$19,MATCH(H6,'Daily Data'!$A$5:$A$19,0)),"") -> 0.72503962 | I7: =IFERROR(INDEX('Daily Data'!$H$5:$H$19,MATCH(I6,'Daily Data'!$A$5:$A$19,0)),"") -> 0.72766885 | L7: =IFERROR(INDEX('Daily Data'!$L$5:$L$19,MATCH(L6,'Daily Data'!$A$5:$A$19,0)),"") | M7: =IFERROR(INDEX('Daily Data'!$L$5:$L$19,MATCH(M6,'Daily Data'!$A$5:$A$19,0)),"") -> 0.63011972 | N7: =IFERROR(INDEX('Daily Data'!$L$5:$L$19,MATCH(N6,'Daily Data'!$A$5:$A$19,0)),"") -> 0.58211795 | O7: =IFERROR(INDEX('Daily Data'!$L$5:$L$19,MATCH(O6,'Daily Data'!$A$5:$A$19,0)),"") -> 0.61457758 | P7: =IFERROR(INDEX('Daily Data'!$L$5:$L$19,MATCH(P6,'Daily Data'!$A$5:$A$19,0)),"") -> 0.5875 | Q7: =IFERROR(INDEX('Daily Data'!$L$5:$L$19,MATCH(Q6,'Daily Data'!$A$5:$A$19,0)),"") -> 0.61568938 | R7: =IFERROR(INDEX('Daily Data'!$L$5:$L$19,MATCH(R6,'Daily Data'!$A$5:$A$19,0)),"") -> 0.59694989
B8: w/c 28 Sep | C8: 46293 | D8: 46294 | E8: 46295 | F8: 46296 | G8: 46297 | H8: 46298 | I8: 46299 | K8: w/c 28 Sep | L8: 46293 | M8: 46294 | N8: 46295 | O8: 46296 | P8: 46297 | Q8: 46298 | R8: 46299
C9: =IFERROR(INDEX('Daily Data'!$H$5:$H$19,MATCH(C8,'Daily Data'!$A$5:$A$19,0)),"") -> 0.73558758 | D9: =IFERROR(INDEX('Daily Data'!$H$5:$H$19,MATCH(D8,'Daily Data'!$A$5:$A$19,0)),"") -> 0.70694259 | E9: =IFERROR(INDEX('Daily Data'!$H$5:$H$19,MATCH(E8,'Daily Data'!$A$5:$A$19,0)),"") -> 0.70813679 | F9: =IFERROR(INDEX('Daily Data'!$H$5:$H$19,MATCH(F8,'Daily Data'!$A$5:$A$19,0)),"") -> 0.67523923 | G9: =IFERROR(INDEX('Daily Data'!$H$5:$H$19,MATCH(G8,'Daily Data'!$A$5:$A$19,0)),"") -> 0.68989959 | H9: =IFERROR(INDEX('Daily Data'!$H$5:$H$19,MATCH(H8,'Daily Data'!$A$5:$A$19,0)),"") -> 0.71643036 | I9: =IFERROR(INDEX('Daily Data'!$H$5:$H$19,MATCH(I8,'Daily Data'!$A$5:$A$19,0)),"") -> 0.69126819 | L9: =IFERROR(INDEX('Daily Data'!$L$5:$L$19,MATCH(L8,'Daily Data'!$A$5:$A$19,0)),"") -> 0.61585366 | M9: =IFERROR(INDEX('Daily Data'!$L$5:$L$19,MATCH(M8,'Daily Data'!$A$5:$A$19,0)),"") -> 0.60547397 | N9: =IFERROR(INDEX('Daily Data'!$L$5:$L$19,MATCH(N8,'Daily Data'!$A$5:$A$19,0)),"") -> 0.60318396 | O9: =IFERROR(INDEX('Daily Data'!$L$5:$L$19,MATCH(O8,'Daily Data'!$A$5:$A$19,0)),"") -> 0.57117225 | P9: =IFERROR(INDEX('Daily Data'!$L$5:$L$19,MATCH(P8,'Daily Data'!$A$5:$A$19,0)),"") -> 0.56940343 | Q9: =IFERROR(INDEX('Daily Data'!$L$5:$L$19,MATCH(Q8,'Daily Data'!$A$5:$A$19,0)),"") -> 0.59049208 | R9: =IFERROR(INDEX('Daily Data'!$L$5:$L$19,MATCH(R8,'Daily Data'!$A$5:$A$19,0)),"") -> 0.59043659
B10: w/c 05 Oct | C10: 46300 | D10: 46301 | E10: 46302 | F10: 46303 | G10: 46304 | H10: 46305 | I10: 46306 | K10: w/c 05 Oct | L10: 46300 | M10: 46301 | N10: 46302 | O10: 46303 | P10: 46304 | Q10: 46305 | R10: 46306
C11: =IFERROR(INDEX('Daily Data'!$H$5:$H$19,MATCH(C10,'Daily Data'!$A$5:$A$19,0)),"") -> 0.69859018 | D11: =IFERROR(INDEX('Daily Data'!$H$5:$H$19,MATCH(D10,'Daily Data'!$A$5:$A$19,0)),"") -> 0.70755287 | E11: =IFERROR(INDEX('Daily Data'!$H$5:$H$19,MATCH(E10,'Daily Data'!$A$5:$A$19,0)),"") | F11: =IFERROR(INDEX('Daily Data'!$H$5:$H$19,MATCH(F10,'Daily Data'!$A$5:$A$19,0)),"") | G11: =IFERROR(INDEX('Daily Data'!$H$5:$H$19,MATCH(G10,'Daily Data'!$A$5:$A$19,0)),"") | H11: =IFERROR(INDEX('Daily Data'!$H$5:$H$19,MATCH(H10,'Daily Data'!$A$5:$A$19,0)),"") | I11: =IFERROR(INDEX('Daily Data'!$H$5:$H$19,MATCH(I10,'Daily Data'!$A$5:$A$19,0)),"") | L11: =IFERROR(INDEX('Daily Data'!$L$5:$L$19,MATCH(L10,'Daily Data'!$A$5:$A$19,0)),"") -> 0.59406903 | M11: =IFERROR(INDEX('Daily Data'!$L$5:$L$19,MATCH(M10,'Daily Data'!$A$5:$A$19,0)),"") -> 0.60060423 | N11: =IFERROR(INDEX('Daily Data'!$L$5:$L$19,MATCH(N10,'Daily Data'!$A$5:$A$19,0)),"") | O11: =IFERROR(INDEX('Daily Data'!$L$5:$L$19,MATCH(O10,'Daily Data'!$A$5:$A$19,0)),"") | P11: =IFERROR(INDEX('Daily Data'!$L$5:$L$19,MATCH(P10,'Daily Data'!$A$5:$A$19,0)),"") | Q11: =IFERROR(INDEX('Daily Data'!$L$5:$L$19,MATCH(Q10,'Daily Data'!$A$5:$A$19,0)),"") | R11: =IFERROR(INDEX('Daily Data'!$L$5:$L$19,MATCH(R10,'Daily Data'!$A$5:$A$19,0)),"")
B13: Metric matrix — every day, every measure (per-column colour scale)
B14: Date | C14: Received | D14: 1-Day AICR | E14: DoD 1-Day (pp) | F14: 7-Day AICR | G14: DoD 7-Day (pp) | H14: Gap (pp) | I14: Late repeats | J14: Late share | K14: 1-Day repeat rate | L14: 7-Day repeat rate | M14: Chat % of 7D repeats | N14: vs avg 1-Day (pp) | O14: vs avg 7-Day (pp) | P14: Week
B15: ='Daily Data'!A5 -> 46287 | C15: ='Daily Data'!D5 -> 1587 | D15: ='Daily Data'!H5 -> 0.73850032 | E15: — | F15: ='Daily Data'!L5 -> 0.63011972 | G15: — | H15: ='Daily Data'!M5 -> 10.838059 | I15: ='Daily Data'!N5 -> 172 | J15: ='Daily Data'!O5 -> 0.29301533 | K15: ='Daily Data'!P5 -> 0.26149968 | L15: ='Daily Data'!Q5 -> 0.36988028 | M15: ='Daily Data'!X5 -> 0.056218058 | N15: ='Daily Data'!Y5 -> 2.7381551 | O15: ='Daily Data'!Z5 -> 3.2254801 | P15: ='Daily Data'!C5 -> Wk1 (22-28 Sep)
B16: ='Daily Data'!A6 -> 46288 | C16: ='Daily Data'!D6 -> 1577 | D16: ='Daily Data'!H6 -> 0.70957514 | E16: ='Daily Data'!R6 -> -2.8925172 | F16: ='Daily Data'!L6 -> 0.58211795 | G16: ='Daily Data'!S6 -> -4.8001777 | H16: ='Daily Data'!M6 -> 12.74572 | I16: ='Daily Data'!N6 -> 201 | J16: ='Daily Data'!O6 -> 0.30500759 | K16: ='Daily Data'!P6 -> 0.29042486 | L16: ='Daily Data'!Q6 -> 0.41788205 | M16: ='Daily Data'!X6 -> 0.053110774 | N16: ='Daily Data'!Y6 -> -0.1543621 | O16: ='Daily Data'!Z6 -> -1.5746976 | P16: ='Daily Data'!C6 -> Wk1 (22-28 Sep)
B17: ='Daily Data'!A7 -> 46289 | C17: ='Daily Data'!D7 -> 1811 | D17: ='Daily Data'!H7 -> 0.72667035 | E17: ='Daily Data'!R7 -> 1.7095205 | F17: ='Daily Data'!L7 -> 0.61457758 | G17: ='Daily Data'!S7 -> 3.2459636 | H17: ='Daily Data'!M7 -> 11.209277 | I17: ='Daily Data'!N7 -> 203 | J17: ='Daily Data'!O7 -> 0.29083095 | K17: ='Daily Data'!P7 -> 0.27332965 | L17: ='Daily Data'!Q7 -> 0.38542242 | M17: ='Daily Data'!X7 -> 0.053008596 | N17: ='Daily Data'!Y7 -> 1.5551584 | O17: ='Daily Data'!Z7 -> 1.671266 | P17: ='Daily Data'!C7 -> Wk1 (22-28 Sep)
B18: ='Daily Data'!A8 -> 46290 | C18: ='Daily Data'!D8 -> 1840 | D18: ='Daily Data'!H8 -> 0.71413043 | E18: ='Daily Data'!R8 -> -1.2539913 | F18: ='Daily Data'!L8 -> 0.5875 | G18: ='Daily Data'!S8 -> -2.7077581 | H18: ='Daily Data'!M8 -> 12.663043 | I18: ='Daily Data'!N8 -> 233 | J18: ='Daily Data'!O8 -> 0.30698287 | K18: ='Daily Data'!P8 -> 0.28586957 | L18: ='Daily Data'!Q8 -> 0.4125 | M18: ='Daily Data'!X8 -> 0.036890646 | N18: ='Daily Data'!Y8 -> 0.30116711 | O18: ='Daily Data'!Z8 -> -1.0364922 | P18: ='Daily Data'!C8 -> Wk1 (22-28 Sep)
B19: ='Daily Data'!A9 -> 46291 | C19: ='Daily Data'!D9 -> 1262 | D19: ='Daily Data'!H9 -> 0.72503962 | E19: ='Daily Data'!R9 -> 1.0909185 | F19: ='Daily Data'!L9 -> 0.61568938 | G19: ='Daily Data'!S9 -> 2.8189382 | H19: ='Daily Data'!M9 -> 10.935024 | I19: ='Daily Data'!N9 -> 138 | J19: ='Daily Data'!O9 -> 0.28453608 | K19: ='Daily Data'!P9 -> 0.27496038 | L19: ='Daily Data'!Q9 -> 0.38431062 | M19: ='Daily Data'!X9 -> 0.063917526 | N19: ='Daily Data'!Y9 -> 1.3920856 | O19: ='Daily Data'!Z9 -> 1.782446 | P19: ='Daily Data'!C9 -> Wk1 (22-28 Sep)
B20: ='Daily Data'!A10 -> 46292 | C20: ='Daily Data'!D10 -> 918 | D20: ='Daily Data'!H10 -> 0.72766885 | E20: ='Daily Data'!R10 -> 0.26292257 | F20: ='Daily Data'!L10 -> 0.59694989 | G20: ='Daily Data'!S10 -> -1.8739491 | H20: ='Daily Data'!M10 -> 13.071895 | I20: ='Daily Data'!N10 -> 120 | J20: ='Daily Data'!O10 -> 0.32432432 | K20: ='Daily Data'!P10 -> 0.27233115 | L20: ='Daily Data'!Q10 -> 0.40305011 | M20: ='Daily Data'!X10 -> 0.059459459 | N20: ='Daily Data'!Y10 -> 1.6550082 | O20: ='Daily Data'!Z10 -> -0.09150308 | P20: ='Daily Data'!C10 -> Wk1 (22-28 Sep)
B21: ='Daily Data'!A11 -> 46293 | C21: ='Daily Data'!D11 -> 1804 | D21: ='Daily Data'!H11 -> 0.73558758 | E21: ='Daily Data'!R11 -> 0.79187378 | F21: ='Daily Data'!L11 -> 0.61585366 | G21: ='Daily Data'!S11 -> 1.8903767 | H21: ='Daily Data'!M11 -> 11.973392 | I21: ='Daily Data'!N11 -> 216 | J21: ='Daily Data'!O11 -> 0.31168831 | K21: ='Daily Data'!P11 -> 0.26441242 | L21: ='Daily Data'!Q11 -> 0.38414634 | M21: ='Daily Data'!X11 -> 0.056277056 | N21: ='Daily Data'!Y11 -> 2.4468819 | O21: ='Daily Data'!Z11 -> 1.7988737 | P21: ='Daily Data'!C11 -> Wk1 (22-28 Sep)
B22: ='Daily Data'!A12 -> 46294 | C22: ='Daily Data'!D12 -> 1498 | D22: ='Daily Data'!H12 -> 0.70694259 | E22: ='Daily Data'!R12 -> -2.8644993 | F22: ='Daily Data'!L12 -> 0.60547397 | G22: ='Daily Data'!S12 -> -1.0379693 | H22: ='Daily Data'!M12 -> 10.146862 | I22: ='Daily Data'!N12 -> 152 | J22: ='Daily Data'!O12 -> 0.2571912 | K22: ='Daily Data'!P12 -> 0.29305741 | L22: ='Daily Data'!Q12 -> 0.39452603 | M22: ='Daily Data'!X12 -> 0.054145516 | N22: ='Daily Data'!Y12 -> -0.41761736 | O22: ='Daily Data'!Z12 -> 0.76090434 | P22: ='Daily Data'!C12 -> Wk2 (29 Sep-5 Oct)
B23: ='Daily Data'!A13 -> 46295 | C23: ='Daily Data'!D13 -> 1696 | D23: ='Daily Data'!H13 -> 0.70813679 | E23: ='Daily Data'!R13 -> 0.11942023 | F23: ='Daily Data'!L13 -> 0.60318396 | G23: ='Daily Data'!S13 -> -0.2290003 | H23: ='Daily Data'!M13 -> 10.495283 | I23: ='Daily Data'!N13 -> 178 | J23: ='Daily Data'!O13 -> 0.26448737 | K23: ='Daily Data'!P13 -> 0.29186321 | L23: ='Daily Data'!Q13 -> 0.39681604 | M23: ='Daily Data'!X13 -> 0.0653789 | N23: ='Daily Data'!Y13 -> -0.29819713 | O23: ='Daily Data'!Z13 -> 0.53190404 | P23: ='Daily Data'!C13 -> Wk2 (29 Sep-5 Oct)
B24: ='Daily Data'!A14 -> 46296 | C24: ='Daily Data'!D14 -> 1672 | D24: ='Daily Data'!H14 -> 0.67523923 | E24: ='Daily Data'!R14 -> -3.2897558 | F24: ='Daily Data'!L14 -> 0.57117225 | G24: ='Daily Data'!S14 -> -3.2011713 | H24: ='Daily Data'!M14 -> 10.406699 | I24: ='Daily Data'!N14 -> 174 | J24: ='Daily Data'!O14 -> 0.24267782 | K24: ='Daily Data'!P14 -> 0.32476077 | L24: ='Daily Data'!Q14 -> 0.42882775 | M24: ='Daily Data'!X14 -> 0.051603905 | N24: ='Daily Data'!Y14 -> -3.5879529 | O24: ='Daily Data'!Z14 -> -2.6692673 | P24: ='Daily Data'!C14 -> Wk2 (29 Sep-5 Oct)
B25: ='Daily Data'!A15 -> 46297 | C25: ='Daily Data'!D15 -> 1693 | D25: ='Daily Data'!H15 -> 0.68989959 | E25: ='Daily Data'!R15 -> 1.4660352 | F25: ='Daily Data'!L15 -> 0.56940343 | G25: ='Daily Data'!S15 -> -0.17688229 | H25: ='Daily Data'!M15 -> 12.049616 | I25: ='Daily Data'!N15 -> 204 | J25: ='Daily Data'!O15 -> 0.27983539 | K25: ='Daily Data'!P15 -> 0.31010041 | L25: ='Daily Data'!Q15 -> 0.43059657 | M25: ='Daily Data'!X15 -> 0.075445816 | N25: ='Daily Data'!Y15 -> -2.1219177 | O25: ='Daily Data'!Z15 -> -2.8461496 | P25: ='Daily Data'!C15 -> Wk2 (29 Sep-5 Oct)
B26: ='Daily Data'!A16 -> 46298 | C26: ='Daily Data'!D16 -> 1199 | D26: ='Daily Data'!H16 -> 0.71643036 | E26: ='Daily Data'!R16 -> 2.6530772 | F26: ='Daily Data'!L16 -> 0.59049208 | G26: ='Daily Data'!S16 -> 2.1088651 | H26: ='Daily Data'!M16 -> 12.593828 | I26: ='Daily Data'!N16 -> 151 | J26: ='Daily Data'!O16 -> 0.30753564 | K26: ='Daily Data'!P16 -> 0.28356964 | L26: ='Daily Data'!Q16 -> 0.40950792 | M26: ='Daily Data'!X16 -> 0.061099796 | N26: ='Daily Data'!Y16 -> 0.53115949 | O26: ='Daily Data'!Z16 -> -0.73728451 | P26: ='Daily Data'!C16 -> Wk2 (29 Sep-5 Oct)
B27: ='Daily Data'!A17 -> 46299 | C27: ='Daily Data'!D17 -> 962 | D27: ='Daily Data'!H17 -> 0.69126819 | E27: ='Daily Data'!R17 -> -2.5162167 | F27: ='Daily Data'!L17 -> 0.59043659 | G27: ='Daily Data'!S17 -> -0.0055486294 | H27: ='Daily Data'!M17 -> 10.08316 | I27: ='Daily Data'!N17 -> 97 | J27: ='Daily Data'!O17 -> 0.24619289 | K27: ='Daily Data'!P17 -> 0.30873181 | L27: ='Daily Data'!Q17 -> 0.40956341 | M27: ='Daily Data'!X17 -> 0.063451777 | N27: ='Daily Data'!Y17 -> -1.9850572 | O27: ='Daily Data'!Z17 -> -0.74283314 | P27: ='Daily Data'!C17 -> Wk2 (29 Sep-5 Oct)
... B29: ='Daily Data'!A19 -> 46301 | C29: ='Daily Data'!D19 -> 1655 | D29: ='Daily Data'!H19 -> 0.70755287 | E29: ='Daily Data'!R19 -> 0.89626902 | F29: ='Daily Data'!L19 -> 0.60060423 | G29: ='Daily Data'!S19 -> 0.6535197 | H29: ='Daily Data'!M19 -> 10.694864 | I29: ='Daily Data'!N19 -> 177 | J29: ='Daily Data'!O19 -> 0.2677761 | K29: ='Daily Data'!P19 -> 0.29244713 | L29: ='Daily Data'!Q19 -> 0.39939577 | M29: ='Daily Data'!X19 -> 0.059001513 | N29: ='Daily Data'!Y19 -> -0.35658936 | O29: ='Daily Data'!Z19 -> 0.27393077 | P29: ='Daily Data'!C19 -> Wk3 (6 Oct, partial)

Sheet Summary
A1: AICR Performance Summary — 1-Day vs 7-Day Comparison
A2: VXI Global – Cairo · Repair · 22 Sep – 06 Oct 2026 (15 days) · all figures are live formulas on the Daily Data sheet
B4: Headline KPIs — period (volume-weighted)
B5: KPI | C5: Value | G5: KPI | H5: Value
B6: Contacts received | C6: ='Daily Data'!D20 -> 23231 | G6: Gap 1-Day vs 7-Day (pp) | H6: ='Daily Data'!M20 -> 11.325384
B7: Repeat contacts within 1 day | C7: ='Daily Data'!E20 -> 6711 | G7: Late repeats (surfaced day 2-7) | H7: ='Daily Data'!N20 -> 2631
B8: Repeat contacts within 7 days | C8: ='Daily Data'!I20 -> 9342 | G8: Late repeats as % of 7-Day repeats | H8: ='Daily Data'!O20 -> 0.28163134
B9: 1-Day AICR | C9: ='Daily Data'!H20 -> 0.71111876 | G9: 1-Day repeat rate | H9: ='Daily Data'!P20 -> 0.28888124
B10: 7-Day AICR | C10: ='Daily Data'!L20 -> 0.59786492 | G10: 7-Day repeat rate | H10: ='Daily Data'!Q20 -> 0.40213508
B12: Target check (edit targets on the Targets & Notes sheet)
B13: Measure | C13: Actual | D13: Target | E13: Gap to target (pp) | G13: Status
B14: 1-Day AICR | C14: ='Daily Data'!H20 -> 0.71111876 | D14: ='Targets & Notes'!C5 -> 0.75 | E14: =(C14-D14)*100 -> -3.8881236 | G14: =IF(E14>=0,"✔ On / above target","✖ Below target by "&TEXT(-E14,"0.00")&" pp") -> ✖ Below target by 3.89 pp
B15: 7-Day AICR | C15: ='Daily Data'!L20 -> 0.59786492 | D15: ='Targets & Notes'!C6 -> 0.65 | E15: =(C15-D15)*100 -> -5.2135078 | G15: =IF(E15>=0,"✔ On / above target","✖ Below target by "&TEXT(-E15,"0.00")&" pp") -> ✖ Below target by 5.21 pp
B17: Week-over-week
B18: Week | C18: Received | D18: 1-Day AICR | E18: 7-Day AICR | G18: Gap (pp) | H18: Late repeats | I18: Late share | J18: 1D vs Wk1 (pp)
B19: Wk1 (22-28 Sep) | C19: =SUMIFS('Daily Data'!$D$5:$D$19,'Daily Data'!$C$5:$C$19,B19) -> 10799 | D19: =1-SUMIFS('Daily Data'!$E$5:$E$19,'Daily Data'!$C$5:$C$19,B19)/C19 -> 0.72515974 | E19: =1-SUMIFS('Daily Data'!$I$5:$I$19,'Daily Data'!$C$5:$C$19,B19)/C19 -> 0.60635244 | G19: =(D19-E19)*100 -> 11.88073 | H19: =SUMIFS('Daily Data'!$N$5:$N$19,'Daily Data'!$C$5:$C$19,B19) -> 1283 | I19: =H19/SUMIFS('Daily Data'!$I$5:$I$19,'Daily Data'!$C$5:$C$19,B19) -> 0.30181134 | J19: =(D19-$D$19)*100 -> 0
B20: Wk2 (29 Sep-5 Oct) | C20: =SUMIFS('Daily Data'!$D$5:$D$19,'Daily Data'!$C$5:$C$19,B20) -> 10777 | D20: =1-SUMIFS('Daily Data'!$E$5:$E$19,'Daily Data'!$C$5:$C$19,B20)/C20 -> 0.69759673 | E20: =1-SUMIFS('Daily Data'!$I$5:$I$19,'Daily Data'!$C$5:$C$19,B20)/C20 -> 0.58893941 | G20: =(D20-E20)*100 -> 10.865733 | H20: =SUMIFS('Daily Data'!$N$5:$N$19,'Daily Data'!$C$5:$C$19,B20) -> 1171 | I20: =H20/SUMIFS('Daily Data'!$I$5:$I$19,'Daily Data'!$C$5:$C$19,B20) -> 0.26433409 | J20: =(D20-$D$19)*100 -> -2.7563003
B21: Wk3 (6 Oct, partial) | C21: =SUMIFS('Daily Data'!$D$5:$D$19,'Daily Data'!$C$5:$C$19,B21) -> 1655 | D21: =1-SUMIFS('Daily Data'!$E$5:$E$19,'Daily Data'!$C$5:$C$19,B21)/C21 -> 0.70755287 | E21: =1-SUMIFS('Daily Data'!$I$5:$I$19,'Daily Data'!$C$5:$C$19,B21)/C21 -> 0.60060423 | G21: =(D21-E21)*100 -> 10.694864 | H21: =SUMIFS('Daily Data'!$N$5:$N$19,'Daily Data'!$C$5:$C$19,B21) -> 177 | I21: =H21/SUMIFS('Daily Data'!$I$5:$I$19,'Daily Data'!$C$5:$C$19,B21) -> 0.2677761 | J21: =(D21-$D$19)*100 -> -1.7606867
B23: Best and worst days
B24: Measure | C24: Value | D24: Date | G24: Measure | H24: Value | I24: Date
B25: Best 1-Day AICR | C25: ='Daily Data'!C24 -> 0.73850032 | D25: ='Daily Data'!D24 -> 46287 | G25: Worst 1-Day AICR | H25: ='Daily Data'!C25 -> 0.67523923 | I25: ='Daily Data'!D25 -> 46296
B26: Best 7-Day AICR | C26: ='Daily Data'!C26 -> 0.63011972 | D26: ='Daily Data'!D26 -> 46287 | G26: Worst 7-Day AICR | H26: ='Daily Data'!C27 -> 0.56940343 | I26: ='Daily Data'!D27 -> 46297
B27: Min late share | C27: ='Daily Data'!C37 -> 0.24267782 | D27: ='Daily Data'!D37 -> 46296 | G27: Max late share | H27: ='Daily Data'!C38 -> 0.32432432 | I27: ='Daily Data'!D38 -> 46292
B29: Key insights (read with the charts; numbers quoted as of the data period)
B30: 1. The 7-Day AICR runs ~11.3 pp below the 1-Day AICR every single day (range 10.1–13.1 pp). Roughly 28% of all repeat contacts arrive on day 2–7, so the 1-Day view under-reports repeats by more than a quarter.
B31: 2. The two measures move together (correlation 0.82): a bad 1-Day day is almost always a bad 7-Day day. Use 1-Day AICR as the daily coaching signal and 7-Day AICR as the KPI you report.
B32: 3. Week 2 (29 Sep–5 Oct) deteriorated vs Week 1: 1-Day AICR fell 2.8 pp and 7-Day fell 1.8 pp. The dip is driven by 1–2 Oct (1-Day 67.5% / 69.0%; 7-Day 57.1% / 56.9%), the worst days of the period.
B33: 4. Volume is NOT the driver: correlation between contacts received and AICR is ~0 on both measures, and weekends (lower volume) perform the same as weekdays. Repeat contacts are a resolution-quality issue, not a workload issue.
B34: 5. Chat repeats arrive late far more often than call repeats: 46% of 7-Day chat repeats are not visible on day 1, vs 27% for calls. Chat follow-through (confirming the fix, next steps, ticket closure) is the clearest gap to coach.
B35: 6. 6 Oct partially recovered (1-Day 70.8%, 7-Day 60.1%) but remains below Week 1 levels. Day-of-week pattern is flat; focus coaching on agent-level first-contact resolution rather than scheduling.

Sheet Daily Data
A1: AICR Day-over-Day Breakdown — 1-Day vs 7-Day
A2: VXI Global – Cairo · Repair · 22 Sep 2026 – 06 Oct 2026 · Source: Overall_Performance_WB (1-Day xlsx, 7-Day csv)
A4: Date | B4: Weekday | C4: Week | D4: Contacts Received | E4: 1-Day Repeats | F4: 1-Day Call Repeats | G4: 1-Day Chat Repeats | H4: 1-Day AICR | I4: 7-Day Repeats | J4: 7-Day Call Repeats | K4: 7-Day Chat Repeats | L4: 7-Day AICR | M4: Gap 1D vs 7D (pp) | N4: Late Repeats (Day 2-7) | O4: Late Share of 7D Repeats | P4: 1-Day Repeat Rate | Q4: 7-Day Repeat Rate | R4: DoD Δ 1-Day AICR (pp) | S4: DoD Δ 7-Day AICR (pp) | T4: DoD Δ Received | U4: 3-Day Avg 1-Day AICR | V4: 3-Day Avg 7-Day AICR | W4: Chat % of 1D Repeats | X4: Chat % of 7D Repeats | Y4: 1D AICR vs Period Avg (pp) | Z4: 7D AICR vs Period Avg (pp)
A5: 46287 | B5: =TEXT(A5,"ddd") -> Tue | C5: =IF(A5<=DATE(2026,9,28),"Wk1 (22-28 Sep)",IF(A5<=DATE(2026,10,5),"Wk2 (29 Sep-5 Oct)","Wk3 (6 Oct, partial)")) -> Wk1 (22-28 Sep) | D5: 1587 | E5: 415 | F5: 404 | G5: 11 | H5: =IF(D5=0,0,1-E5/D5) -> 0.73850032 | I5: 587 | J5: 554 | K5: 33 | L5: =IF(D5=0,0,1-I5/D5) -> 0.63011972 | M5: =(H5-L5)*100 -> 10.838059 | N5: =I5-E5 -> 172 | O5: =IF(I5=0,0,N5/I5) -> 0.29301533 | P5: =IF(D5=0,0,E5/D5) -> 0.26149968 | Q5: =IF(D5=0,0,I5/D5) -> 0.36988028 | R5: — | S5: — | T5: — | U5: — | V5: — | W5: =IF(E5=0,0,G5/E5) -> 0.026506024 | X5: =IF(I5=0,0,K5/I5) -> 0.056218058 | Y5: =(H5-$H$20)*100 -> 2.7381551 | Z5: =(L5-$L$20)*100 -> 3.2254801
A6: 46288 | B6: =TEXT(A6,"ddd") -> Wed | C6: =IF(A6<=DATE(2026,9,28),"Wk1 (22-28 Sep)",IF(A6<=DATE(2026,10,5),"Wk2 (29 Sep-5 Oct)","Wk3 (6 Oct, partial)")) -> Wk1 (22-28 Sep) | D6: 1577 | E6: 458 | F6: 442 | G6: 16 | H6: =IF(D6=0,0,1-E6/D6) -> 0.70957514 | I6: 659 | J6: 624 | K6: 35 | L6: =IF(D6=0,0,1-I6/D6) -> 0.58211795 | M6: =(H6-L6)*100 -> 12.74572 | N6: =I6-E6 -> 201 | O6: =IF(I6=0,0,N6/I6) -> 0.30500759 | P6: =IF(D6=0,0,E6/D6) -> 0.29042486 | Q6: =IF(D6=0,0,I6/D6) -> 0.41788205 | R6: =(H6-H5)*100 -> -2.8925172 | S6: =(L6-L5)*100 -> -4.8001777 | T6: =D6-D5 -> -10 | U6: — | V6: — | W6: =IF(E6=0,0,G6/E6) -> 0.034934498 | X6: =IF(I6=0,0,K6/I6) -> 0.053110774 | Y6: =(H6-$H$20)*100 -> -0.1543621 | Z6: =(L6-$L$20)*100 -> -1.5746976
A7: 46289 | B7: =TEXT(A7,"ddd") -> Thu | C7: =IF(A7<=DATE(2026,9,28),"Wk1 (22-28 Sep)",IF(A7<=DATE(2026,10,5),"Wk2 (29 Sep-5 Oct)","Wk3 (6 Oct, partial)")) -> Wk1 (22-28 Sep) | D7: 1811 | E7: 495 | F7: 472 | G7: 23 | H7: =IF(D7=0,0,1-E7/D7) -> 0.72667035 | I7: 698 | J7: 661 | K7: 37 | L7: =IF(D7=0,0,1-I7/D7) -> 0.61457758 | M7: =(H7-L7)*100 -> 11.209277 | N7: =I7-E7 -> 203 | O7: =IF(I7=0,0,N7/I7) -> 0.29083095 | P7: =IF(D7=0,0,E7/D7) -> 0.27332965 | Q7: =IF(D7=0,0,I7/D7) -> 0.38542242 | R7: =(H7-H6)*100 -> 1.7095205 | S7: =(L7-L6)*100 -> 3.2459636 | T7: =D7-D6 -> 234 | U7: =1-SUM(E5:E7)/SUM(D5:D7) -> 0.72502513 | V7: =1-SUM(I5:I7)/SUM(D5:D7) -> 0.60924623 | W7: =IF(E7=0,0,G7/E7) -> 0.046464646 | X7: =IF(I7=0,0,K7/I7) -> 0.053008596 | Y7: =(H7-$H$20)*100 -> 1.5551584 | Z7: =(L7-$L$20)*100 -> 1.671266
A8: 46290 | B8: =TEXT(A8,"ddd") -> Fri | C8: =IF(A8<=DATE(2026,9,28),"Wk1 (22-28 Sep)",IF(A8<=DATE(2026,10,5),"Wk2 (29 Sep-5 Oct)","Wk3 (6 Oct, partial)")) -> Wk1 (22-28 Sep) | D8: 1840 | E8: 526 | F8: 514 | G8: 12 | H8: =IF(D8=0,0,1-E8/D8) -> 0.71413043 | I8: 759 | J8: 731 | K8: 28 | L8: =IF(D8=0,0,1-I8/D8) -> 0.5875 | M8: =(H8-L8)*100 -> 12.663043 | N8: =I8-E8 -> 233 | O8: =IF(I8=0,0,N8/I8) -> 0.30698287 | P8: =IF(D8=0,0,E8/D8) -> 0.28586957 | Q8: =IF(D8=0,0,I8/D8) -> 0.4125 | R8: =(H8-H7)*100 -> -1.2539913 | S8: =(L8-L7)*100 -> -2.7077581 | T8: =D8-D7 -> 29 | U8: =1-SUM(E6:E8)/SUM(D6:D8) -> 0.71710023 | V8: =1-SUM(I6:I8)/SUM(D6:D8) -> 0.59525631 | W8: =IF(E8=0,0,G8/E8) -> 0.022813688 | X8: =IF(I8=0,0,K8/I8) -> 0.036890646 | Y8: =(H8-$H$20)*100 -> 0.30116711 | Z8: =(L8-$L$20)*100 -> -1.0364922
A9: 46291 | B9: =TEXT(A9,"ddd") -> Sat | C9: =IF(A9<=DATE(2026,9,28),"Wk1 (22-28 Sep)",IF(A9<=DATE(2026,10,5),"Wk2 (29 Sep-5 Oct)","Wk3 (6 Oct, partial)")) -> Wk1 (22-28 Sep) | D9: 1262 | E9: 347 | F9: 327 | G9: 20 | H9: =IF(D9=0,0,1-E9/D9) -> 0.72503962 | I9: 485 | J9: 454 | K9: 31 | L9: =IF(D9=0,0,1-I9/D9) -> 0.61568938 | M9: =(H9-L9)*100 -> 10.935024 | N9: =I9-E9 -> 138 | O9: =IF(I9=0,0,N9/I9) -> 0.28453608 | P9: =IF(D9=0,0,E9/D9) -> 0.27496038 | Q9: =IF(D9=0,0,I9/D9) -> 0.38431062 | R9: =(H9-H8)*100 -> 1.0909185 | S9: =(L9-L8)*100 -> 2.8189382 | T9: =D9-D8 -> -578 | U9: =1-SUM(E7:E9)/SUM(D7:D9) -> 0.72155506 | V9: =1-SUM(I7:I9)/SUM(D7:D9) -> 0.60472217 | W9: =IF(E9=0,0,G9/E9) -> 0.057636888 | X9: =IF(I9=0,0,K9/I9) -> 0.063917526 | Y9: =(H9-$H$20)*100 -> 1.3920856 | Z9: =(L9-$L$20)*100 -> 1.782446
A10: 46292 | B10: =TEXT(A10,"ddd") -> Sun | C10: =IF(A10<=DATE(2026,9,28),"Wk1 (22-28 Sep)",IF(A10<=DATE(2026,10,5),"Wk2 (29 Sep-5 Oct)","Wk3 (6 Oct, partial)")) -> Wk1 (22-28 Sep) | D10: 918 | E10: 250 | F10: 241 | G10: 9 | H10: =IF(D10=0,0,1-E10/D10) -> 0.72766885 | I10: 370 | J10: 348 | K10: 22 | L10: =IF(D10=0,0,1-I10/D10) -> 0.59694989 | M10: =(H10-L10)*100 -> 13.071895 | N10: =I10-E10 -> 120 | O10: =IF(I10=0,0,N10/I10) -> 0.32432432 | P10: =IF(D10=0,0,E10/D10) -> 0.27233115 | Q10: =IF(D10=0,0,I10/D10) -> 0.40305011 | R10: =(H10-H9)*100 -> 0.26292257 | S10: =(L10-L9)*100 -> -1.8739491 | T10: =D10-D9 -> -344 | U10: =1-SUM(E8:E10)/SUM(D8:D10) -> 0.72064677 | V10: =1-SUM(I8:I10)/SUM(D8:D10) -> 0.59850746 | W10: =IF(E10=0,0,G10/E10) -> 0.036 | X10: =IF(I10=0,0,K10/I10) -> 0.059459459 | Y10: =(H10-$H$20)*100 -> 1.6550082 | Z10: =(L10-$L$20)*100 -> -0.09150308
A11: 46293 | B11: =TEXT(A11,"ddd") -> Mon | C11: =IF(A11<=DATE(2026,9,28),"Wk1 (22-28 Sep)",IF(A11<=DATE(2026,10,5),"Wk2 (29 Sep-5 Oct)","Wk3 (6 Oct, partial)")) -> Wk1 (22-28 Sep) | D11: 1804 | E11: 477 | F11: 457 | G11: 20 | H11: =IF(D11=0,0,1-E11/D11) -> 0.73558758 | I11: 693 | J11: 654 | K11: 39 | L11: =IF(D11=0,0,1-I11/D11) -> 0.61585366 | M11: =(H11-L11)*100 -> 11.973392 | N11: =I11-E11 -> 216 | O11: =IF(I11=0,0,N11/I11) -> 0.31168831 | P11: =IF(D11=0,0,E11/D11) -> 0.26441242 | Q11: =IF(D11=0,0,I11/D11) -> 0.38414634 | R11: =(H11-H10)*100 -> 0.79187378 | S11: =(L11-L10)*100 -> 1.8903767 | T11: =D11-D10 -> 886 | U11: =1-SUM(E9:E11)/SUM(D9:D11) -> 0.73042169 | V11: =1-SUM(I9:I11)/SUM(D9:D11) -> 0.61144578 | W11: =IF(E11=0,0,G11/E11) -> 0.041928721 | X11: =IF(I11=0,0,K11/I11) -> 0.056277056 | Y11: =(H11-$H$20)*100 -> 2.4468819 | Z11: =(L11-$L$20)*100 -> 1.7988737
A12: 46294 | B12: =TEXT(A12,"ddd") -> Tue | C12: =IF(A12<=DATE(2026,9,28),"Wk1 (22-28 Sep)",IF(A12<=DATE(2026,10,5),"Wk2 (29 Sep-5 Oct)","Wk3 (6 Oct, partial)")) -> Wk2 (29 Sep-5 Oct) | D12: 1498 | E12: 439 | F12: 421 | G12: 18 | H12: =IF(D12=0,0,1-E12/D12) -> 0.70694259 | I12: 591 | J12: 559 | K12: 32 | L12: =IF(D12=0,0,1-I12/D12) -> 0.60547397 | M12: =(H12-L12)*100 -> 10.146862 | N12: =I12-E12 -> 152 | O12: =IF(I12=0,0,N12/I12) -> 0.2571912 | P12: =IF(D12=0,0,E12/D12) -> 0.29305741 | Q12: =IF(D12=0,0,I12/D12) -> 0.39452603 | R12: =(H12-H11)*100 -> -2.8644993 | S12: =(L12-L11)*100 -> -1.0379693 | T12: =D12-D11 -> -306 | U12: =1-SUM(E10:E12)/SUM(D10:D12) -> 0.72369668 | V12: =1-SUM(I10:I12)/SUM(D10:D12) -> 0.60805687 | W12: =IF(E12=0,0,G12/E12) -> 0.041002278 | X12: =IF(I12=0,0,K12/I12) -> 0.054145516 | Y12: =(H12-$H$20)*100 -> -0.41761736 | Z12: =(L12-$L$20)*100 -> 0.76090434
A13: 46295 | B13: =TEXT(A13,"ddd") -> Wed | C13: =IF(A13<=DATE(2026,9,28),"Wk1 (22-28 Sep)",IF(A13<=DATE(2026,10,5),"Wk2 (29 Sep-5 Oct)","Wk3 (6 Oct, partial)")) -> Wk2 (29 Sep-5 Oct) | D13: 1696 | E13: 495 | F13: 467 | G13: 28 | H13: =IF(D13=0,0,1-E13/D13) -> 0.70813679 | I13: 673 | J13: 629 | K13: 44 | L13: =IF(D13=0,0,1-I13/D13) -> 0.60318396 | M13: =(H13-L13)*100 -> 10.495283 | N13: =I13-E13 -> 178 | O13: =IF(I13=0,0,N13/I13) -> 0.26448737 | P13: =IF(D13=0,0,E13/D13) -> 0.29186321 | Q13: =IF(D13=0,0,I13/D13) -> 0.39681604 | R13: =(H13-H12)*100 -> 0.11942023 | S13: =(L13-L12)*100 -> -0.2290003 | T13: =D13-D12 -> 198 | U13: =1-SUM(E11:E13)/SUM(D11:D13) -> 0.71768707 | V13: =1-SUM(I11:I13)/SUM(D11:D13) -> 0.60844338 | W13: =IF(E13=0,0,G13/E13) -> 0.056565657 | X13: =IF(I13=0,0,K13/I13) -> 0.0653789 | Y13: =(H13-$H$20)*100 -> -0.29819713 | Z13: =(L13-$L$20)*100 -> 0.53190404
A14: 46296 | B14: =TEXT(A14,"ddd") -> Thu | C14: =IF(A14<=DATE(2026,9,28),"Wk1 (22-28 Sep)",IF(A14<=DATE(2026,10,5),"Wk2 (29 Sep-5 Oct)","Wk3 (6 Oct, partial)")) -> Wk2 (29 Sep-5 Oct) | D14: 1672 | E14: 543 | F14: 523 | G14: 20 | H14: =IF(D14=0,0,1-E14/D14) -> 0.67523923 | I14: 717 | J14: 680 | K14: 37 | L14: =IF(D14=0,0,1-I14/D14) -> 0.57117225 | M14: =(H14-L14)*100 -> 10.406699 | N14: =I14-E14 -> 174 | O14: =IF(I14=0,0,N14/I14) -> 0.24267782 | P14: =IF(D14=0,0,E14/D14) -> 0.32476077 | Q14: =IF(D14=0,0,I14/D14) -> 0.42882775 | R14: =(H14-H13)*100 -> -3.2897558 | S14: =(L14-L13)*100 -> -3.2011713 | T14: =D14-D13 -> -24 | U14: =1-SUM(E12:E14)/SUM(D12:D14) -> 0.69646527 | V14: =1-SUM(I12:I14)/SUM(D12:D14) -> 0.59288944 | W14: =IF(E14=0,0,G14/E14) -> 0.036832413 | X14: =IF(I14=0,0,K14/I14) -> 0.051603905 | Y14: =(H14-$H$20)*100 -> -3.5879529 | Z14: =(L14-$L$20)*100 -> -2.6692673
A15: 46297 | B15: =TEXT(A15,"ddd") -> Fri | C15: =IF(A15<=DATE(2026,9,28),"Wk1 (22-28 Sep)",IF(A15<=DATE(2026,10,5),"Wk2 (29 Sep-5 Oct)","Wk3 (6 Oct, partial)")) -> Wk2 (29 Sep-5 Oct) | D15: 1693 | E15: 525 | F15: 497 | G15: 28 | H15: =IF(D15=0,0,1-E15/D15) -> 0.68989959 | I15: 729 | J15: 674 | K15: 55 | L15: =IF(D15=0,0,1-I15/D15) -> 0.56940343 | M15: =(H15-L15)*100 -> 12.049616 | N15: =I15-E15 -> 204 | O15: =IF(I15=0,0,N15/I15) -> 0.27983539 | P15: =IF(D15=0,0,E15/D15) -> 0.31010041 | Q15: =IF(D15=0,0,I15/D15) -> 0.43059657 | R15: =(H15-H14)*100 -> 1.4660352 | S15: =(L15-L14)*100 -> -0.17688229 | T15: =D15-D14 -> 21 | U15: =1-SUM(E13:E15)/SUM(D13:D15) -> 0.69116775 | V15: =1-SUM(I13:I15)/SUM(D13:D15) -> 0.58130804 | W15: =IF(E15=0,0,G15/E15) -> 0.053333333 | X15: =IF(I15=0,0,K15/I15) -> 0.075445816 | Y15: =(H15-$H$20)*100 -> -2.1219177 | Z15: =(L15-$L$20)*100 -> -2.8461496
A16: 46298 | B16: =TEXT(A16,"ddd") -> Sat | C16: =IF(A16<=DATE(2026,9,28),"Wk1 (22-28 Sep)",IF(A16<=DATE(2026,10,5),"Wk2 (29 Sep-5 Oct)","Wk3 (6 Oct, partial)")) -> Wk2 (29 Sep-5 Oct) | D16: 1199 | E16: 340 | F16: 327 | G16: 13 | H16: =IF(D16=0,0,1-E16/D16) -> 0.71643036 | I16: 491 | J16: 461 | K16: 30 | L16: =IF(D16=0,0,1-I16/D16) -> 0.59049208 | M16: =(H16-L16)*100 -> 12.593828 | N16: =I16-E16 -> 151 | O16: =IF(I16=0,0,N16/I16) -> 0.30753564 | P16: =IF(D16=0,0,E16/D16) -> 0.28356964 | Q16: =IF(D16=0,0,I16/D16) -> 0.40950792 | R16: =(H16-H15)*100 -> 2.6530772 | S16: =(L16-L15)*100 -> 2.1088651 | T16: =D16-D15 -> -494 | U16: =1-SUM(E14:E16)/SUM(D14:D16) -> 0.69149869 | V16: =1-SUM(I14:I16)/SUM(D14:D16) -> 0.57559159 | W16: =IF(E16=0,0,G16/E16) -> 0.038235294 | X16: =IF(I16=0,0,K16/I16) -> 0.061099796 | Y16: =(H16-$H$20)*100 -> 0.53115949 | Z16: =(L16-$L$20)*100 -> -0.73728451
A17: 46299 | B17: =TEXT(A17,"ddd") -> Sun | C17: =IF(A17<=DATE(2026,9,28),"Wk1 (22-28 Sep)",IF(A17<=DATE(2026,10,5),"Wk2 (29 Sep-5 Oct)","Wk3 (6 Oct, partial)")) -> Wk2 (29 Sep-5 Oct) | D17: 962 | E17: 297 | F17: 278 | G17: 19 | H17: =IF(D17=0,0,1-E17/D17) -> 0.69126819 | I17: 394 | J17: 369 | K17: 25 | L17: =IF(D17=0,0,1-I17/D17) -> 0.59043659 | M17: =(H17-L17)*100 -> 10.08316 | N17: =I17-E17 -> 97 | O17: =IF(I17=0,0,N17/I17) -> 0.24619289 | P17: =IF(D17=0,0,E17/D17) -> 0.30873181 | Q17: =IF(D17=0,0,I17/D17) -> 0.40956341 | R17: =(H17-H16)*100 -> -2.5162167 | S17: =(L17-L16)*100 -> -0.0055486294 | T17: =D17-D16 -> -237 | U17: =1-SUM(E15:E17)/SUM(D15:D17) -> 0.69849507 | V17: =1-SUM(I15:I17)/SUM(D15:D17) -> 0.58121432 | W17: =IF(E17=0,0,G17/E17) -> 0.063973064 | X17: =IF(I17=0,0,K17/I17) -> 0.063451777 | Y17: =(H17-$H$20)*100 -> -1.9850572 | Z17: =(L17-$L$20)*100 -> -0.74283314
A18: 46300 | B18: =TEXT(A18,"ddd") -> Mon | C18: =IF(A18<=DATE(2026,9,28),"Wk1 (22-28 Sep)",IF(A18<=DATE(2026,10,5),"Wk2 (29 Sep-5 Oct)","Wk3 (6 Oct, partial)")) -> Wk2 (29 Sep-5 Oct) | D18: 2057 | E18: 620 | F18: 587 | G18: 33 | H18: =IF(D18=0,0,1-E18/D18) -> 0.69859018 | I18: 835 | J18: 780 | K18: 55 | L18: =IF(D18=0,0,1-I18/D18) -> 0.59406903 | M18: =(H18-L18)*100 -> 10.452115 | N18: =I18-E18 -> 215 | O18: =IF(I18=0,0,N18/I18) -> 0.25748503 | P18: =IF(D18=0,0,E18/D18) -> 0.30140982 | Q18: =IF(D18=0,0,I18/D18) -> 0.40593097 | R18: =(H18-H17)*100 -> 0.73219886 | S18: =(L18-L17)*100 -> 0.36324421 | T18: =D18-D17 -> 1095 | U18: =1-SUM(E16:E18)/SUM(D16:D18) -> 0.70199147 | V18: =1-SUM(I16:I18)/SUM(D16:D18) -> 0.5922238 | W18: =IF(E18=0,0,G18/E18) -> 0.053225806 | X18: =IF(I18=0,0,K18/I18) -> 0.065868263 | Y18: =(H18-$H$20)*100 -> -1.2528584 | Z18: =(L18-$L$20)*100 -> -0.37958893
A19: 46301 | B19: =TEXT(A19,"ddd") -> Tue | C19: =IF(A19<=DATE(2026,9,28),"Wk1 (22-28 Sep)",IF(A19<=DATE(2026,10,5),"Wk2 (29 Sep-5 Oct)","Wk3 (6 Oct, partial)")) -> Wk3 (6 Oct, partial) | D19: 1655 | E19: 484 | F19: 459 | G19: 25 | H19: =IF(D19=0,0,1-E19/D19) -> 0.70755287 | I19: 661 | J19: 622 | K19: 39 | L19: =IF(D19=0,0,1-I19/D19) -> 0.60060423 | M19: =(H19-L19)*100 -> 10.694864 | N19: =I19-E19 -> 177 | O19: =IF(I19=0,0,N19/I19) -> 0.2677761 | P19: =IF(D19=0,0,E19/D19) -> 0.29244713 | Q19: =IF(D19=0,0,I19/D19) -> 0.39939577 | R19: =(H19-H18)*100 -> 0.89626902 | S19: =(L19-L18)*100 -> 0.6535197 | T19: =D19-D18 -> -402 | U19: =1-SUM(E17:E19)/SUM(D17:D19) -> 0.70025674 | V19: =1-SUM(I17:I19)/SUM(D17:D19) -> 0.59563543 | W19: =IF(E19=0,0,G19/E19) -> 0.051652893 | X19: =IF(I19=0,0,K19/I19) -> 0.059001513 | Y19: =(H19-$H$20)*100 -> -0.35658936 | Z19: =(L19-$L$20)*100 -> 0.27393077
A20: Period Total / Avg | D20: =SUM(D5:D19) -> 23231 | E20: =SUM(E5:E19) -> 6711 | F20: =SUM(F5:F19) -> 6416 | G20: =SUM(G5:G19) -> 295 | H20: =1-E20/D20 -> 0.71111876 | I20: =SUM(I5:I19) -> 9342 | J20: =SUM(J5:J19) -> 8800 | K20: =SUM(K5:K19) -> 542 | L20: =1-I20/D20 -> 0.59786492 | M20: =(H20-L20)*100 -> 11.325384 | N20: =SUM(N5:N19) -> 2631 | O20: =N20/I20 -> 0.28163134 | P20: =E20/D20 -> 0.28888124 | Q20: =I20/D20 -> 0.40213508 | R20: =(H19-H5)*100 -> -3.0947445 | S20: =(L19-L5)*100 -> -2.9515493 | T20: =D19-D5 -> 68 | U20: =AVERAGE(H5:H19) -> 0.71141547 | V20: =AVERAGE(L5:L19) -> 0.59784291 | W20: =G20/E20 -> 0.043957681 | X20: =K20/I20 -> 0.058017555
A22: Period statistics (formulas)
A23: Statistic | C23: Date
A24: Best 1-Day AICR | C24: =MAX(H5:H19) -> 0.73850032 | D24: =INDEX(A5:A19,MATCH(MAX(H5:H19),H5:H19,0)) -> 46287
A25: Worst 1-Day AICR | C25: =MIN(H5:H19) -> 0.67523923 | D25: =INDEX(A5:A19,MATCH(MIN(H5:H19),H5:H19,0)) -> 46296
A26: Best 7-Day AICR | C26: =MAX(L5:L19) -> 0.63011972 | D26: =INDEX(A5:A19,MATCH(MAX(L5:L19),L5:L19,0)) -> 46287
A27: Worst 7-Day AICR | C27: =MIN(L5:L19) -> 0.56940343 | D27: =INDEX(A5:A19,MATCH(MIN(L5:L19),L5:L19,0)) -> 46297
A28: Range 1-Day AICR (pp) | C28: =(MAX(H5:H19)-MIN(H5:H19))*100 -> 6.3261081
A29: Range 7-Day AICR (pp) | C29: =(MAX(L5:L19)-MIN(L5:L19))*100 -> 6.0716297
A30: Std-dev 1-Day AICR (pp) | C30: =STDEV(H5:H19)*100 -> 1.7776425
A31: Std-dev 7-Day AICR (pp) | C31: =STDEV(L5:L19)*100 -> 1.7023968
A32: Correlation 1-Day vs 7-Day AICR | C32: =CORREL(H5:H19,L5:L19) -> 0.81891269
A33: Correlation Received vs 1-Day AICR | C33: =CORREL(D5:D19,H5:H19) -> -0.084683634
A34: Correlation Received vs 7-Day AICR | C34: =CORREL(D5:D19,L5:L19) -> 0.0065588347
A35: Days 1-Day AICR below period avg | C35: =COUNTIF(H5:H19,"<"&H20) -> 8
A36: Days 7-Day AICR below period avg | C36: =COUNTIF(L5:L19,"<"&L20) -> 8
A37: Min late share | C37: =MIN(O5:O19) -> 0.24267782 | D37: =INDEX(A5:A19,MATCH(MIN(O5:O19),O5:O19,0)) -> 46296
A38: Max late share | C38: =MAX(O5:O19) -> 0.32432432 | D38: =INDEX(A5:A19,MATCH(MAX(O5:O19),O5:O19,0)) -> 46292

Sheet DoD Comparison
A1: Day-over-Day Comparison — 1-Day and 7-Day AICR
A2: Each day vs the previous day and vs the period average. Flags: ▲ above average, ▼ below average. Trend compares both measures DoD.
A4: Date | B4: Weekday | C4: Received | D4: Δ Received | E4: 1-Day AICR | F4: DoD Δ (pp) | G4: vs Period Avg (pp) | H4: 1-Day flag | I4: 7-Day AICR | J4: DoD Δ (pp) | K4: vs Period Avg (pp) | L4: 7-Day flag | M4: Gap (pp) | N4: Late repeats | O4: Late share | P4: Day trend
A5: ='Daily Data'!A5 -> 46287 | B5: ='Daily Data'!B5 -> Tue | C5: ='Daily Data'!D5 -> 1587 | D5: ='Daily Data'!T5 -> — | E5: ='Daily Data'!H5 -> 0.73850032 | F5: ='Daily Data'!R5 -> — | G5: ='Daily Data'!Y5 -> 2.7381551 | H5: =IF(G5>=0,"▲ above avg","▼ below avg") -> ▲ above avg | I5: ='Daily Data'!L5 -> 0.63011972 | J5: ='Daily Data'!S5 -> — | K5: ='Daily Data'!Z5 -> 3.2254801 | L5: =IF(K5>=0,"▲ above avg","▼ below avg") -> ▲ above avg | M5: ='Daily Data'!M5 -> 10.838059 | N5: ='Daily Data'!N5 -> 172 | O5: ='Daily Data'!O5 -> 0.29301533 | P5: Baseline day
A6: ='Daily Data'!A6 -> 46288 | B6: ='Daily Data'!B6 -> Wed | C6: ='Daily Data'!D6 -> 1577 | D6: ='Daily Data'!T6 -> -10 | E6: ='Daily Data'!H6 -> 0.70957514 | F6: ='Daily Data'!R6 -> -2.8925172 | G6: ='Daily Data'!Y6 -> -0.1543621 | H6: =IF(G6>=0,"▲ above avg","▼ below avg") -> ▼ below avg | I6: ='Daily Data'!L6 -> 0.58211795 | J6: ='Daily Data'!S6 -> -4.8001777 | K6: ='Daily Data'!Z6 -> -1.5746976 | L6: =IF(K6>=0,"▲ above avg","▼ below avg") -> ▼ below avg | M6: ='Daily Data'!M6 -> 12.74572 | N6: ='Daily Data'!N6 -> 201 | O6: ='Daily Data'!O6 -> 0.30500759 | P6: =IF(AND(F6>0,J6>0),"Improved on both",IF(AND(F6<0,J6<0),"Declined on both",IF(F6>0,"1-Day up, 7-Day down","1-Day down, 7-Day up"))) -> Declined on both
A7: ='Daily Data'!A7 -> 46289 | B7: ='Daily Data'!B7 -> Thu | C7: ='Daily Data'!D7 -> 1811 | D7: ='Daily Data'!T7 -> 234 | E7: ='Daily Data'!H7 -> 0.72667035 | F7: ='Daily Data'!R7 -> 1.7095205 | G7: ='Daily Data'!Y7 -> 1.5551584 | H7: =IF(G7>=0,"▲ above avg","▼ below avg") -> ▲ above avg | I7: ='Daily Data'!L7 -> 0.61457758 | J7: ='Daily Data'!S7 -> 3.2459636 | K7: ='Daily Data'!Z7 -> 1.671266 | L7: =IF(K7>=0,"▲ above avg","▼ below avg") -> ▲ above avg | M7: ='Daily Data'!M7 -> 11.209277 | N7: ='Daily Data'!N7 -> 203 | O7: ='Daily Data'!O7 -> 0.29083095 | P7: =IF(AND(F7>0,J7>0),"Improved on both",IF(AND(F7<0,J7<0),"Declined on both",IF(F7>0,"1-Day up, 7-Day down","1-Day down, 7-Day up"))) -> Improved on both
A8: ='Daily Data'!A8 -> 46290 | B8: ='Daily Data'!B8 -> Fri | C8: ='Daily Data'!D8 -> 1840 | D8: ='Daily Data'!T8 -> 29 | E8: ='Daily Data'!H8 -> 0.71413043 | F8: ='Daily Data'!R8 -> -1.2539913 | G8: ='Daily Data'!Y8 -> 0.30116711 | H8: =IF(G8>=0,"▲ above avg","▼ below avg") -> ▲ above avg | I8: ='Daily Data'!L8 -> 0.5875 | J8: ='Daily Data'!S8 -> -2.7077581 | K8: ='Daily Data'!Z8 -> -1.0364922 | L8: =IF(K8>=0,"▲ above avg","▼ below avg") -> ▼ below avg | M8: ='Daily Data'!M8 -> 12.663043 | N8: ='Daily Data'!N8 -> 233 | O8: ='Daily Data'!O8 -> 0.30698287 | P8: =IF(AND(F8>0,J8>0),"Improved on both",IF(AND(F8<0,J8<0),"Declined on both",IF(F8>0,"1-Day up, 7-Day down","1-Day down, 7-Day up"))) -> Declined on both
A9: ='Daily Data'!A9 -> 46291 | B9: ='Daily Data'!B9 -> Sat | C9: ='Daily Data'!D9 -> 1262 | D9: ='Daily Data'!T9 -> -578 | E9: ='Daily Data'!H9 -> 0.72503962 | F9: ='Daily Data'!R9 -> 1.0909185 | G9: ='Daily Data'!Y9 -> 1.3920856 | H9: =IF(G9>=0,"▲ above avg","▼ below avg") -> ▲ above avg | I9: ='Daily Data'!L9 -> 0.61568938 | J9: ='Daily Data'!S9 -> 2.8189382 | K9: ='Daily Data'!Z9 -> 1.782446 | L9: =IF(K9>=0,"▲ above avg","▼ below avg") -> ▲ above avg | M9: ='Daily Data'!M9 -> 10.935024 | N9: ='Daily Data'!N9 -> 138 | O9: ='Daily Data'!O9 -> 0.28453608 | P9: =IF(AND(F9>0,J9>0),"Improved on both",IF(AND(F9<0,J9<0),"Declined on both",IF(F9>0,"1-Day up, 7-Day down","1-Day down, 7-Day up"))) -> Improved on both
A10: ='Daily Data'!A10 -> 46292 | B10: ='Daily Data'!B10 -> Sun | C10: ='Daily Data'!D10 -> 918 | D10: ='Daily Data'!T10 -> -344 | E10: ='Daily Data'!H10 -> 0.72766885 | F10: ='Daily Data'!R10 -> 0.26292257 | G10: ='Daily Data'!Y10 -> 1.6550082 | H10: =IF(G10>=0,"▲ above avg","▼ below avg") -> ▲ above avg | I10: ='Daily Data'!L10 -> 0.59694989 | J10: ='Daily Data'!S10 -> -1.8739491 | K10: ='Daily Data'!Z10 -> -0.09150308 | L10: =IF(K10>=0,"▲ above avg","▼ below avg") -> ▼ below avg | M10: ='Daily Data'!M10 -> 13.071895 | N10: ='Daily Data'!N10 -> 120 | O10: ='Daily Data'!O10 -> 0.32432432 | P10: =IF(AND(F10>0,J10>0),"Improved on both",IF(AND(F10<0,J10<0),"Declined on both",IF(F10>0,"1-Day up, 7-Day down","1-Day down, 7-Day up"))) -> 1-Day up, 7-Day down
A11: ='Daily Data'!A11 -> 46293 | B11: ='Daily Data'!B11 -> Mon | C11: ='Daily Data'!D11 -> 1804 | D11: ='Daily Data'!T11 -> 886 | E11: ='Daily Data'!H11 -> 0.73558758 | F11: ='Daily Data'!R11 -> 0.79187378 | G11: ='Daily Data'!Y11 -> 2.4468819 | H11: =IF(G11>=0,"▲ above avg","▼ below avg") -> ▲ above avg | I11: ='Daily Data'!L11 -> 0.61585366 | J11: ='Daily Data'!S11 -> 1.8903767 | K11: ='Daily Data'!Z11 -> 1.7988737 | L11: =IF(K11>=0,"▲ above avg","▼ below avg") -> ▲ above avg | M11: ='Daily Data'!M11 -> 11.973392 | N11: ='Daily Data'!N11 -> 216 | O11: ='Daily Data'!O11 -> 0.31168831 | P11: =IF(AND(F11>0,J11>0),"Improved on both",IF(AND(F11<0,J11<0),"Declined on both",IF(F11>0,"1-Day up, 7-Day down","1-Day down, 7-Day up"))) -> Improved on both
A12: ='Daily Data'!A12 -> 46294 | B12: ='Daily Data'!B12 -> Tue | C12: ='Daily Data'!D12 -> 1498 | D12: ='Daily Data'!T12 -> -306 | E12: ='Daily Data'!H12 -> 0.70694259 | F12: ='Daily Data'!R12 -> -2.8644993 | G12: ='Daily Data'!Y12 -> -0.41761736 | H12: =IF(G12>=0,"▲ above avg","▼ below avg") -> ▼ below avg | I12: ='Daily Data'!L12 -> 0.60547397 | J12: ='Daily Data'!S12 -> -1.0379693 | K12: ='Daily Data'!Z12 -> 0.76090434 | L12: =IF(K12>=0,"▲ above avg","▼ below avg") -> ▲ above avg | M12: ='Daily Data'!M12 -> 10.146862 | N12: ='Daily Data'!N12 -> 152 | O12: ='Daily Data'!O12 -> 0.2571912 | P12: =IF(AND(F12>0,J12>0),"Improved on both",IF(AND(F12<0,J12<0),"Declined on both",IF(F12>0,"1-Day up, 7-Day down","1-Day down, 7-Day up"))) -> Declined on both
A13: ='Daily Data'!A13 -> 46295 | B13: ='Daily Data'!B13 -> Wed | C13: ='Daily Data'!D13 -> 1696 | D13: ='Daily Data'!T13 -> 198 | E13: ='Daily Data'!H13 -> 0.70813679 | F13: ='Daily Data'!R13 -> 0.11942023 | G13: ='Daily Data'!Y13 -> -0.29819713 | H13: =IF(G13>=0,"▲ above avg","▼ below avg") -> ▼ below avg | I13: ='Daily Data'!L13 -> 0.60318396 | J13: ='Daily Data'!S13 -> -0.2290003 | K13: ='Daily Data'!Z13 -> 0.53190404 | L13: =IF(K13>=0,"▲ above avg","▼ below avg") -> ▲ above avg | M13: ='Daily Data'!M13 -> 10.495283 | N13: ='Daily Data'!N13 -> 178 | O13: ='Daily Data'!O13 -> 0.26448737 | P13: =IF(AND(F13>0,J13>0),"Improved on both",IF(AND(F13<0,J13<0),"Declined on both",IF(F13>0,"1-Day up, 7-Day down","1-Day down, 7-Day up"))) -> 1-Day up, 7-Day down
A14: ='Daily Data'!A14 -> 46296 | B14: ='Daily Data'!B14 -> Thu | C14: ='Daily Data'!D14 -> 1672 | D14: ='Daily Data'!T14 -> -24 | E14: ='Daily Data'!H14 -> 0.67523923 | F14: ='Daily Data'!R14 -> -3.2897558 | G14: ='Daily Data'!Y14 -> -3.5879529 | H14: =IF(G14>=0,"▲ above avg","▼ below avg") -> ▼ below avg | I14: ='Daily Data'!L14 -> 0.57117225 | J14: ='Daily Data'!S14 -> -3.2011713 | K14: ='Daily Data'!Z14 -> -2.6692673 | L14: =IF(K14>=0,"▲ above avg","▼ below avg") -> ▼ below avg | M14: ='Daily Data'!M14 -> 10.406699 | N14: ='Daily Data'!N14 -> 174 | O14: ='Daily Data'!O14 -> 0.24267782 | P14: =IF(AND(F14>0,J14>0),"Improved on both",IF(AND(F14<0,J14<0),"Declined on both",IF(F14>0,"1-Day up, 7-Day down","1-Day down, 7-Day up"))) -> Declined on both
A15: ='Daily Data'!A15 -> 46297 | B15: ='Daily Data'!B15 -> Fri | C15: ='Daily Data'!D15 -> 1693 | D15: ='Daily Data'!T15 -> 21 | E15: ='Daily Data'!H15 -> 0.68989959 | F15: ='Daily Data'!R15 -> 1.4660352 | G15: ='Daily Data'!Y15 -> -2.1219177 | H15: =IF(G15>=0,"▲ above avg","▼ below avg") -> ▼ below avg | I15: ='Daily Data'!L15 -> 0.56940343 | J15: ='Daily Data'!S15 -> -0.17688229 | K15: ='Daily Data'!Z15 -> -2.8461496 | L15: =IF(K15>=0,"▲ above avg","▼ below avg") -> ▼ below avg | M15: ='Daily Data'!M15 -> 12.049616 | N15: ='Daily Data'!N15 -> 204 | O15: ='Daily Data'!O15 -> 0.27983539 | P15: =IF(AND(F15>0,J15>0),"Improved on both",IF(AND(F15<0,J15<0),"Declined on both",IF(F15>0,"1-Day up, 7-Day down","1-Day down, 7-Day up"))) -> 1-Day up, 7-Day down
A16: ='Daily Data'!A16 -> 46298 | B16: ='Daily Data'!B16 -> Sat | C16: ='Daily Data'!D16 -> 1199 | D16: ='Daily Data'!T16 -> -494 | E16: ='Daily Data'!H16 -> 0.71643036 | F16: ='Daily Data'!R16 -> 2.6530772 | G16: ='Daily Data'!Y16 -> 0.53115949 | H16: =IF(G16>=0,"▲ above avg","▼ below avg") -> ▲ above avg | I16: ='Daily Data'!L16 -> 0.59049208 | J16: ='Daily Data'!S16 -> 2.1088651 | K16: ='Daily Data'!Z16 -> -0.73728451 | L16: =IF(K16>=0,"▲ above avg","▼ below avg") -> ▼ below avg | M16: ='Daily Data'!M16 -> 12.593828 | N16: ='Daily Data'!N16 -> 151 | O16: ='Daily Data'!O16 -> 0.30753564 | P16: =IF(AND(F16>0,J16>0),"Improved on both",IF(AND(F16<0,J16<0),"Declined on both",IF(F16>0,"1-Day up, 7-Day down","1-Day down, 7-Day up"))) -> Improved on both
A17: ='Daily Data'!A17 -> 46299 | B17: ='Daily Data'!B17 -> Sun | C17: ='Daily Data'!D17 -> 962 | D17: ='Daily Data'!T17 -> -237 | E17: ='Daily Data'!H17 -> 0.69126819 | F17: ='Daily Data'!R17 -> -2.5162167 | G17: ='Daily Data'!Y17 -> -1.9850572 | H17: =IF(G17>=0,"▲ above avg","▼ below avg") -> ▼ below avg | I17: ='Daily Data'!L17 -> 0.59043659 | J17: ='Daily Data'!S17 -> -0.0055486294 | K17: ='Daily Data'!Z17 -> -0.74283314 | L17: =IF(K17>=0,"▲ above avg","▼ below avg") -> ▼ below avg | M17: ='Daily Data'!M17 -> 10.08316 | N17: ='Daily Data'!N17 -> 97 | O17: ='Daily Data'!O17 -> 0.24619289 | P17: =IF(AND(F17>0,J17>0),"Improved on both",IF(AND(F17<0,J17<0),"Declined on both",IF(F17>0,"1-Day up, 7-Day down","1-Day down, 7-Day up"))) -> Declined on both
... A19: ='Daily Data'!A19 -> 46301 | B19: ='Daily Data'!B19 -> Tue | C19: ='Daily Data'!D19 -> 1655 | D19: ='Daily Data'!T19 -> -402 | E19: ='Daily Data'!H19 -> 0.70755287 | F19: ='Daily Data'!R19 -> 0.89626902 | G19: ='Daily Data'!Y19 -> -0.35658936 | H19: =IF(G19>=0,"▲ above avg","▼ below avg") -> ▼ below avg | I19: ='Daily Data'!L19 -> 0.60060423 | J19: ='Daily Data'!S19 -> 0.6535197 | K19: ='Daily Data'!Z19 -> 0.27393077 | L19: =IF(K19>=0,"▲ above avg","▼ below avg") -> ▲ above avg | M19: ='Daily Data'!M19 -> 10.694864 | N19: ='Daily Data'!N19 -> 177 | O19: ='Daily Data'!O19 -> 0.2677761 | P19: =IF(AND(F19>0,J19>0),"Improved on both",IF(AND(F19<0,J19<0),"Declined on both",IF(F19>0,"1-Day up, 7-Day down","1-Day down, 7-Day up"))) -> Improved on both
A20: Period | C20: ='Daily Data'!D20 -> 23231 | E20: ='Daily Data'!H20 -> 0.71111876 | I20: ='Daily Data'!L20 -> 0.59786492 | M20: ='Daily Data'!M20 -> 11.325384 | N20: ='Daily Data'!N20 -> 2631 | O20: ='Daily Data'!O20 -> 0.28163134 | P20: =COUNTIF(P6:P19,"Declined on both")&" days declined on both" -> 5 days declined on both

Sheet Channel Split
A1: Repeat Contacts by Channel — Call vs Chat
A2: Late share = repeats that appear only in the 7-Day window as a share of that channel's 7-Day repeats. Chat volume is not in the source, so chat repeat rate cannot be computed; chat per 1,000 total contacts is shown instead.
A4: Date | B4: Weekday | C4: Received | D4: 1D Call Repeats | E4: 7D Call Repeats | F4: Late Call Repeats | G4: Call late share | H4: 1D Chat Repeats | I4: 7D Chat Repeats | J4: Late Chat Repeats | K4: Chat late share | L4: Chat % of 1D repeats | M4: Chat % of 7D repeats | N4: Call repeat rate (7D) | O4: Chat repeats per 1,000 contacts (7D)
A5: ='Daily Data'!A5 -> 46287 | B5: ='Daily Data'!B5 -> Tue | C5: ='Daily Data'!D5 -> 1587 | D5: ='Daily Data'!F5 -> 404 | E5: ='Daily Data'!J5 -> 554 | F5: =E5-D5 -> 150 | G5: =IF(E5=0,0,F5/E5) -> 0.27075812 | H5: ='Daily Data'!G5 -> 11 | I5: ='Daily Data'!K5 -> 33 | J5: =I5-H5 -> 22 | K5: =IF(I5=0,0,J5/I5) -> 0.66666667 | L5: ='Daily Data'!W5 -> 0.026506024 | M5: ='Daily Data'!X5 -> 0.056218058 | N5: =IF(C5=0,0,E5/C5) -> 0.34908633 | O5: =IF(C5=0,0,I5/C5*1000) -> 20.793951
A6: ='Daily Data'!A6 -> 46288 | B6: ='Daily Data'!B6 -> Wed | C6: ='Daily Data'!D6 -> 1577 | D6: ='Daily Data'!F6 -> 442 | E6: ='Daily Data'!J6 -> 624 | F6: =E6-D6 -> 182 | G6: =IF(E6=0,0,F6/E6) -> 0.29166667 | H6: ='Daily Data'!G6 -> 16 | I6: ='Daily Data'!K6 -> 35 | J6: =I6-H6 -> 19 | K6: =IF(I6=0,0,J6/I6) -> 0.54285714 | L6: ='Daily Data'!W6 -> 0.034934498 | M6: ='Daily Data'!X6 -> 0.053110774 | N6: =IF(C6=0,0,E6/C6) -> 0.39568802 | O6: =IF(C6=0,0,I6/C6*1000) -> 22.194039
A7: ='Daily Data'!A7 -> 46289 | B7: ='Daily Data'!B7 -> Thu | C7: ='Daily Data'!D7 -> 1811 | D7: ='Daily Data'!F7 -> 472 | E7: ='Daily Data'!J7 -> 661 | F7: =E7-D7 -> 189 | G7: =IF(E7=0,0,F7/E7) -> 0.28593041 | H7: ='Daily Data'!G7 -> 23 | I7: ='Daily Data'!K7 -> 37 | J7: =I7-H7 -> 14 | K7: =IF(I7=0,0,J7/I7) -> 0.37837838 | L7: ='Daily Data'!W7 -> 0.046464646 | M7: ='Daily Data'!X7 -> 0.053008596 | N7: =IF(C7=0,0,E7/C7) -> 0.36499172 | O7: =IF(C7=0,0,I7/C7*1000) -> 20.430701
A8: ='Daily Data'!A8 -> 46290 | B8: ='Daily Data'!B8 -> Fri | C8: ='Daily Data'!D8 -> 1840 | D8: ='Daily Data'!F8 -> 514 | E8: ='Daily Data'!J8 -> 731 | F8: =E8-D8 -> 217 | G8: =IF(E8=0,0,F8/E8) -> 0.29685363 | H8: ='Daily Data'!G8 -> 12 | I8: ='Daily Data'!K8 -> 28 | J8: =I8-H8 -> 16 | K8: =IF(I8=0,0,J8/I8) -> 0.57142857 | L8: ='Daily Data'!W8 -> 0.022813688 | M8: ='Daily Data'!X8 -> 0.036890646 | N8: =IF(C8=0,0,E8/C8) -> 0.39728261 | O8: =IF(C8=0,0,I8/C8*1000) -> 15.217391
A9: ='Daily Data'!A9 -> 46291 | B9: ='Daily Data'!B9 -> Sat | C9: ='Daily Data'!D9 -> 1262 | D9: ='Daily Data'!F9 -> 327 | E9: ='Daily Data'!J9 -> 454 | F9: =E9-D9 -> 127 | G9: =IF(E9=0,0,F9/E9) -> 0.27973568 | H9: ='Daily Data'!G9 -> 20 | I9: ='Daily Data'!K9 -> 31 | J9: =I9-H9 -> 11 | K9: =IF(I9=0,0,J9/I9) -> 0.35483871 | L9: ='Daily Data'!W9 -> 0.057636888 | M9: ='Daily Data'!X9 -> 0.063917526 | N9: =IF(C9=0,0,E9/C9) -> 0.35974643 | O9: =IF(C9=0,0,I9/C9*1000) -> 24.564184
A10: ='Daily Data'!A10 -> 46292 | B10: ='Daily Data'!B10 -> Sun | C10: ='Daily Data'!D10 -> 918 | D10: ='Daily Data'!F10 -> 241 | E10: ='Daily Data'!J10 -> 348 | F10: =E10-D10 -> 107 | G10: =IF(E10=0,0,F10/E10) -> 0.30747126 | H10: ='Daily Data'!G10 -> 9 | I10: ='Daily Data'!K10 -> 22 | J10: =I10-H10 -> 13 | K10: =IF(I10=0,0,J10/I10) -> 0.59090909 | L10: ='Daily Data'!W10 -> 0.036 | M10: ='Daily Data'!X10 -> 0.059459459 | N10: =IF(C10=0,0,E10/C10) -> 0.37908497 | O10: =IF(C10=0,0,I10/C10*1000) -> 23.965142
