Workbook

Sheet Executive Summary
A1: NPS Scrubbing — Executive Summary
A2: VXI · Comcast · Scrub data 01-Apr → 07-Oct-2026 · 2,283 scrubs · 12 scrubbers
A5: Total Scrubs | C5: Agent Opp % | E5: Comcast % | G5: No Audio % | I5: Rows w/ Dup Survey ID | K5: Today (07-Oct) | M5: DoD Δ Volume
A6: =COUNTA(Data!$D$2:$D$2284) -> 2283 | C6: =COUNTIFS(Data!$H$2:$H$2284,"Agent Opportunity")/COUNTA(Data!$D$2:$D$2284) -> 0.63863338 | E6: =COUNTIFS(Data!$H$2:$H$2284,"Comcast Process/Tools")/COUNTA(Data!$D$2:$D$2284) -> 0.17564608 | G6: =COUNTIFS(Data!$H$2:$H$2284,"No Audio Found on I3")/COUNTA(Data!$D$2:$D$2284) -> 0.081909768 | I6: =COUNTIFS(Data!$L$2:$L$2284,"Y") -> 260 | K6: =COUNTIFS(Data!$B$2:$B$2284,DATE(2026,10,7)) -> 110 | M6: ='Day over Day'!K6 -> 26
A8: Key Insights — Account
A9: 1. VOLUME SPIKE: 07-Oct (110) and 06-Oct (84) are the two highest scrub days on record (prior peak 78 on 24-Aug) — backlog clearing; check whether quality held.
A10: 2. AGENT OPPORTUNITY = 64% of all detractors. Oct MTD is 56% vs 68% in Sep: 06-Oct dipped to 46% AO (Comcast 31%), 07-Oct recovered to 65% (+18 pts DoD).
A11: 3. "CALL HANDLING" is 41% of Agent Opp (596) — too generic to coach. Split it into specific behaviours; Communication/Soft Skills (24%) is #2, Knowledge Gap #3.
A12: 4. CALIBRATION GAP: scrubbers range from 21% AO (Anas) to 78% AO (Eslam). Same survey type, different verdicts → affects agent QA/NPS fairness.
A13: 5. DATA QUALITY: 260 rows share a Survey ID (133 extra copies); 36 surveys carry CONFLICTING RCAs; 36 rows with invalid BPID (numbers/typos); 81 blank Survey Dates; 6 Survey Dates in the future.
A14: 6. NO AUDIO = 8% (187 scrubs) — scrub effort with zero insight. Escalate I3 recording gaps to WFM/IT.
A15: 7. REPEAT DETRACTORS: bp-hawad742 (43 AO) and bp-gghane435 (42 AO) lead — top 10 BPIDs = 19% of all Agent Opp. Coaching focus for team leaders.
A16: 8. COMCAST drivers: Technician complaints (112) and Dissatisfied with service (158) — non-controllable but shareable with client as VOC.
A18: Key Insights — Omar Mansour (29 scrubs)
A19: • RCA mix skews non-controllable: Agent Opp 38% vs 64% account; Comcast 34% vs 18%. One Comcast-tagged call (ID 2120) shows agent misinformation → likely Agent Opp.
A20: • Accuracy: 4 of 29 rows (14%) are a test row ("11") or duplicates — one duplicate survey has two different RCAs.
... A32: Insight text written from the data at build time (07-Oct-2026); KPI tiles and all tables are live formulas on the Data tab.

Sheet Omar Mansour Review
A1: Scrubber Review — Omar Mansour
A2: Submitted as "Omar Ali Mohamed" · Omar.Mansour@vxi.com · 29 scrubs (29-Sep → 07-Oct-2026)
A5: Omar vs Account — KPIs
A6: KPI | B6: Omar | C6: Account | D6: Gap | E6: Read
A7: Total scrubs | B7: =COUNTIFS(Data!$D$2:$D$2284,"Omar.Mansour@vxi.com") -> 29 | C7: =COUNTA(Data!$D$2:$D$2284) -> 2283 | E7: Low volume — joined late Sep; 27 of 29 on 6–7 Oct
A8: Agent Opportunity % | B8: =COUNTIFS(Data!$D$2:$D$2284,"Omar.Mansour@vxi.com",Data!$H$2:$H$2284,"Agent Opportunity")/B7 -> 0.37931034 | C8: =COUNTIFS(Data!$H$2:$H$2284,"Agent Opportunity")/C7 -> 0.63863338 | D8: =(B8-C8)*100 -> -25.932303 | E8: Lowest AO% after Anas — leans to non-controllable
A9: Comcast Process/Tools % | B9: =COUNTIFS(Data!$D$2:$D$2284,"Omar.Mansour@vxi.com",Data!$H$2:$H$2284,"Comcast Process/Tools")/B7 -> 0.34482759 | C9: =COUNTIFS(Data!$H$2:$H$2284,"Comcast Process/Tools")/C7 -> 0.17564608 | D9: =(B9-C9)*100 -> 16.918151 | E9: ~2x account — validate each Comcast tag
A10: Customer % | B10: =COUNTIFS(Data!$D$2:$D$2284,"Omar.Mansour@vxi.com",Data!$H$2:$H$2284,"Customer")/B7 -> 0.13793103 | C10: =COUNTIFS(Data!$H$2:$H$2284,"Customer")/C7 -> 0.08935611 | D10: =(B10-C10)*100 -> 4.8574924 | E10: Higher; 2 are positive-feedback calls (good catch)
A11: No Audio % | B11: =COUNTIFS(Data!$D$2:$D$2284,"Omar.Mansour@vxi.com",Data!$H$2:$H$2284,"No Audio Found on I3")/B7 -> 0.13793103 | C11: =COUNTIFS(Data!$H$2:$H$2284,"No Audio Found on I3")/C7 -> 0.081909768 | D11: =(B11-C11)*100 -> 5.6021267 | E11: Includes 1 test row + 1 duplicate
A12: Rows sharing a Survey ID | B12: =COUNTIFS(Data!$D$2:$D$2284,"Omar.Mansour@vxi.com",Data!$L$2:$L$2284,"Y") -> 4 | C12: =COUNTIFS(Data!$L$2:$L$2284,"Y") -> 260 | D12: =B12/B7-C12/C7 -> 0.024045796 | E12: 2 surveys submitted twice
A13: Comment filled % | B13: =COUNTIFS(Data!$D$2:$D$2284,"Omar.Mansour@vxi.com",Data!$J$2:$J$2284,"<>")/B7 -> 0.86206897 | C13: =COUNTIFS(Data!$J$2:$J$2284,"<>")/C7 -> 0.91633815 | E13: All non-No-Audio rows have comments; richest narratives on account
A15: Omar — Day over Day
A16: Scrub Date | B16: Scrubs | C16: Agent Opp | D16: Comcast | E16: Customer | F16: No Audio | G16: AO %
A17: 46294 | B17: =COUNTIFS(Data!$D$2:$D$2284,"Omar.Mansour@vxi.com",Data!$B$2:$B$2284,A17) -> 2 | C17: =COUNTIFS(Data!$D$2:$D$2284,"Omar.Mansour@vxi.com",Data!$B$2:$B$2284,$A17,Data!$H$2:$H$2284,"Agent Opportunity") -> 1 | D17: =COUNTIFS(Data!$D$2:$D$2284,"Omar.Mansour@vxi.com",Data!$B$2:$B$2284,$A17,Data!$H$2:$H$2284,"Comcast Process/Tools") -> 0 | E17: =COUNTIFS(Data!$D$2:$D$2284,"Omar.Mansour@vxi.com",Data!$B$2:$B$2284,$A17,Data!$H$2:$H$2284,"Customer") -> 0 | F17: =COUNTIFS(Data!$D$2:$D$2284,"Omar.Mansour@vxi.com",Data!$B$2:$B$2284,$A17,Data!$H$2:$H$2284,"No Audio Found on I3") -> 1 | G17: =IF(B17=0,0,C17/B17) -> 0.5
A18: 46301 | B18: =COUNTIFS(Data!$D$2:$D$2284,"Omar.Mansour@vxi.com",Data!$B$2:$B$2284,A18) -> 13 | C18: =COUNTIFS(Data!$D$2:$D$2284,"Omar.Mansour@vxi.com",Data!$B$2:$B$2284,$A18,Data!$H$2:$H$2284,"Agent Opportunity") -> 5 | D18: =COUNTIFS(Data!$D$2:$D$2284,"Omar.Mansour@vxi.com",Data!$B$2:$B$2284,$A18,Data!$H$2:$H$2284,"Comcast Process/Tools") -> 4 | E18: =COUNTIFS(Data!$D$2:$D$2284,"Omar.Mansour@vxi.com",Data!$B$2:$B$2284,$A18,Data!$H$2:$H$2284,"Customer") -> 4 | F18: =COUNTIFS(Data!$D$2:$D$2284,"Omar.Mansour@vxi.com",Data!$B$2:$B$2284,$A18,Data!$H$2:$H$2284,"No Audio Found on I3") -> 0 | G18: =IF(B18=0,0,C18/B18) -> 0.38461538
A19: 46302 | B19: =COUNTIFS(Data!$D$2:$D$2284,"Omar.Mansour@vxi.com",Data!$B$2:$B$2284,A19) -> 14 | C19: =COUNTIFS(Data!$D$2:$D$2284,"Omar.Mansour@vxi.com",Data!$B$2:$B$2284,$A19,Data!$H$2:$H$2284,"Agent Opportunity") -> 5 | D19: =COUNTIFS(Data!$D$2:$D$2284,"Omar.Mansour@vxi.com",Data!$B$2:$B$2284,$A19,Data!$H$2:$H$2284,"Comcast Process/Tools") -> 6 | E19: =COUNTIFS(Data!$D$2:$D$2284,"Omar.Mansour@vxi.com",Data!$B$2:$B$2284,$A19,Data!$H$2:$H$2284,"Customer") -> 0 | F19: =COUNTIFS(Data!$D$2:$D$2284,"Omar.Mansour@vxi.com",Data!$B$2:$B$2284,$A19,Data!$H$2:$H$2284,"No Audio Found on I3") -> 3 | G19: =IF(B19=0,0,C19/B19) -> 0.35714286
A21: Audit Flags — row-level findings (QA review of Omar's 29 entries)
A22: Data ID | B22: Survey ID | C22: Severity | D22: Finding | E22: Recommended Action
A23: 2030 | B23: 11 | C23: High | D23: Test/junk entry: BPID = "11", Survey ID = "11". | E23: Delete from scrub file.
A24: 2215 | B24: 2196171839 | C24: High | D24: Same survey scrubbed twice with CONFLICTING RCA: Comcast Restriction (07-Oct) vs Agent Opp – Knowledge Gap. | E24: Keep one final RCA; remove the other.
A25: 2236 | B25: 2196171839 | C25: High | D25: Duplicate of above. Comment "Discovery / Identifying Customer Needs" fits "Did not ask discovery questions" better than Knowledge Gap. | E25: Merge with ID 2215; retag T2.
A26: 2277 | B26: 2197808496 | C26: Medium | D26: Survey submitted twice (IDs 2277 & 2278), both No Audio. | E26: Delete one row.
A27: 2120 | B27: 2195165826 | C27: Medium | D27: Tagged Comcast Outage, but comment says agent told customer "it's just you" without validating — misinformation is controllable. | E27: Re-review: likely Agent Opp – Incorrect/Incomplete Resolution.
A28: 2031 | B28: 30003055651790377517 | C28: Medium | D28: T2 = Communication/Soft Skills but comment itself concludes "Incorrect/Incomplete Resolution". Survey ID format (20 digits) unusual. | E28: Align T2 to comment; verify Survey ID.
A29: 2135 | B29: 2196814455 | C29: Low | D29: BPID typo "p-aelshe876" (missing "b") — breaks agent-level reporting. | E29: Correct to bp-aelshe876.
A30: 2275 | B30: 2197847600 | C30: Low | D30: Comment contains paste artifact "Pasted text". | E30: Clean comment.
A31: 2233 | B31: 2197495330 | C31: Low | D31: Comment is a tag list only, no call evidence. | E31: Add 1–2 lines of evidence.
A32: 2215 | B32: 2196171839 | C32: Low | D32: Handle time 3 seconds; ID 2273 left open 10+ hrs — timestamps not reliable for productivity. | E32: Submit form per call.
A34: Strengths
A35: ✔ Best-quality comments on the account: evidence-based, quotes the customer verbatim, explains WHY it is / is not controllable.
A36: ✔ Correctly separates "Another Agent's Opportunity" and "Positive feedback" from the handling agent — protects agents from unfair detractors.
A37: ✔ 100% Survey Date populated; all non-No-Audio rows have T2 + comment.
A39: Coaching Points for Omar
A40: 1. Accuracy over volume: 4 of 29 rows (14%) are junk/duplicate — check Survey ID before submitting.
A41: 2. Comcast tags at 34% vs 18% account: if the agent added misinformation or poor expectation-setting on top of an outage, tag Agent Opp.
A42: 3. Make T2 match the conclusion written in the comment.
A43: 4. Calibration session with a top-volume scrubber (e.g., Shereen Kamal) on 5 shared surveys.

Sheet Day over Day
A1: NPS Scrubbing — Day over Day (Account)
A2: Counts by scrub submission date · all formulas reference the Data tab
N4: Active Scrubbers: computed in Python (distinct count)
A5: Scrub Date | B5: Total Scrubs | C5: Agent Opp | D5: Customer | E5: Comcast | F5: No Audio | G5: VXI | H5: Agent Opp % | I5: Comcast % | J5: No Audio % | K5: DoD Δ Volume | L5: DoD Δ Agent Opp % (pts) | M5: Omar Scrubs | N5: Active Scrubbers
A6: 46302 | B6: =COUNTIFS(Data!$B$2:$B$2284,$A6) -> 110 | C6: =COUNTIFS(Data!$B$2:$B$2284,$A6,Data!$H$2:$H$2284,"Agent Opportunity") -> 71 | D6: =COUNTIFS(Data!$B$2:$B$2284,$A6,Data!$H$2:$H$2284,"Customer") -> 9 | E6: =COUNTIFS(Data!$B$2:$B$2284,$A6,Data!$H$2:$H$2284,"Comcast Process/Tools") -> 26 | F6: =COUNTIFS(Data!$B$2:$B$2284,$A6,Data!$H$2:$H$2284,"No Audio Found on I3") -> 3 | G6: =COUNTIFS(Data!$B$2:$B$2284,$A6,Data!$H$2:$H$2284,"VXI Process/Tools") -> 1 | H6: =IF(B6=0,0,C6/B6) -> 0.64545455 | I6: =IF(B6=0,0,E6/B6) -> 0.23636364 | J6: =IF(B6=0,0,F6/B6) -> 0.027272727 | K6: =B6-B7 -> 26 | L6: =(H6-H7)*100 -> 18.116883 | M6: =COUNTIFS(Data!$B$2:$B$2284,$A6,Data!$D$2:$D$2284,"Omar.Mansour@vxi.com") -> 14 | N6: 6
A7: 46301 | B7: =COUNTIFS(Data!$B$2:$B$2284,$A7) -> 84 | C7: =COUNTIFS(Data!$B$2:$B$2284,$A7,Data!$H$2:$H$2284,"Agent Opportunity") -> 39 | D7: =COUNTIFS(Data!$B$2:$B$2284,$A7,Data!$H$2:$H$2284,"Customer") -> 10 | E7: =COUNTIFS(Data!$B$2:$B$2284,$A7,Data!$H$2:$H$2284,"Comcast Process/Tools") -> 26 | F7: =COUNTIFS(Data!$B$2:$B$2284,$A7,Data!$H$2:$H$2284,"No Audio Found on I3") -> 9 | G7: =COUNTIFS(Data!$B$2:$B$2284,$A7,Data!$H$2:$H$2284,"VXI Process/Tools") -> 0 | H7: =IF(B7=0,0,C7/B7) -> 0.46428571 | I7: =IF(B7=0,0,E7/B7) -> 0.30952381 | J7: =IF(B7=0,0,F7/B7) -> 0.10714286 | K7: =B7-B8 -> 56 | L7: =(H7-H8)*100 -> -10.714286 | M7: =COUNTIFS(Data!$B$2:$B$2284,$A7,Data!$D$2:$D$2284,"Omar.Mansour@vxi.com") -> 13 | N7: 6
A8: 46299 | B8: =COUNTIFS(Data!$B$2:$B$2284,$A8) -> 28 | C8: =COUNTIFS(Data!$B$2:$B$2284,$A8,Data!$H$2:$H$2284,"Agent Opportunity") -> 16 | D8: =COUNTIFS(Data!$B$2:$B$2284,$A8,Data!$H$2:$H$2284,"Customer") -> 3 | E8: =COUNTIFS(Data!$B$2:$B$2284,$A8,Data!$H$2:$H$2284,"Comcast Process/Tools") -> 6 | F8: =COUNTIFS(Data!$B$2:$B$2284,$A8,Data!$H$2:$H$2284,"No Audio Found on I3") -> 2 | G8: =COUNTIFS(Data!$B$2:$B$2284,$A8,Data!$H$2:$H$2284,"VXI Process/Tools") -> 1 | H8: =IF(B8=0,0,C8/B8) -> 0.57142857 | I8: =IF(B8=0,0,E8/B8) -> 0.21428571 | J8: =IF(B8=0,0,F8/B8) -> 0.071428571 | K8: =B8-B9 -> 11 | L8: =(H8-H9)*100 -> 21.848739 | M8: =COUNTIFS(Data!$B$2:$B$2284,$A8,Data!$D$2:$D$2284,"Omar.Mansour@vxi.com") -> 0 | N8: 2
A9: 46298 | B9: =COUNTIFS(Data!$B$2:$B$2284,$A9) -> 17 | C9: =COUNTIFS(Data!$B$2:$B$2284,$A9,Data!$H$2:$H$2284,"Agent Opportunity") -> 6 | D9: =COUNTIFS(Data!$B$2:$B$2284,$A9,Data!$H$2:$H$2284,"Customer") -> 0 | E9: =COUNTIFS(Data!$B$2:$B$2284,$A9,Data!$H$2:$H$2284,"Comcast Process/Tools") -> 10 | F9: =COUNTIFS(Data!$B$2:$B$2284,$A9,Data!$H$2:$H$2284,"No Audio Found on I3") -> 1 | G9: =COUNTIFS(Data!$B$2:$B$2284,$A9,Data!$H$2:$H$2284,"VXI Process/Tools") -> 0 | H9: =IF(B9=0,0,C9/B9) -> 0.35294118 | I9: =IF(B9=0,0,E9/B9) -> 0.58823529 | J9: =IF(B9=0,0,F9/B9) -> 0.058823529 | K9: =B9-B10 -> 9 | L9: =(H9-H10)*100 -> -27.205882 | M9: =COUNTIFS(Data!$B$2:$B$2284,$A9,Data!$D$2:$D$2284,"Omar.Mansour@vxi.com") -> 0 | N9: 3
A10: 46297 | B10: =COUNTIFS(Data!$B$2:$B$2284,$A10) -> 8 | C10: =COUNTIFS(Data!$B$2:$B$2284,$A10,Data!$H$2:$H$2284,"Agent Opportunity") -> 5 | D10: =COUNTIFS(Data!$B$2:$B$2284,$A10,Data!$H$2:$H$2284,"Customer") -> 1 | E10: =COUNTIFS(Data!$B$2:$B$2284,$A10,Data!$H$2:$H$2284,"Comcast Process/Tools") -> 1 | F10: =COUNTIFS(Data!$B$2:$B$2284,$A10,Data!$H$2:$H$2284,"No Audio Found on I3") -> 1 | G10: =COUNTIFS(Data!$B$2:$B$2284,$A10,Data!$H$2:$H$2284,"VXI Process/Tools") -> 0 | H10: =IF(B10=0,0,C10/B10) -> 0.625 | I10: =IF(B10=0,0,E10/B10) -> 0.125 | J10: =IF(B10=0,0,F10/B10) -> 0.125 | K10: =B10-B11 -> 4 | L10: =(H10-H11)*100 -> -37.5 | M10: =COUNTIFS(Data!$B$2:$B$2284,$A10,Data!$D$2:$D$2284,"Omar.Mansour@vxi.com") -> 0 | N10: 2
A11: 46296 | B11: =COUNTIFS(Data!$B$2:$B$2284,$A11) -> 4 | C11: =COUNTIFS(Data!$B$2:$B$2284,$A11,Data!$H$2:$H$2284,"Agent Opportunity") -> 4 | D11: =COUNTIFS(Data!$B$2:$B$2284,$A11,Data!$H$2:$H$2284,"Customer") -> 0 | E11: =COUNTIFS(Data!$B$2:$B$2284,$A11,Data!$H$2:$H$2284,"Comcast Process/Tools") -> 0 | F11: =COUNTIFS(Data!$B$2:$B$2284,$A11,Data!$H$2:$H$2284,"No Audio Found on I3") -> 0 | G11: =COUNTIFS(Data!$B$2:$B$2284,$A11,Data!$H$2:$H$2284,"VXI Process/Tools") -> 0 | H11: =IF(B11=0,0,C11/B11) -> 1 | I11: =IF(B11=0,0,E11/B11) -> 0 | J11: =IF(B11=0,0,F11/B11) -> 0 | K11: =B11-B12 -> 0 | L11: =(H11-H12)*100 -> 25 | M11: =COUNTIFS(Data!$B$2:$B$2284,$A11,Data!$D$2:$D$2284,"Omar.Mansour@vxi.com") -> 0 | N11: 2
A12: 46294 | B12: =COUNTIFS(Data!$B$2:$B$2284,$A12) -> 4 | C12: =COUNTIFS(Data!$B$2:$B$2284,$A12,Data!$H$2:$H$2284,"Agent Opportunity") -> 3 | D12: =COUNTIFS(Data!$B$2:$B$2284,$A12,Data!$H$2:$H$2284,"Customer") -> 0 | E12: =COUNTIFS(Data!$B$2:$B$2284,$A12,Data!$H$2:$H$2284,"Comcast Process/Tools") -> 0 | F12: =COUNTIFS(Data!$B$2:$B$2284,$A12,Data!$H$2:$H$2284,"No Audio Found on I3") -> 1 | G12: =COUNTIFS(Data!$B$2:$B$2284,$A12,Data!$H$2:$H$2284,"VXI Process/Tools") -> 0 | H12: =IF(B12=0,0,C12/B12) -> 0.75 | I12: =IF(B12=0,0,E12/B12) -> 0 | J12: =IF(B12=0,0,F12/B12) -> 0.25 | K12: =B12-B13 -> -3 | L12: =(H12-H13)*100 -> -10.714286 | M12: =COUNTIFS(Data!$B$2:$B$2284,$A12,Data!$D$2:$D$2284,"Omar.Mansour@vxi.com") -> 2 | N12: 2
A13: 46293 | B13: =COUNTIFS(Data!$B$2:$B$2284,$A13) -> 7 | C13: =COUNTIFS(Data!$B$2:$B$2284,$A13,Data!$H$2:$H$2284,"Agent Opportunity") -> 6 | D13: =COUNTIFS(Data!$B$2:$B$2284,$A13,Data!$H$2:$H$2284,"Customer") -> 1 | E13: =COUNTIFS(Data!$B$2:$B$2284,$A13,Data!$H$2:$H$2284,"Comcast Process/Tools") -> 0 | F13: =COUNTIFS(Data!$B$2:$B$2284,$A13,Data!$H$2:$H$2284,"No Audio Found on I3") -> 0 | G13: =COUNTIFS(Data!$B$2:$B$2284,$A13,Data!$H$2:$H$2284,"VXI Process/Tools") -> 0 | H13: =IF(B13=0,0,C13/B13) -> 0.85714286 | I13: =IF(B13=0,0,E13/B13) -> 0 | J13: =IF(B13=0,0,F13/B13) -> 0 | K13: =B13-B14 -> 6 | L13: =(H13-H14)*100 -> -14.285714 | M13: =COUNTIFS(Data!$B$2:$B$2284,$A13,Data!$D$2:$D$2284,"Omar.Mansour@vxi.com") -> 0 | N13: 4
A14: 46292 | B14: =COUNTIFS(Data!$B$2:$B$2284,$A14) -> 1 | C14: =COUNTIFS(Data!$B$2:$B$2284,$A14,Data!$H$2:$H$2284,"Agent Opportunity") -> 1 | D14: =COUNTIFS(Data!$B$2:$B$2284,$A14,Data!$H$2:$H$2284,"Customer") -> 0 | E14: =COUNTIFS(Data!$B$2:$B$2284,$A14,Data!$H$2:$H$2284,"Comcast Process/Tools") -> 0 | F14: =COUNTIFS(Data!$B$2:$B$2284,$A14,Data!$H$2:$H$2284,"No Audio Found on I3") -> 0 | G14: =COUNTIFS(Data!$B$2:$B$2284,$A14,Data!$H$2:$H$2284,"VXI Process/Tools") -> 0 | H14: =IF(B14=0,0,C14/B14) -> 1 | I14: =IF(B14=0,0,E14/B14) -> 0 | J14: =IF(B14=0,0,F14/B14) -> 0 | K14: =B14-B15 -> -13 | L14: =(H14-H15)*100 -> 50 | M14: =COUNTIFS(Data!$B$2:$B$2284,$A14,Data!$D$2:$D$2284,"Omar.Mansour@vxi.com") -> 0 | N14: 1
A15: 46291 | B15: =COUNTIFS(Data!$B$2:$B$2284,$A15) -> 14 | C15: =COUNTIFS(Data!$B$2:$B$2284,$A15,Data!$H$2:$H$2284,"Agent Opportunity") -> 7 | D15: =COUNTIFS(Data!$B$2:$B$2284,$A15,Data!$H$2:$H$2284,"Customer") -> 4 | E15: =COUNTIFS(Data!$B$2:$B$2284,$A15,Data!$H$2:$H$2284,"Comcast Process/Tools") -> 2 | F15: =COUNTIFS(Data!$B$2:$B$2284,$A15,Data!$H$2:$H$2284,"No Audio Found on I3") -> 1 | G15: =COUNTIFS(Data!$B$2:$B$2284,$A15,Data!$H$2:$H$2284,"VXI Process/Tools") -> 0 | H15: =IF(B15=0,0,C15/B15) -> 0.5 | I15: =IF(B15=0,0,E15/B15) -> 0.14285714 | J15: =IF(B15=0,0,F15/B15) -> 0.071428571 | K15: =B15-B16 -> 5 | L15: =(H15-H16)*100 -> -38.888889 | M15: =COUNTIFS(Data!$B$2:$B$2284,$A15,Data!$D$2:$D$2284,"Omar.Mansour@vxi.com") -> 0 | N15: 3
A16: 46290 | B16: =COUNTIFS(Data!$B$2:$B$2284,$A16) -> 9 | C16: =COUNTIFS(Data!$B$2:$B$2284,$A16,Data!$H$2:$H$2284,"Agent Opportunity") -> 8 | D16: =COUNTIFS(Data!$B$2:$B$2284,$A16,Data!$H$2:$H$2284,"Customer") -> 1 | E16: =COUNTIFS(Data!$B$2:$B$2284,$A16,Data!$H$2:$H$2284,"Comcast Process/Tools") -> 0 | F16: =COUNTIFS(Data!$B$2:$B$2284,$A16,Data!$H$2:$H$2284,"No Audio Found on I3") -> 0 | G16: =COUNTIFS(Data!$B$2:$B$2284,$A16,Data!$H$2:$H$2284,"VXI Process/Tools") -> 0 | H16: =IF(B16=0,0,C16/B16) -> 0.88888889 | I16: =IF(B16=0,0,E16/B16) -> 0 | J16: =IF(B16=0,0,F16/B16) -> 0 | K16: =B16-B17 -> 7 | L16: =(H16-H17)*100 -> 38.888889 | M16: =COUNTIFS(Data!$B$2:$B$2284,$A16,Data!$D$2:$D$2284,"Omar.Mansour@vxi.com") -> 0 | N16: 4
A17: 46289 | B17: =COUNTIFS(Data!$B$2:$B$2284,$A17) -> 2 | C17: =COUNTIFS(Data!$B$2:$B$2284,$A17,Data!$H$2:$H$2284,"Agent Opportunity") -> 1 | D17: =COUNTIFS(Data!$B$2:$B$2284,$A17,Data!$H$2:$H$2284,"Customer") -> 0 | E17: =COUNTIFS(Data!$B$2:$B$2284,$A17,Data!$H$2:$H$2284,"Comcast Process/Tools") -> 1 | F17: =COUNTIFS(Data!$B$2:$B$2284,$A17,Data!$H$2:$H$2284,"No Audio Found on I3") -> 0 | G17: =COUNTIFS(Data!$B$2:$B$2284,$A17,Data!$H$2:$H$2284,"VXI Process/Tools") -> 0 | H17: =IF(B17=0,0,C17/B17) -> 0.5 | I17: =IF(B17=0,0,E17/B17) -> 0.5 | J17: =IF(B17=0,0,F17/B17) -> 0 | K17: =B17-B18 -> -15 | L17: =(H17-H18)*100 -> -8.8235294 | M17: =COUNTIFS(Data!$B$2:$B$2284,$A17,Data!$D$2:$D$2284,"Omar.Mansour@vxi.com") -> 0 | N17: 2
... A167: 46114 | B167: =COUNTIFS(Data!$B$2:$B$2284,$A167) -> 7 | C167: =COUNTIFS(Data!$B$2:$B$2284,$A167,Data!$H$2:$H$2284,"Agent Opportunity") -> 5 | D167: =COUNTIFS(Data!$B$2:$B$2284,$A167,Data!$H$2:$H$2284,"Customer") -> 1 | E167: =COUNTIFS(Data!$B$2:$B$2284,$A167,Data!$H$2:$H$2284,"Comcast Process/Tools") -> 0 | F167: =COUNTIFS(Data!$B$2:$B$2284,$A167,Data!$H$2:$H$2284,"No Audio Found on I3") -> 1 | G167: =COUNTIFS(Data!$B$2:$B$2284,$A167,Data!$H$2:$H$2284,"VXI Process/Tools") -> 0 | H167: =IF(B167=0,0,C167/B167) -> 0.71428571 | I167: =IF(B167=0,0,E167/B167) -> 0 | J167: =IF(B167=0,0,F167/B167) -> 0.14285714 | K167: =B167-B168 -> -2 | L167: =(H167-H168)*100 -> 4.7619048 | M167: =COUNTIFS(Data!$B$2:$B$2284,$A167,Data!$D$2:$D$2284,"Omar.Mansour@vxi.com") -> 0 | N167: 2
A168: 46113 | B168: =COUNTIFS(Data!$B$2:$B$2284,$A168) -> 9 | C168: =COUNTIFS(Data!$B$2:$B$2284,$A168,Data!$H$2:$H$2284,"Agent Opportunity") -> 6 | D168: =COUNTIFS(Data!$B$2:$B$2284,$A168,Data!$H$2:$H$2284,"Customer") -> 1 | E168: =COUNTIFS(Data!$B$2:$B$2284,$A168,Data!$H$2:$H$2284,"Comcast Process/Tools") -> 1 | F168: =COUNTIFS(Data!$B$2:$B$2284,$A168,Data!$H$2:$H$2284,"No Audio Found on I3") -> 1 | G168: =COUNTIFS(Data!$B$2:$B$2284,$A168,Data!$H$2:$H$2284,"VXI Process/Tools") -> 0 | H168: =IF(B168=0,0,C168/B168) -> 0.66666667 | I168: =IF(B168=0,0,E168/B168) -> 0.11111111 | J168: =IF(B168=0,0,F168/B168) -> 0.11111111 | K168: =0 -> 0 | L168: =0 -> 0 | M168: =COUNTIFS(Data!$B$2:$B$2284,$A168,Data!$D$2:$D$2284,"Omar.Mansour@vxi.com") -> 0 | N168: 2

Sheet Monthly Trend
A1: NPS Scrubbing — Month over Month
A2: Month = scrub submission month
A5: Month Start | B5: Month End | C5: Total | D5: Agent Opp | E5: Customer | F5: Comcast | G5: No Audio | H5: VXI | I5: Agent Opp % | J5: Comcast % | K5: MoM Δ Volume | L5: MoM Δ AO % (pts)
A6: 46113 | B6: 46142 | C6: =COUNTIFS(Data!$B$2:$B$2284,">="&A6,Data!$B$2:$B$2284,"<="&B6) -> 247 | D6: =COUNTIFS(Data!$B$2:$B$2284,">="&A6,Data!$B$2:$B$2284,"<="&B6,Data!$H$2:$H$2284,"Agent Opportunity") -> 147 | E6: =COUNTIFS(Data!$B$2:$B$2284,">="&A6,Data!$B$2:$B$2284,"<="&B6,Data!$H$2:$H$2284,"Customer") -> 25 | F6: =COUNTIFS(Data!$B$2:$B$2284,">="&A6,Data!$B$2:$B$2284,"<="&B6,Data!$H$2:$H$2284,"Comcast Process/Tools") -> 47 | G6: =COUNTIFS(Data!$B$2:$B$2284,">="&A6,Data!$B$2:$B$2284,"<="&B6,Data!$H$2:$H$2284,"No Audio Found on I3") -> 26 | H6: =COUNTIFS(Data!$B$2:$B$2284,">="&A6,Data!$B$2:$B$2284,"<="&B6,Data!$H$2:$H$2284,"VXI Process/Tools") -> 2 | I6: =IF(C6=0,0,D6/C6) -> 0.5951417 | J6: =IF(C6=0,0,F6/C6) -> 0.1902834 | K6: =0 -> 0 | L6: =0 -> 0
A7: 46143 | B7: 46173 | C7: =COUNTIFS(Data!$B$2:$B$2284,">="&A7,Data!$B$2:$B$2284,"<="&B7) -> 342 | D7: =COUNTIFS(Data!$B$2:$B$2284,">="&A7,Data!$B$2:$B$2284,"<="&B7,Data!$H$2:$H$2284,"Agent Opportunity") -> 220 | E7: =COUNTIFS(Data!$B$2:$B$2284,">="&A7,Data!$B$2:$B$2284,"<="&B7,Data!$H$2:$H$2284,"Customer") -> 33 | F7: =COUNTIFS(Data!$B$2:$B$2284,">="&A7,Data!$B$2:$B$2284,"<="&B7,Data!$H$2:$H$2284,"Comcast Process/Tools") -> 58 | G7: =COUNTIFS(Data!$B$2:$B$2284,">="&A7,Data!$B$2:$B$2284,"<="&B7,Data!$H$2:$H$2284,"No Audio Found on I3") -> 20 | H7: =COUNTIFS(Data!$B$2:$B$2284,">="&A7,Data!$B$2:$B$2284,"<="&B7,Data!$H$2:$H$2284,"VXI Process/Tools") -> 11 | I7: =IF(C7=0,0,D7/C7) -> 0.64327485 | J7: =IF(C7=0,0,F7/C7) -> 0.16959064 | K7: =C7-C6 -> 95 | L7: =(I7-I6)*100 -> 4.8133153
A8: 46174 | B8: 46203 | C8: =COUNTIFS(Data!$B$2:$B$2284,">="&A8,Data!$B$2:$B$2284,"<="&B8) -> 289 | D8: =COUNTIFS(Data!$B$2:$B$2284,">="&A8,Data!$B$2:$B$2284,"<="&B8,Data!$H$2:$H$2284,"Agent Opportunity") -> 178 | E8: =COUNTIFS(Data!$B$2:$B$2284,">="&A8,Data!$B$2:$B$2284,"<="&B8,Data!$H$2:$H$2284,"Customer") -> 23 | F8: =COUNTIFS(Data!$B$2:$B$2284,">="&A8,Data!$B$2:$B$2284,"<="&B8,Data!$H$2:$H$2284,"Comcast Process/Tools") -> 51 | G8: =COUNTIFS(Data!$B$2:$B$2284,">="&A8,Data!$B$2:$B$2284,"<="&B8,Data!$H$2:$H$2284,"No Audio Found on I3") -> 32 | H8: =COUNTIFS(Data!$B$2:$B$2284,">="&A8,Data!$B$2:$B$2284,"<="&B8,Data!$H$2:$H$2284,"VXI Process/Tools") -> 5 | I8: =IF(C8=0,0,D8/C8) -> 0.61591696 | J8: =IF(C8=0,0,F8/C8) -> 0.17647059 | K8: =C8-C7 -> -53 | L8: =(I8-I7)*100 -> -2.7357899
A9: 46204 | B9: 46234 | C9: =COUNTIFS(Data!$B$2:$B$2284,">="&A9,Data!$B$2:$B$2284,"<="&B9) -> 381 | D9: =COUNTIFS(Data!$B$2:$B$2284,">="&A9,Data!$B$2:$B$2284,"<="&B9,Data!$H$2:$H$2284,"Agent Opportunity") -> 259 | E9: =COUNTIFS(Data!$B$2:$B$2284,">="&A9,Data!$B$2:$B$2284,"<="&B9,Data!$H$2:$H$2284,"Customer") -> 27 | F9: =COUNTIFS(Data!$B$2:$B$2284,">="&A9,Data!$B$2:$B$2284,"<="&B9,Data!$H$2:$H$2284,"Comcast Process/Tools") -> 50 | G9: =COUNTIFS(Data!$B$2:$B$2284,">="&A9,Data!$B$2:$B$2284,"<="&B9,Data!$H$2:$H$2284,"No Audio Found on I3") -> 38 | H9: =COUNTIFS(Data!$B$2:$B$2284,">="&A9,Data!$B$2:$B$2284,"<="&B9,Data!$H$2:$H$2284,"VXI Process/Tools") -> 7 | I9: =IF(C9=0,0,D9/C9) -> 0.67979003 | J9: =IF(C9=0,0,F9/C9) -> 0.1312336 | K9: =C9-C8 -> 92 | L9: =(I9-I8)*100 -> 6.3873071
A10: 46235 | B10: 46265 | C10: =COUNTIFS(Data!$B$2:$B$2284,">="&A10,Data!$B$2:$B$2284,"<="&B10) -> 543 | D10: =COUNTIFS(Data!$B$2:$B$2284,">="&A10,Data!$B$2:$B$2284,"<="&B10,Data!$H$2:$H$2284,"Agent Opportunity") -> 357 | E10: =COUNTIFS(Data!$B$2:$B$2284,">="&A10,Data!$B$2:$B$2284,"<="&B10,Data!$H$2:$H$2284,"Customer") -> 46 | F10: =COUNTIFS(Data!$B$2:$B$2284,">="&A10,Data!$B$2:$B$2284,"<="&B10,Data!$H$2:$H$2284,"Comcast Process/Tools") -> 99 | G10: =COUNTIFS(Data!$B$2:$B$2284,">="&A10,Data!$B$2:$B$2284,"<="&B10,Data!$H$2:$H$2284,"No Audio Found on I3") -> 36 | H10: =COUNTIFS(Data!$B$2:$B$2284,">="&A10,Data!$B$2:$B$2284,"<="&B10,Data!$H$2:$H$2284,"VXI Process/Tools") -> 5 | I10: =IF(C10=0,0,D10/C10) -> 0.65745856 | J10: =IF(C10=0,0,F10/C10) -> 0.18232044 | K10: =C10-C9 -> 162 | L10: =(I10-I9)*100 -> -2.2331463
A11: 46266 | B11: 46295 | C11: =COUNTIFS(Data!$B$2:$B$2284,">="&A11,Data!$B$2:$B$2284,"<="&B11) -> 230 | D11: =COUNTIFS(Data!$B$2:$B$2284,">="&A11,Data!$B$2:$B$2284,"<="&B11,Data!$H$2:$H$2284,"Agent Opportunity") -> 156 | E11: =COUNTIFS(Data!$B$2:$B$2284,">="&A11,Data!$B$2:$B$2284,"<="&B11,Data!$H$2:$H$2284,"Customer") -> 27 | F11: =COUNTIFS(Data!$B$2:$B$2284,">="&A11,Data!$B$2:$B$2284,"<="&B11,Data!$H$2:$H$2284,"Comcast Process/Tools") -> 27 | G11: =COUNTIFS(Data!$B$2:$B$2284,">="&A11,Data!$B$2:$B$2284,"<="&B11,Data!$H$2:$H$2284,"No Audio Found on I3") -> 19 | H11: =COUNTIFS(Data!$B$2:$B$2284,">="&A11,Data!$B$2:$B$2284,"<="&B11,Data!$H$2:$H$2284,"VXI Process/Tools") -> 1 | I11: =IF(C11=0,0,D11/C11) -> 0.67826087 | J11: =IF(C11=0,0,F11/C11) -> 0.1173913 | K11: =C11-C10 -> -313 | L11: =(I11-I10)*100 -> 2.0802306
A12: 46296 | B12: 46326 | C12: =COUNTIFS(Data!$B$2:$B$2284,">="&A12,Data!$B$2:$B$2284,"<="&B12) -> 251 | D12: =COUNTIFS(Data!$B$2:$B$2284,">="&A12,Data!$B$2:$B$2284,"<="&B12,Data!$H$2:$H$2284,"Agent Opportunity") -> 141 | E12: =COUNTIFS(Data!$B$2:$B$2284,">="&A12,Data!$B$2:$B$2284,"<="&B12,Data!$H$2:$H$2284,"Customer") -> 23 | F12: =COUNTIFS(Data!$B$2:$B$2284,">="&A12,Data!$B$2:$B$2284,"<="&B12,Data!$H$2:$H$2284,"Comcast Process/Tools") -> 69 | G12: =COUNTIFS(Data!$B$2:$B$2284,">="&A12,Data!$B$2:$B$2284,"<="&B12,Data!$H$2:$H$2284,"No Audio Found on I3") -> 16 | H12: =COUNTIFS(Data!$B$2:$B$2284,">="&A12,Data!$B$2:$B$2284,"<="&B12,Data!$H$2:$H$2284,"VXI Process/Tools") -> 2 | I12: =IF(C12=0,0,D12/C12) -> 0.56175299 | J12: =IF(C12=0,0,F12/C12) -> 0.2749004 | K12: =C12-C11 -> 21 | L12: =(I12-I11)*100 -> -11.650788
A13: Total | C13: =SUM(C6:C12) -> 2283 | D13: =SUM(D6:D12) -> 1458 | E13: =SUM(E6:E12) -> 204 | F13: =SUM(F6:F12) -> 401 | G13: =SUM(G6:G12) -> 187 | H13: =SUM(H6:H12) -> 33 | I13: =D13/C13 -> 0.63863338 | J13: =F13/C13 -> 0.17564608
A14: October = MTD through 07-Oct-2026 (partial month).

Sheet Scrubber Scorecard
A1: Scrubber Scorecard & Calibration
A2: RCA mix per scrubber vs account — wide gaps signal calibration need
A5: Scrubber | B5: Email | C5: Total | D5: Agent Opp % | E5: Customer % | F5: Comcast % | G5: No Audio % | H5: T2 Filled % (excl. No Audio) | I5: Dup Survey IDs | J5: Bad BPID Format | K5: Median Min / Scrub | L5: AO % gap vs Account (pts) | M5: Calibration Flag
A6: Shereen Kamal | B6: shereen.kamal@vxi.com | C6: =COUNTIFS(Data!$D$2:$D$2284,B6) -> 382 | D6: =COUNTIFS(Data!$D$2:$D$2284,B6,Data!$H$2:$H$2284,"Agent Opportunity")/C6 -> 0.7617801 | E6: =COUNTIFS(Data!$D$2:$D$2284,B6,Data!$H$2:$H$2284,"Customer")/C6 -> 0.086387435 | F6: =COUNTIFS(Data!$D$2:$D$2284,B6,Data!$H$2:$H$2284,"Comcast Process/Tools")/C6 -> 0.10732984 | G6: =COUNTIFS(Data!$D$2:$D$2284,B6,Data!$H$2:$H$2284,"No Audio Found on I3")/C6 -> 0.031413613 | H6: =IFERROR(COUNTIFS(Data!$D$2:$D$2284,B6,Data!$H$2:$H$2284,"<>No Audio Found on I3",Data!$I$2:$I$2284,"<>")/COUNTIFS(Data!$D$2:$D$2284,B6,Data!$H$2:$H$2284,"<>No Audio Found on I3"),0) -> 1 | I6: =COUNTIFS(Data!$D$2:$D$2284,B6,Data!$L$2:$L$2284,"Y") -> 54 | J6: =COUNTIFS(Data!$D$2:$D$2284,B6,Data!$M$2:$M$2284,"N") -> 18 | K6: 2.4 | L6: =(D6-$D$18)*100 -> 12.314673 | M6: =IF(ABS(L6)>15,"Calibrate",IF(ABS(L6)>8,"Watch","Aligned")) -> Watch
A7: Mina Milad Khalaf Mansour | B7: mina.mansour@vxi.com | C7: =COUNTIFS(Data!$D$2:$D$2284,B7) -> 352 | D7: =COUNTIFS(Data!$D$2:$D$2284,B7,Data!$H$2:$H$2284,"Agent Opportunity")/C7 -> 0.65909091 | E7: =COUNTIFS(Data!$D$2:$D$2284,B7,Data!$H$2:$H$2284,"Customer")/C7 -> 0.11363636 | F7: =COUNTIFS(Data!$D$2:$D$2284,B7,Data!$H$2:$H$2284,"Comcast Process/Tools")/C7 -> 0.13920455 | G7: =COUNTIFS(Data!$D$2:$D$2284,B7,Data!$H$2:$H$2284,"No Audio Found on I3")/C7 -> 0.076704545 | H7: =IFERROR(COUNTIFS(Data!$D$2:$D$2284,B7,Data!$H$2:$H$2284,"<>No Audio Found on I3",Data!$I$2:$I$2284,"<>")/COUNTIFS(Data!$D$2:$D$2284,B7,Data!$H$2:$H$2284,"<>No Audio Found on I3"),0) -> 1 | I7: =COUNTIFS(Data!$D$2:$D$2284,B7,Data!$L$2:$L$2284,"Y") -> 28 | J7: =COUNTIFS(Data!$D$2:$D$2284,B7,Data!$M$2:$M$2284,"N") -> 0 | K7: 9.9 | L7: =(D7-$D$18)*100 -> 2.0457532 | M7: =IF(ABS(L7)>15,"Calibrate",IF(ABS(L7)>8,"Watch","Aligned")) -> Aligned
A8: Salma Ahmed | B8: salma.ahmed@vxi.com | C8: =COUNTIFS(Data!$D$2:$D$2284,B8) -> 316 | D8: =COUNTIFS(Data!$D$2:$D$2284,B8,Data!$H$2:$H$2284,"Agent Opportunity")/C8 -> 0.50949367 | E8: =COUNTIFS(Data!$D$2:$D$2284,B8,Data!$H$2:$H$2284,"Customer")/C8 -> 0.085443038 | F8: =COUNTIFS(Data!$D$2:$D$2284,B8,Data!$H$2:$H$2284,"Comcast Process/Tools")/C8 -> 0.24050633 | G8: =COUNTIFS(Data!$D$2:$D$2284,B8,Data!$H$2:$H$2284,"No Audio Found on I3")/C8 -> 0.14556962 | H8: =IFERROR(COUNTIFS(Data!$D$2:$D$2284,B8,Data!$H$2:$H$2284,"<>No Audio Found on I3",Data!$I$2:$I$2284,"<>")/COUNTIFS(Data!$D$2:$D$2284,B8,Data!$H$2:$H$2284,"<>No Audio Found on I3"),0) -> 1 | I8: =COUNTIFS(Data!$D$2:$D$2284,B8,Data!$L$2:$L$2284,"Y") -> 41 | J8: =COUNTIFS(Data!$D$2:$D$2284,B8,Data!$M$2:$M$2284,"N") -> 1 | K8: 4.9 | L8: =(D8-$D$18)*100 -> -12.913971 | M8: =IF(ABS(L8)>15,"Calibrate",IF(ABS(L8)>8,"Watch","Aligned")) -> Watch
A9: AbdelRahman Abdo | B9: Abdelrahman.Fouad@vxi.com | C9: =COUNTIFS(Data!$D$2:$D$2284,B9) -> 294 | D9: =COUNTIFS(Data!$D$2:$D$2284,B9,Data!$H$2:$H$2284,"Agent Opportunity")/C9 -> 0.64965986 | E9: =COUNTIFS(Data!$D$2:$D$2284,B9,Data!$H$2:$H$2284,"Customer")/C9 -> 0.047619048 | F9: =COUNTIFS(Data!$D$2:$D$2284,B9,Data!$H$2:$H$2284,"Comcast Process/Tools")/C9 -> 0.22789116 | G9: =COUNTIFS(Data!$D$2:$D$2284,B9,Data!$H$2:$H$2284,"No Audio Found on I3")/C9 -> 0.030612245 | H9: =IFERROR(COUNTIFS(Data!$D$2:$D$2284,B9,Data!$H$2:$H$2284,"<>No Audio Found on I3",Data!$I$2:$I$2284,"<>")/COUNTIFS(Data!$D$2:$D$2284,B9,Data!$H$2:$H$2284,"<>No Audio Found on I3"),0) -> 1 | I9: =COUNTIFS(Data!$D$2:$D$2284,B9,Data!$L$2:$L$2284,"Y") -> 4 | J9: =COUNTIFS(Data!$D$2:$D$2284,B9,Data!$M$2:$M$2284,"N") -> 6 | K9: 0.7 | L9: =(D9-$D$18)*100 -> 1.1026487 | M9: =IF(ABS(L9)>15,"Calibrate",IF(ABS(L9)>8,"Watch","Aligned")) -> Aligned
A10: Mohamed Ashour | B10: mohamed.ashour3@vxi.com | C10: =COUNTIFS(Data!$D$2:$D$2284,B10) -> 261 | D10: =COUNTIFS(Data!$D$2:$D$2284,B10,Data!$H$2:$H$2284,"Agent Opportunity")/C10 -> 0.67049808 | E10: =COUNTIFS(Data!$D$2:$D$2284,B10,Data!$H$2:$H$2284,"Customer")/C10 -> 0.088122605 | F10: =COUNTIFS(Data!$D$2:$D$2284,B10,Data!$H$2:$H$2284,"Comcast Process/Tools")/C10 -> 0.17241379 | G10: =COUNTIFS(Data!$D$2:$D$2284,B10,Data!$H$2:$H$2284,"No Audio Found on I3")/C10 -> 0.068965517 | H10: =IFERROR(COUNTIFS(Data!$D$2:$D$2284,B10,Data!$H$2:$H$2284,"<>No Audio Found on I3",Data!$I$2:$I$2284,"<>")/COUNTIFS(Data!$D$2:$D$2284,B10,Data!$H$2:$H$2284,"<>No Audio Found on I3"),0) -> 1 | I10: =COUNTIFS(Data!$D$2:$D$2284,B10,Data!$L$2:$L$2284,"Y") -> 47 | J10: =COUNTIFS(Data!$D$2:$D$2284,B10,Data!$M$2:$M$2284,"N") -> 0 | K10: 1.9 | L10: =(D10-$D$18)*100 -> 3.1864707 | M10: =IF(ABS(L10)>15,"Calibrate",IF(ABS(L10)>8,"Watch","Aligned")) -> Aligned
A11: Rahma El-Behery | B11: rahma.samir@vxi.com | C11: =COUNTIFS(Data!$D$2:$D$2284,B11) -> 259 | D11: =COUNTIFS(Data!$D$2:$D$2284,B11,Data!$H$2:$H$2284,"Agent Opportunity")/C11 -> 0.58687259 | E11: =COUNTIFS(Data!$D$2:$D$2284,B11,Data!$H$2:$H$2284,"Customer")/C11 -> 0.1042471 | F11: =COUNTIFS(Data!$D$2:$D$2284,B11,Data!$H$2:$H$2284,"Comcast Process/Tools")/C11 -> 0.18918919 | G11: =COUNTIFS(Data!$D$2:$D$2284,B11,Data!$H$2:$H$2284,"No Audio Found on I3")/C11 -> 0.1042471 | H11: =IFERROR(COUNTIFS(Data!$D$2:$D$2284,B11,Data!$H$2:$H$2284,"<>No Audio Found on I3",Data!$I$2:$I$2284,"<>")/COUNTIFS(Data!$D$2:$D$2284,B11,Data!$H$2:$H$2284,"<>No Audio Found on I3"),0) -> 1 | I11: =COUNTIFS(Data!$D$2:$D$2284,B11,Data!$L$2:$L$2284,"Y") -> 40 | J11: =COUNTIFS(Data!$D$2:$D$2284,B11,Data!$M$2:$M$2284,"N") -> 3 | K11: 1.8 | L11: =(D11-$D$18)*100 -> -5.176079 | M11: =IF(ABS(L11)>15,"Calibrate",IF(ABS(L11)>8,"Watch","Aligned")) -> Aligned
A12: Eslam Mohamed Farouk | B12: eslam.farouk@vxi.com | C12: =COUNTIFS(Data!$D$2:$D$2284,B12) -> 212 | D12: =COUNTIFS(Data!$D$2:$D$2284,B12,Data!$H$2:$H$2284,"Agent Opportunity")/C12 -> 0.77830189 | E12: =COUNTIFS(Data!$D$2:$D$2284,B12,Data!$H$2:$H$2284,"Customer")/C12 -> 0.08490566 | F12: =COUNTIFS(Data!$D$2:$D$2284,B12,Data!$H$2:$H$2284,"Comcast Process/Tools")/C12 -> 0.04245283 | G12: =COUNTIFS(Data!$D$2:$D$2284,B12,Data!$H$2:$H$2284,"No Audio Found on I3")/C12 -> 0.094339623 | H12: =IFERROR(COUNTIFS(Data!$D$2:$D$2284,B12,Data!$H$2:$H$2284,"<>No Audio Found on I3",Data!$I$2:$I$2284,"<>")/COUNTIFS(Data!$D$2:$D$2284,B12,Data!$H$2:$H$2284,"<>No Audio Found on I3"),0) -> 1 | I12: =COUNTIFS(Data!$D$2:$D$2284,B12,Data!$L$2:$L$2284,"Y") -> 10 | J12: =COUNTIFS(Data!$D$2:$D$2284,B12,Data!$M$2:$M$2284,"N") -> 2 | K12: 9.5 | L12: =(D12-$D$18)*100 -> 13.966851 | M12: =IF(ABS(L12)>15,"Calibrate",IF(ABS(L12)>8,"Watch","Aligned")) -> Watch
A13: Shrouk Ahmed | B13: Shrouk.Hanafy@vxi.com | C13: =COUNTIFS(Data!$D$2:$D$2284,B13) -> 79 | D13: =COUNTIFS(Data!$D$2:$D$2284,B13,Data!$H$2:$H$2284,"Agent Opportunity")/C13 -> 0.46835443 | E13: =COUNTIFS(Data!$D$2:$D$2284,B13,Data!$H$2:$H$2284,"Customer")/C13 -> 0.10126582 | F13: =COUNTIFS(Data!$D$2:$D$2284,B13,Data!$H$2:$H$2284,"Comcast Process/Tools")/C13 -> 0.25316456 | G13: =COUNTIFS(Data!$D$2:$D$2284,B13,Data!$H$2:$H$2284,"No Audio Found on I3")/C13 -> 0.16455696 | H13: =IFERROR(COUNTIFS(Data!$D$2:$D$2284,B13,Data!$H$2:$H$2284,"<>No Audio Found on I3",Data!$I$2:$I$2284,"<>")/COUNTIFS(Data!$D$2:$D$2284,B13,Data!$H$2:$H$2284,"<>No Audio Found on I3"),0) -> 1 | I13: =COUNTIFS(Data!$D$2:$D$2284,B13,Data!$L$2:$L$2284,"Y") -> 7 | J13: =COUNTIFS(Data!$D$2:$D$2284,B13,Data!$M$2:$M$2284,"N") -> 3 | K13: 10.6 | L13: =(D13-$D$18)*100 -> -17.027895 | M13: =IF(ABS(L13)>15,"Calibrate",IF(ABS(L13)>8,"Watch","Aligned")) -> Calibrate
A14: Anas Sayed abdelmaksod | B14: Anas.Sayedabdelmaksod@vxi.com | C14: =COUNTIFS(Data!$D$2:$D$2284,B14) -> 48 | D14: =COUNTIFS(Data!$D$2:$D$2284,B14,Data!$H$2:$H$2284,"Agent Opportunity")/C14 -> 0.20833333 | E14: =COUNTIFS(Data!$D$2:$D$2284,B14,Data!$H$2:$H$2284,"Customer")/C14 -> 0.10416667 | F14: =COUNTIFS(Data!$D$2:$D$2284,B14,Data!$H$2:$H$2284,"Comcast Process/Tools")/C14 -> 0.60416667 | G14: =COUNTIFS(Data!$D$2:$D$2284,B14,Data!$H$2:$H$2284,"No Audio Found on I3")/C14 -> 0.083333333 | H14: =IFERROR(COUNTIFS(Data!$D$2:$D$2284,B14,Data!$H$2:$H$2284,"<>No Audio Found on I3",Data!$I$2:$I$2284,"<>")/COUNTIFS(Data!$D$2:$D$2284,B14,Data!$H$2:$H$2284,"<>No Audio Found on I3"),0) -> 1 | I14: =COUNTIFS(Data!$D$2:$D$2284,B14,Data!$L$2:$L$2284,"Y") -> 10 | J14: =COUNTIFS(Data!$D$2:$D$2284,B14,Data!$M$2:$M$2284,"N") -> 1 | K14: 2.2 | L14: =(D14-$D$18)*100 -> -43.030004 | M14: =IF(ABS(L14)>15,"Calibrate",IF(ABS(L14)>8,"Watch","Aligned")) -> Calibrate
A15: Kareem Abosaif | B15: kareem.abosaif@vxi.com | C15: =COUNTIFS(Data!$D$2:$D$2284,B15) -> 30 | D15: =COUNTIFS(Data!$D$2:$D$2284,B15,Data!$H$2:$H$2284,"Agent Opportunity")/C15 -> 0.66666667 | E15: =COUNTIFS(Data!$D$2:$D$2284,B15,Data!$H$2:$H$2284,"Customer")/C15 -> 0.1 | F15: =COUNTIFS(Data!$D$2:$D$2284,B15,Data!$H$2:$H$2284,"Comcast Process/Tools")/C15 -> 0.066666667 | G15: =COUNTIFS(Data!$D$2:$D$2284,B15,Data!$H$2:$H$2284,"No Audio Found on I3")/C15 -> 0.16666667 | H15: =IFERROR(COUNTIFS(Data!$D$2:$D$2284,B15,Data!$H$2:$H$2284,"<>No Audio Found on I3",Data!$I$2:$I$2284,"<>")/COUNTIFS(Data!$D$2:$D$2284,B15,Data!$H$2:$H$2284,"<>No Audio Found on I3"),0) -> 1 | I15: =COUNTIFS(Data!$D$2:$D$2284,B15,Data!$L$2:$L$2284,"Y") -> 5 | J15: =COUNTIFS(Data!$D$2:$D$2284,B15,Data!$M$2:$M$2284,"N") -> 0 | K15: 5.1 | L15: =(D15-$D$18)*100 -> 2.803329 | M15: =IF(ABS(L15)>15,"Calibrate",IF(ABS(L15)>8,"Watch","Aligned")) -> Aligned
A16: Omar Mansour (Omar Ali Mohamed) | B16: Omar.Mansour@vxi.com | C16: =COUNTIFS(Data!$D$2:$D$2284,B16) -> 29 | D16: =COUNTIFS(Data!$D$2:$D$2284,B16,Data!$H$2:$H$2284,"Agent Opportunity")/C16 -> 0.37931034 | E16: =COUNTIFS(Data!$D$2:$D$2284,B16,Data!$H$2:$H$2284,"Customer")/C16 -> 0.13793103 | F16: =COUNTIFS(Data!$D$2:$D$2284,B16,Data!$H$2:$H$2284,"Comcast Process/Tools")/C16 -> 0.34482759 | G16: =COUNTIFS(Data!$D$2:$D$2284,B16,Data!$H$2:$H$2284,"No Audio Found on I3")/C16 -> 0.13793103 | H16: =IFERROR(COUNTIFS(Data!$D$2:$D$2284,B16,Data!$H$2:$H$2284,"<>No Audio Found on I3",Data!$I$2:$I$2284,"<>")/COUNTIFS(Data!$D$2:$D$2284,B16,Data!$H$2:$H$2284,"<>No Audio Found on I3"),0) -> 1 | I16: =COUNTIFS(Data!$D$2:$D$2284,B16,Data!$L$2:$L$2284,"Y") -> 4 | J16: =COUNTIFS(Data!$D$2:$D$2284,B16,Data!$M$2:$M$2284,"N") -> 2 | K16: 11.8 | L16: =(D16-$D$18)*100 -> -25.932303 | M16: =IF(ABS(L16)>15,"Calibrate",IF(ABS(L16)>8,"Watch","Aligned")) -> Calibrate
A17: Abdelrahman Mokhtar | B17: abdelrahman.mokhtar@vxi.com | C17: =COUNTIFS(Data!$D$2:$D$2284,B17) -> 21 | D17: =COUNTIFS(Data!$D$2:$D$2284,B17,Data!$H$2:$H$2284,"Agent Opportunity")/C17 -> 0.61904762 | E17: =COUNTIFS(Data!$D$2:$D$2284,B17,Data!$H$2:$H$2284,"Customer")/C17 -> 0.095238095 | F17: =COUNTIFS(Data!$D$2:$D$2284,B17,Data!$H$2:$H$2284,"Comcast Process/Tools")/C17 -> 0.19047619 | G17: =COUNTIFS(Data!$D$2:$D$2284,B17,Data!$H$2:$H$2284,"No Audio Found on I3")/C17 -> 0.095238095 | H17: =IFERROR(COUNTIFS(Data!$D$2:$D$2284,B17,Data!$H$2:$H$2284,"<>No Audio Found on I3",Data!$I$2:$I$2284,"<>")/COUNTIFS(Data!$D$2:$D$2284,B17,Data!$H$2:$H$2284,"<>No Audio Found on I3"),0) -> 1 | I17: =COUNTIFS(Data!$D$2:$D$2284,B17,Data!$L$2:$L$2284,"Y") -> 10 | J17: =COUNTIFS(Data!$D$2:$D$2284,B17,Data!$M$2:$M$2284,"N") -> 0 | K17: 85.2 | L17: =(D17-$D$18)*100 -> -1.9585758 | M17: =IF(ABS(L17)>15,"Calibrate",IF(ABS(L17)>8,"Watch","Aligned")) -> Aligned
A18: ACCOUNT | C18: =SUM(C6:C17) -> 2283 | D18: =COUNTIFS(Data!$H$2:$H$2284,"Agent Opportunity")/C18 -> 0.63863338 | E18: =COUNTIFS(Data!$H$2:$H$2284,"Customer")/C18 -> 0.08935611 | F18: =COUNTIFS(Data!$H$2:$H$2284,"Comcast Process/Tools")/C18 -> 0.17564608 | G18: =COUNTIFS(Data!$H$2:$H$2284,"No Audio Found on I3")/C18 -> 0.081909768 | H18: =COUNTIFS(Data!$H$2:$H$2284,"<>No Audio Found on I3",Data!$I$2:$I$2284,"<>")/COUNTIFS(Data!$H$2:$H$2284,"<>No Audio Found on I3") -> 1 | I18: =SUM(I6:I17) -> 260 | J18: =SUM(J6:J17) -> 36 | K18: 3.8
A19: Median Min/Scrub computed in Python (Completion−Start). Very low (<1 min) = possible bulk/form-prefill; very high = form left open. Flag thresholds: >15 pts Calibrate, >8 pts Watch (assumption).

Sheet RCA Drivers
A1: Detractor Drivers — Tier 1 & Tier 2
A2: What is driving detractors on the account, and where Omar differs
A5: Tier 1 RCA
A6: RCA | B6: Account # | C6: Account % | D6: Omar # | E6: Omar % | F6: Gap (pts) | H6: Account % denominator 2,283 = total rows (hardcoded from source)
A7: Agent Opportunity | B7: =COUNTIFS(Data!$H$2:$H$2284,A7) -> 1458 | C7: =B7/2283 -> 0.63863338 | D7: =COUNTIFS(Data!$H$2:$H$2284,A7,Data!$D$2:$D$2284,"Omar.Mansour@vxi.com") -> 11 | E7: =D7/COUNTIFS(Data!$D$2:$D$2284,"Omar.Mansour@vxi.com") -> 0.37931034 | F7: =(E7-C7)*100 -> -25.932303
A8: Customer | B8: =COUNTIFS(Data!$H$2:$H$2284,A8) -> 204 | C8: =B8/2283 -> 0.08935611 | D8: =COUNTIFS(Data!$H$2:$H$2284,A8,Data!$D$2:$D$2284,"Omar.Mansour@vxi.com") -> 4 | E8: =D8/COUNTIFS(Data!$D$2:$D$2284,"Omar.Mansour@vxi.com") -> 0.13793103 | F8: =(E8-C8)*100 -> 4.8574924
A9: Comcast Process/Tools | B9: =COUNTIFS(Data!$H$2:$H$2284,A9) -> 401 | C9: =B9/2283 -> 0.17564608 | D9: =COUNTIFS(Data!$H$2:$H$2284,A9,Data!$D$2:$D$2284,"Omar.Mansour@vxi.com") -> 10 | E9: =D9/COUNTIFS(Data!$D$2:$D$2284,"Omar.Mansour@vxi.com") -> 0.34482759 | F9: =(E9-C9)*100 -> 16.918151
A10: No Audio Found on I3 | B10: =COUNTIFS(Data!$H$2:$H$2284,A10) -> 187 | C10: =B10/2283 -> 0.081909768 | D10: =COUNTIFS(Data!$H$2:$H$2284,A10,Data!$D$2:$D$2284,"Omar.Mansour@vxi.com") -> 4 | E10: =D10/COUNTIFS(Data!$D$2:$D$2284,"Omar.Mansour@vxi.com") -> 0.13793103 | F10: =(E10-C10)*100 -> 5.6021267
A11: VXI Process/Tools | B11: =COUNTIFS(Data!$H$2:$H$2284,A11) -> 33 | C11: =B11/2283 -> 0.014454665 | D11: =COUNTIFS(Data!$H$2:$H$2284,A11,Data!$D$2:$D$2284,"Omar.Mansour@vxi.com") -> 0 | E11: =D11/COUNTIFS(Data!$D$2:$D$2284,"Omar.Mansour@vxi.com") -> 0 | F11: =(E11-C11)*100 -> -1.4454665
A14: Tier 2 — Agent Opportunity
A15: RCA T2 | B15: Account # | C15: % of Agent Opportunity | D15: Omar # | E15: Cumulative %
A16: Call Handling | B16: =COUNTIFS(Data!$H$2:$H$2284,"Agent Opportunity",Data!$I$2:$I$2284,A16) -> 596 | C16: =B16/COUNTIFS(Data!$H$2:$H$2284,"Agent Opportunity") -> 0.40877915 | D16: =COUNTIFS(Data!$H$2:$H$2284,"Agent Opportunity",Data!$I$2:$I$2284,A16,Data!$D$2:$D$2284,"Omar.Mansour@vxi.com") -> 0 | E16: =C16 -> 0.40877915
A17: Communication / Soft Skills | B17: =COUNTIFS(Data!$H$2:$H$2284,"Agent Opportunity",Data!$I$2:$I$2284,A17) -> 353 | C17: =B17/COUNTIFS(Data!$H$2:$H$2284,"Agent Opportunity") -> 0.24211248 | D17: =COUNTIFS(Data!$H$2:$H$2284,"Agent Opportunity",Data!$I$2:$I$2284,A17,Data!$D$2:$D$2284,"Omar.Mansour@vxi.com") -> 6 | E17: =E16+C17 -> 0.65089163
A18: Knowledge Gap | B18: =COUNTIFS(Data!$H$2:$H$2284,"Agent Opportunity",Data!$I$2:$I$2284,A18) -> 106 | C18: =B18/COUNTIFS(Data!$H$2:$H$2284,"Agent Opportunity") -> 0.072702332 | D18: =COUNTIFS(Data!$H$2:$H$2284,"Agent Opportunity",Data!$I$2:$I$2284,A18,Data!$D$2:$D$2284,"Omar.Mansour@vxi.com") -> 1 | E18: =E17+C18 -> 0.72359396
A19: Excessive Hold/Mute | B19: =COUNTIFS(Data!$H$2:$H$2284,"Agent Opportunity",Data!$I$2:$I$2284,A19) -> 99 | C19: =B19/COUNTIFS(Data!$H$2:$H$2284,"Agent Opportunity") -> 0.067901235 | D19: =COUNTIFS(Data!$H$2:$H$2284,"Agent Opportunity",Data!$I$2:$I$2284,A19,Data!$D$2:$D$2284,"Omar.Mansour@vxi.com") -> 2 | E19: =E18+C19 -> 0.7914952
A20: Incorrect/ Incomplete Resolution | B20: =COUNTIFS(Data!$H$2:$H$2284,"Agent Opportunity",Data!$I$2:$I$2284,A20) -> 92 | C20: =B20/COUNTIFS(Data!$H$2:$H$2284,"Agent Opportunity") -> 0.063100137 | D20: =COUNTIFS(Data!$H$2:$H$2284,"Agent Opportunity",Data!$I$2:$I$2284,A20,Data!$D$2:$D$2284,"Omar.Mansour@vxi.com") -> 1 | E20: =E19+C20 -> 0.85459534
A21: Ownership | B21: =COUNTIFS(Data!$H$2:$H$2284,"Agent Opportunity",Data!$I$2:$I$2284,A21) -> 72 | C21: =B21/COUNTIFS(Data!$H$2:$H$2284,"Agent Opportunity") -> 0.049382716 | D21: =COUNTIFS(Data!$H$2:$H$2284,"Agent Opportunity",Data!$I$2:$I$2284,A21,Data!$D$2:$D$2284,"Omar.Mansour@vxi.com") -> 1 | E21: =E20+C21 -> 0.90397805
A22: Tone - Pace | B22: =COUNTIFS(Data!$H$2:$H$2284,"Agent Opportunity",Data!$I$2:$I$2284,A22) -> 31 | C22: =B22/COUNTIFS(Data!$H$2:$H$2284,"Agent Opportunity") -> 0.021262003 | D22: =COUNTIFS(Data!$H$2:$H$2284,"Agent Opportunity",Data!$I$2:$I$2284,A22,Data!$D$2:$D$2284,"Omar.Mansour@vxi.com") -> 0 | E22: =E21+C22 -> 0.92524005
A23: Wrong ITG | B23: =COUNTIFS(Data!$H$2:$H$2284,"Agent Opportunity",Data!$I$2:$I$2284,A23) -> 28 | C23: =B23/COUNTIFS(Data!$H$2:$H$2284,"Agent Opportunity") -> 0.01920439 | D23: =COUNTIFS(Data!$H$2:$H$2284,"Agent Opportunity",Data!$I$2:$I$2284,A23,Data!$D$2:$D$2284,"Omar.Mansour@vxi.com") -> 0 | E23: =E22+C23 -> 0.94444444
A24: Incorrect/Incomplete ITG | B24: =COUNTIFS(Data!$H$2:$H$2284,"Agent Opportunity",Data!$I$2:$I$2284,A24) -> 28 | C24: =B24/COUNTIFS(Data!$H$2:$H$2284,"Agent Opportunity") -> 0.01920439 | D24: =COUNTIFS(Data!$H$2:$H$2284,"Agent Opportunity",Data!$I$2:$I$2284,A24,Data!$D$2:$D$2284,"Omar.Mansour@vxi.com") -> 0 | E24: =E23+C24 -> 0.96364883
A25: Customer Education - Setting Expectations | B25: =COUNTIFS(Data!$H$2:$H$2284,"Agent Opportunity",Data!$I$2:$I$2284,A25) -> 25 | C25: =B25/COUNTIFS(Data!$H$2:$H$2284,"Agent Opportunity") -> 0.017146776 | D25: =COUNTIFS(Data!$H$2:$H$2284,"Agent Opportunity",Data!$I$2:$I$2284,A25,Data!$D$2:$D$2284,"Omar.Mansour@vxi.com") -> 0 | E25: =E24+C25 -> 0.98079561
A26: Did not ask discovery questions | B26: =COUNTIFS(Data!$H$2:$H$2284,"Agent Opportunity",Data!$I$2:$I$2284,A26) -> 13 | C26: =B26/COUNTIFS(Data!$H$2:$H$2284,"Agent Opportunity") -> 0.0089163237 | D26: =COUNTIFS(Data!$H$2:$H$2284,"Agent Opportunity",Data!$I$2:$I$2284,A26,Data!$D$2:$D$2284,"Omar.Mansour@vxi.com") -> 0 | E26: =E25+C26 -> 0.98971193
A27: Missing ITG | B27: =COUNTIFS(Data!$H$2:$H$2284,"Agent Opportunity",Data!$I$2:$I$2284,A27) -> 8 | C27: =B27/COUNTIFS(Data!$H$2:$H$2284,"Agent Opportunity") -> 0.0054869684 | D27: =COUNTIFS(Data!$H$2:$H$2284,"Agent Opportunity",Data!$I$2:$I$2284,A27,Data!$D$2:$D$2284,"Omar.Mansour@vxi.com") -> 0 | E27: =E26+C27 -> 0.9951989
A28: Language Proficiency | B28: =COUNTIFS(Data!$H$2:$H$2284,"Agent Opportunity",Data!$I$2:$I$2284,A28) -> 5 | C28: =B28/COUNTIFS(Data!$H$2:$H$2284,"Agent Opportunity") -> 0.0034293553 | D28: =COUNTIFS(Data!$H$2:$H$2284,"Agent Opportunity",Data!$I$2:$I$2284,A28,Data!$D$2:$D$2284,"Omar.Mansour@vxi.com") -> 0 | E28: =E27+C28 -> 0.99862826
A29: Tools Navigation/Utilization | B29: =COUNTIFS(Data!$H$2:$H$2284,"Agent Opportunity",Data!$I$2:$I$2284,A29) -> 2 | C29: =B29/COUNTIFS(Data!$H$2:$H$2284,"Agent Opportunity") -> 0.0013717421 | D29: =COUNTIFS(Data!$H$2:$H$2284,"Agent Opportunity",Data!$I$2:$I$2284,A29,Data!$D$2:$D$2284,"Omar.Mansour@vxi.com") -> 0 | E29: =E28+C29 -> 1
A32: Tier 2 — Comcast Process/Tools
A33: RCA T2 | B33: Account # | C33: % of Comcast Process/Tools | D33: Omar # | E33: Cumulative %
A34: Dissatisfied with service | B34: =COUNTIFS(Data!$H$2:$H$2284,"Comcast Process/Tools",Data!$I$2:$I$2284,A34) -> 158 | C34: =B34/COUNTIFS(Data!$H$2:$H$2284,"Comcast Process/Tools") -> 0.39401496 | D34: =COUNTIFS(Data!$H$2:$H$2284,"Comcast Process/Tools",Data!$I$2:$I$2284,A34,Data!$D$2:$D$2284,"Omar.Mansour@vxi.com") -> 3 | E34: =C34 -> 0.39401496
A35: Complaints about the technician | B35: =COUNTIFS(Data!$H$2:$H$2284,"Comcast Process/Tools",Data!$I$2:$I$2284,A35) -> 112 | C35: =B35/COUNTIFS(Data!$H$2:$H$2284,"Comcast Process/Tools") -> 0.27930175 | D35: =COUNTIFS(Data!$H$2:$H$2284,"Comcast Process/Tools",Data!$I$2:$I$2284,A35,Data!$D$2:$D$2284,"Omar.Mansour@vxi.com") -> 1 | E35: =E34+C35 -> 0.67331671
A36: Outage | B36: =COUNTIFS(Data!$H$2:$H$2284,"Comcast Process/Tools",Data!$I$2:$I$2284,A36) -> 48 | C36: =B36/COUNTIFS(Data!$H$2:$H$2284,"Comcast Process/Tools") -> 0.11970075 | D36: =COUNTIFS(Data!$H$2:$H$2284,"Comcast Process/Tools",Data!$I$2:$I$2284,A36,Data!$D$2:$D$2284,"Omar.Mansour@vxi.com") -> 3 | E36: =E35+C36 -> 0.79301746
A37: IVR / Routing | B37: =COUNTIFS(Data!$H$2:$H$2284,"Comcast Process/Tools",Data!$I$2:$I$2284,A37) -> 26 | C37: =B37/COUNTIFS(Data!$H$2:$H$2284,"Comcast Process/Tools") -> 0.064837905 | D37: =COUNTIFS(Data!$H$2:$H$2284,"Comcast Process/Tools",Data!$I$2:$I$2284,A37,Data!$D$2:$D$2284,"Omar.Mansour@vxi.com") -> 0 | E37: =E36+C37 -> 0.85785536
A38: Comcast Restriction | B38: =COUNTIFS(Data!$H$2:$H$2284,"Comcast Process/Tools",Data!$I$2:$I$2284,A38) -> 23 | C38: =B38/COUNTIFS(Data!$H$2:$H$2284,"Comcast Process/Tools") -> 0.057356608 | D38: =COUNTIFS(Data!$H$2:$H$2284,"Comcast Process/Tools",Data!$I$2:$I$2284,A38,Data!$D$2:$D$2284,"Omar.Mansour@vxi.com") -> 0 | E38: =E37+C38 -> 0.91521197
A39: Comcast Restriction (add on the comment which Restriction) | B39: =COUNTIFS(Data!$H$2:$H$2284,"Comcast Process/Tools",Data!$I$2:$I$2284,A39) -> 21 | C39: =B39/COUNTIFS(Data!$H$2:$H$2284,"Comcast Process/Tools") -> 0.052369077 | D39: =COUNTIFS(Data!$H$2:$H$2284,"Comcast Process/Tools",Data!$I$2:$I$2284,A39,Data!$D$2:$D$2284,"Omar.Mansour@vxi.com") -> 3 | E39: =E38+C39 -> 0.96758105
A40: Comcast Tools Outage or update | B40: =COUNTIFS(Data!$H$2:$H$2284,"Comcast Process/Tools",Data!$I$2:$I$2284,A40) -> 13 | C40: =B40/COUNTIFS(Data!$H$2:$H$2284,"Comcast Process/Tools") -> 0.032418953 | D40: =COUNTIFS(Data!$H$2:$H$2284,"Comcast Process/Tools",Data!$I$2:$I$2284,A40,Data!$D$2:$D$2284,"Omar.Mansour@vxi.com") -> 0 | E40: =E39+C40 -> 1
A43: Tier 2 — Customer
A44: RCA T2 | B44: Account # | C44: % of Customer | D44: Omar # | E44: Cumulative %
A45: Another Agent's Opportunity | B45: =COUNTIFS(Data!$H$2:$H$2284,"Customer",Data!$I$2:$I$2284,A45) -> 103 | C45: =B45/COUNTIFS(Data!$H$2:$H$2284,"Customer") -> 0.50490196 | D45: =COUNTIFS(Data!$H$2:$H$2284,"Customer",Data!$I$2:$I$2284,A45,Data!$D$2:$D$2284,"Omar.Mansour@vxi.com") -> 2 | E45: =C45 -> 0.50490196
A46: Customer Provided the agent positive feedback | B46: =COUNTIFS(Data!$H$2:$H$2284,"Customer",Data!$I$2:$I$2284,A46) -> 74 | C46: =B46/COUNTIFS(Data!$H$2:$H$2284,"Customer") -> 0.3627451 | D46: =COUNTIFS(Data!$H$2:$H$2284,"Customer",Data!$I$2:$I$2284,A46,Data!$D$2:$D$2284,"Omar.Mansour@vxi.com") -> 2 | E46: =E45+C46 -> 0.86764706
A47: Customer Demanded for a US Rep | B47: =COUNTIFS(Data!$H$2:$H$2284,"Customer",Data!$I$2:$I$2284,A47) -> 15 | C47: =B47/COUNTIFS(Data!$H$2:$H$2284,"Customer") -> 0.073529412 | D47: =COUNTIFS(Data!$H$2:$H$2284,"Customer",Data!$I$2:$I$2284,A47,Data!$D$2:$D$2284,"Omar.Mansour@vxi.com") -> 0 | E47: =E46+C47 -> 0.94117647
A48: Customer Preferred to speak to the previous agent | B48: =COUNTIFS(Data!$H$2:$H$2284,"Customer",Data!$I$2:$I$2284,A48) -> 12 | C48: =B48/COUNTIFS(Data!$H$2:$H$2284,"Customer") -> 0.058823529 | D48: =COUNTIFS(Data!$H$2:$H$2284,"Customer",Data!$I$2:$I$2284,A48,Data!$D$2:$D$2284,"Omar.Mansour@vxi.com") -> 0 | E48: =E47+C48 -> 1
...

Sheet Repeat Agents (BPID)
A1: Repeat Detractor Agents — Top 25 BPIDs by Agent Opportunity
A2: Coaching priority list for team leaders
A5: BPID | B5: Agent Opp # | C5: Total Scrubs | D5: Agent Opp % | E5: Top T2 Driver | F5: Top T2 # | G5: Last Scrub Date | H5: Last 30 Days AO #
A6: bp-hawad742 | B6: =COUNTIFS(Data!$E$2:$E$2284,A6,Data!$H$2:$H$2284,"Agent Opportunity") -> 47 | C6: =COUNTIFS(Data!$E$2:$E$2284,A6) -> 63 | D6: =B6/C6 -> 0.74603175 | E6: Call Handling | F6: =COUNTIFS(Data!$E$2:$E$2284,A6,Data!$H$2:$H$2284,"Agent Opportunity",Data!$I$2:$I$2284,E6) -> 30 | G6: 46301 | H6: =COUNTIFS(Data!$E$2:$E$2284,A6,Data!$H$2:$H$2284,"Agent Opportunity",Data!$B$2:$B$2284,">="&DATE(2026,9,7)) -> 2
A7: bp-gghane435 | B7: =COUNTIFS(Data!$E$2:$E$2284,A7,Data!$H$2:$H$2284,"Agent Opportunity") -> 42 | C7: =COUNTIFS(Data!$E$2:$E$2284,A7) -> 65 | D7: =B7/C7 -> 0.64615385 | E7: Call Handling | F7: =COUNTIFS(Data!$E$2:$E$2284,A7,Data!$H$2:$H$2284,"Agent Opportunity",Data!$I$2:$I$2284,E7) -> 21 | G7: 46301 | H7: =COUNTIFS(Data!$E$2:$E$2284,A7,Data!$H$2:$H$2284,"Agent Opportunity",Data!$B$2:$B$2284,">="&DATE(2026,9,7)) -> 4
A8: bp-watta702 | B8: =COUNTIFS(Data!$E$2:$E$2284,A8,Data!$H$2:$H$2284,"Agent Opportunity") -> 30 | C8: =COUNTIFS(Data!$E$2:$E$2284,A8) -> 35 | D8: =B8/C8 -> 0.85714286 | E8: Call Handling | F8: =COUNTIFS(Data!$E$2:$E$2284,A8,Data!$H$2:$H$2284,"Agent Opportunity",Data!$I$2:$I$2284,E8) -> 23 | G8: 46275 | H8: =COUNTIFS(Data!$E$2:$E$2284,A8,Data!$H$2:$H$2284,"Agent Opportunity",Data!$B$2:$B$2284,">="&DATE(2026,9,7)) -> 1
A9: bp-anail804 | B9: =COUNTIFS(Data!$E$2:$E$2284,A9,Data!$H$2:$H$2284,"Agent Opportunity") -> 30 | C9: =COUNTIFS(Data!$E$2:$E$2284,A9) -> 36 | D9: =B9/C9 -> 0.83333333 | E9: Communication / Soft Skills | F9: =COUNTIFS(Data!$E$2:$E$2284,A9,Data!$H$2:$H$2284,"Agent Opportunity",Data!$I$2:$I$2284,E9) -> 11 | G9: 46302 | H9: =COUNTIFS(Data!$E$2:$E$2284,A9,Data!$H$2:$H$2284,"Agent Opportunity",Data!$B$2:$B$2284,">="&DATE(2026,9,7)) -> 18
A10: bp-jhaana620 | B10: =COUNTIFS(Data!$E$2:$E$2284,A10,Data!$H$2:$H$2284,"Agent Opportunity") -> 29 | C10: =COUNTIFS(Data!$E$2:$E$2284,A10) -> 37 | D10: =B10/C10 -> 0.78378378 | E10: Call Handling | F10: =COUNTIFS(Data!$E$2:$E$2284,A10,Data!$H$2:$H$2284,"Agent Opportunity",Data!$I$2:$I$2284,E10) -> 13 | G10: 46302 | H10: =COUNTIFS(Data!$E$2:$E$2284,A10,Data!$H$2:$H$2284,"Agent Opportunity",Data!$B$2:$B$2284,">="&DATE(2026,9,7)) -> 4
A11: bp-amorsy796 | B11: =COUNTIFS(Data!$E$2:$E$2284,A11,Data!$H$2:$H$2284,"Agent Opportunity") -> 26 | C11: =COUNTIFS(Data!$E$2:$E$2284,A11) -> 43 | D11: =B11/C11 -> 0.60465116 | E11: Call Handling | F11: =COUNTIFS(Data!$E$2:$E$2284,A11,Data!$H$2:$H$2284,"Agent Opportunity",Data!$I$2:$I$2284,E11) -> 20 | G11: 46250 | H11: =COUNTIFS(Data!$E$2:$E$2284,A11,Data!$H$2:$H$2284,"Agent Opportunity",Data!$B$2:$B$2284,">="&DATE(2026,9,7)) -> 0
A12: bp-asakr617 | B12: =COUNTIFS(Data!$E$2:$E$2284,A12,Data!$H$2:$H$2284,"Agent Opportunity") -> 26 | C12: =COUNTIFS(Data!$E$2:$E$2284,A12) -> 31 | D12: =B12/C12 -> 0.83870968 | E12: Call Handling | F12: =COUNTIFS(Data!$E$2:$E$2284,A12,Data!$H$2:$H$2284,"Agent Opportunity",Data!$I$2:$I$2284,E12) -> 13 | G12: 46299 | H12: =COUNTIFS(Data!$E$2:$E$2284,A12,Data!$H$2:$H$2284,"Agent Opportunity",Data!$B$2:$B$2284,">="&DATE(2026,9,7)) -> 3
A13: bp-dmadbo843 | B13: =COUNTIFS(Data!$E$2:$E$2284,A13,Data!$H$2:$H$2284,"Agent Opportunity") -> 23 | C13: =COUNTIFS(Data!$E$2:$E$2284,A13) -> 27 | D13: =B13/C13 -> 0.85185185 | E13: Call Handling | F13: =COUNTIFS(Data!$E$2:$E$2284,A13,Data!$H$2:$H$2284,"Agent Opportunity",Data!$I$2:$I$2284,E13) -> 9 | G13: 46267 | H13: =COUNTIFS(Data!$E$2:$E$2284,A13,Data!$H$2:$H$2284,"Agent Opportunity",Data!$B$2:$B$2284,">="&DATE(2026,9,7)) -> 0
A14: bp-aetman106 | B14: =COUNTIFS(Data!$E$2:$E$2284,A14,Data!$H$2:$H$2284,"Agent Opportunity") -> 22 | C14: =COUNTIFS(Data!$E$2:$E$2284,A14) -> 41 | D14: =B14/C14 -> 0.53658537 | E14: Call Handling | F14: =COUNTIFS(Data!$E$2:$E$2284,A14,Data!$H$2:$H$2284,"Agent Opportunity",Data!$I$2:$I$2284,E14) -> 12 | G14: 46275 | H14: =COUNTIFS(Data!$E$2:$E$2284,A14,Data!$H$2:$H$2284,"Agent Opportunity",Data!$B$2:$B$2284,">="&DATE(2026,9,7)) -> 1
A15: bp-ygawda039 | B15: =COUNTIFS(Data!$E$2:$E$2284,A15,Data!$H$2:$H$2284,"Agent Opportunity") -> 21 | C15: =COUNTIFS(Data!$E$2:$E$2284,A15) -> 46 | D15: =B15/C15 -> 0.45652174 | E15: Call Handling | F15: =COUNTIFS(Data!$E$2:$E$2284,A15,Data!$H$2:$H$2284,"Agent Opportunity",Data!$I$2:$I$2284,E15) -> 11 | G15: 46275 | H15: =COUNTIFS(Data!$E$2:$E$2284,A15,Data!$H$2:$H$2284,"Agent Opportunity",Data!$B$2:$B$2284,">="&DATE(2026,9,7)) -> 1
A16: bp-onabwy363 | B16: =COUNTIFS(Data!$E$2:$E$2284,A16,Data!$H$2:$H$2284,"Agent Opportunity") -> 21 | C16: =COUNTIFS(Data!$E$2:$E$2284,A16) -> 27 | D16: =B16/C16 -> 0.77777778 | E16: Call Handling | F16: =COUNTIFS(Data!$E$2:$E$2284,A16,Data!$H$2:$H$2284,"Agent Opportunity",Data!$I$2:$I$2284,E16) -> 19 | G16: 46236 | H16: =COUNTIFS(Data!$E$2:$E$2284,A16,Data!$H$2:$H$2284,"Agent Opportunity",Data!$B$2:$B$2284,">="&DATE(2026,9,7)) -> 0
A17: bp-ehazem048 | B17: =COUNTIFS(Data!$E$2:$E$2284,A17,Data!$H$2:$H$2284,"Agent Opportunity") -> 20 | C17: =COUNTIFS(Data!$E$2:$E$2284,A17) -> 28 | D17: =B17/C17 -> 0.71428571 | E17: Call Handling | F17: =COUNTIFS(Data!$E$2:$E$2284,A17,Data!$H$2:$H$2284,"Agent Opportunity",Data!$I$2:$I$2284,E17) -> 6 | G17: 46258 | H17: =COUNTIFS(Data!$E$2:$E$2284,A17,Data!$H$2:$H$2284,"Agent Opportunity",Data!$B$2:$B$2284,">="&DATE(2026,9,7)) -> 0
... A30: bp-mhalee702 | B30: =COUNTIFS(Data!$E$2:$E$2284,A30,Data!$H$2:$H$2284,"Agent Opportunity") -> 16 | C30: =COUNTIFS(Data!$E$2:$E$2284,A30) -> 23 | D30: =B30/C30 -> 0.69565217 | E30: Call Handling | F30: =COUNTIFS(Data!$E$2:$E$2284,A30,Data!$H$2:$H$2284,"Agent Opportunity",Data!$I$2:$I$2284,E30) -> 10 | G30: 46302 | H30: =COUNTIFS(Data!$E$2:$E$2284,A30,Data!$H$2:$H$2284,"Agent Opportunity",Data!$B$2:$B$2284,">="&DATE(2026,9,7)) -> 1
A32: Top T2 Driver & Last Scrub Date computed in Python. Last 30 days = scrubs on/after 07-Sep-2026. Red = 3+ AO detractors in last 30 days → active coaching.

Sheet Data
A1: ID | B1: Scrub Date | C1: Scrubber | D1: Email | E1: BPID | F1: Survey ID | G1: Survey Date | H1: RCA (Clean) | I1: RCA T2 (Clean) | J1: Comment | K1: Handle Min | L1: Dup Survey ID | M1: BPID Format OK | N1: Original RCA | O1: Start time | P1: Completion time | R1: Notes
A2: 207 | B2: 46113 | C2: Shrouk Ahmed | D2: Shrouk.Hanafy@vxi.com | E2: bp-mashou692 | F2: 2133806148 | H2: Agent Opportunity | I2: Call Handling | J2: lack of empathy and very long mute | K2: 4.1 | L2: Y | M2: Y | N2: Agent Opportunity | O2: 46113.561 | P2: 46113.564 | R2: Source: NPS_Scrubbing1-2283.xlsx (uploaded by user), 2,283 rows.
A3: 208 | B3: 46113 | C3: Shrouk Ahmed | D3: Shrouk.Hanafy@vxi.com | E3: bp-mashou692 | F3: 2132948976 | H3: Comcast Process/Tools | I3: Dissatisfied with service | J3: customer dissatisfied with the bill | K3: 22.9 | L3: N | M3: Y | N3: Comcast Process or Tools | O3: 46113.564 | P3: 46113.58 | R3: Scrub Date = date of "Start time" (when the scrub was submitted).
A4: 209 | B4: 46113 | C4: Shrouk Ahmed | D4: Shrouk.Hanafy@vxi.com | E4: bp-mashou692 | F4: 2133427132 | H4: No Audio Found on I3 | K4: 11.2 | L4: N | M4: Y | N4: No Audio Found on I3 | O4: 46113.58 | P4: 46113.588 | R4: RCA (Clean) merges label variants: "Comcast Policy/Process or Tools"+"Comcast Process or Tools" -> Comcast Process/Tools; same for VXI.
A5: 210 | B5: 46113 | C5: Shrouk Ahmed | D5: Shrouk.Hanafy@vxi.com | E5: bp-mashou692 | F5: 2133806148 | H5: Agent Opportunity | I5: Call Handling | J5: long silence gap, lack of empathy | K5: 18.8 | L5: Y | M5: Y | N5: Agent Opportunity | O5: 46113.588 | P5: 46113.601 | R5: RCA T2 (Clean) = first filled T2 column (Agent/Customer/Comcast/VXI), label variants merged.
A6: 211 | B6: 46113 | C6: Shrouk Ahmed | D6: Shrouk.Hanafy@vxi.com | E6: bp-mashou692 | F6: 2133806148 | H6: Agent Opportunity | I6: Call Handling | J6: silence gap and lack of empathy | K6: 1 | L6: Y | M6: Y | N6: Agent Opportunity | O6: 46113.602 | P6: 46113.603 | R6: Handle Min = Completion time - Start time (minutes). Dup Survey ID / BPID Format computed in Python at build time.
A7: 212 | B7: 46113 | C7: Shrouk Ahmed | D7: Shrouk.Hanafy@vxi.com | E7: bp-mashou692 | F7: 2135586426 | H7: Customer | I7: Another Agent's Opportunity | J7: customer is satisfied from Ashour dissatisfied with the service and the previous agent, he didn't call after Ashour | K7: 5.9 | L7: N | M7: Y | N7: Customer | O7: 46113.603 | P7: 46113.607 | R7: Omar Mansour submits under display name "Omar Ali Mohamed" (Omar.Mansour@vxi.com).
A8: 213 | B8: 46113 | C8: Shereen Kamal | D8: shereen.kamal@vxi.com | E8: bp-hawad742 | F8: 10009054011774557093 | H8: Agent Opportunity | I8: Call Handling | J8: Point of Improv: -Tone of Voice (Not willing to help) -Monotonic -Active listening -Guessing instead of understand the issue -Attitude -Got the wrong case and arguing -talking with high pitch comes with attitude **Saying whisperly at 4:28 (How am I supposed to do this? ) - didn't own the issue **At 5:22 (I don't understand why i'm doing this?) which is not professional and reflect for the poor skills ** the cx asked for a manger at 6:40 followed by dead air from the agent till 6:52 Followed by Hold Without Permission ** 9 Hold without permission or refreshing (the agent refreshed the cx with dead air) **7 Silence Gap bettwen each hold instead of refreshing the cx - not using any soft skills to handel the customer even while offering an alternative | K8: 5.6 | L8: N | M8: Y | N8: Agent Opportunity | O8: 46113.905 | P8: 46113.909
A9: 215 | B9: 46113 | C9: Shereen Kamal | D9: shereen.kamal@vxi.com | E9: bp-hawad742 | F9: 10005025441774634266 | H9: Agent Opportunity | I9: Call Handling | J9: - the agent shoulden't confirm or disclose the full account number as the caller not account holder - the agent is driking somthing and the sound so obvious (3:09 ---3:25----3:29---3:40 ) - 5:29 the agent said ""So what would you like to do right now just to know"- "I just said that there is an amount needs to be paid so I'm not gonna be able to activate it " at 5:47 | K9: 3.2 | L9: N | M9: Y | N9: Agent Opportunity | O9: 46113.907 | P9: 46113.909
