Workbook

Sheet Dashboard
A1: Cairo Repair TSX – Sales Performance Dashboard
A2: Source: Sales Tracker (Microsoft Forms) 22 Jul 2026 – 08 Oct 2026 + TSX Roster. Days are business days (shift 15:00 → 07:00 next morning). Change the yellow cells; every table, rank and chart recalculates.
A4: CONTROL PANEL | E4: Total Units | G4: XM Lines | I4: GSR Units | K4: Submissions | M4: Active Sellers
A5: From Date | C5: 46297 | E5: =SUMIFS(Sales_Data!$O$2:$O$3520,Sales_Data!$C$2:$C$3520,">="&Dashboard!$C$5,Sales_Data!$C$2:$C$3520,"<="&Dashboard!$C$6,Sales_Data!$H$2:$H$3520,Dashboard!$C$14,Sales_Data!$I$2:$I$3520,Dashboard!$C$15,Sales_Data!$AE$2:$AE$3520,1) -> 565 | G5: =SUMIFS(Sales_Data!$M$2:$M$3520,Sales_Data!$C$2:$C$3520,">="&Dashboard!$C$5,Sales_Data!$C$2:$C$3520,"<="&Dashboard!$C$6,Sales_Data!$H$2:$H$3520,Dashboard!$C$14,Sales_Data!$I$2:$I$3520,Dashboard!$C$15,Sales_Data!$AE$2:$AE$3520,1) -> 149 | I5: =SUMIFS(Sales_Data!$N$2:$N$3520,Sales_Data!$C$2:$C$3520,">="&Dashboard!$C$5,Sales_Data!$C$2:$C$3520,"<="&Dashboard!$C$6,Sales_Data!$H$2:$H$3520,Dashboard!$C$14,Sales_Data!$I$2:$I$3520,Dashboard!$C$15,Sales_Data!$AE$2:$AE$3520,1) -> 416 | K5: =SUMIFS(Sales_Data!$AE$2:$AE$3520,Sales_Data!$C$2:$C$3520,">="&Dashboard!$C$5,Sales_Data!$C$2:$C$3520,"<="&Dashboard!$C$6,Sales_Data!$H$2:$H$3520,Dashboard!$C$14,Sales_Data!$I$2:$I$3520,Dashboard!$C$15,Sales_Data!$AE$2:$AE$3520,1) -> 478 | M5: =COUNTIFS(Agent_Summary!$T$5:$T$254,1,Agent_Summary!$K$5:$K$254,">0") -> 138
A6: To Date | C6: 46303 | E6: =E5-(SUMIFS(Sales_Data!$O$2:$O$3520,Sales_Data!$C$2:$C$3520,">="&Dashboard!$C$12,Sales_Data!$C$2:$C$3520,"<="&Dashboard!$C$13,Sales_Data!$H$2:$H$3520,Dashboard!$C$14,Sales_Data!$I$2:$I$3520,Dashboard!$C$15,Sales_Data!$AE$2:$AE$3520,1)) -> 110 | G6: =G5-(SUMIFS(Sales_Data!$M$2:$M$3520,Sales_Data!$C$2:$C$3520,">="&Dashboard!$C$12,Sales_Data!$C$2:$C$3520,"<="&Dashboard!$C$13,Sales_Data!$H$2:$H$3520,Dashboard!$C$14,Sales_Data!$I$2:$I$3520,Dashboard!$C$15,Sales_Data!$AE$2:$AE$3520,1)) -> 23 | I6: =I5-(SUMIFS(Sales_Data!$N$2:$N$3520,Sales_Data!$C$2:$C$3520,">="&Dashboard!$C$12,Sales_Data!$C$2:$C$3520,"<="&Dashboard!$C$13,Sales_Data!$H$2:$H$3520,Dashboard!$C$14,Sales_Data!$I$2:$I$3520,Dashboard!$C$15,Sales_Data!$AE$2:$AE$3520,1)) -> 87 | K6: =K5-(SUMIFS(Sales_Data!$AE$2:$AE$3520,Sales_Data!$C$2:$C$3520,">="&Dashboard!$C$12,Sales_Data!$C$2:$C$3520,"<="&Dashboard!$C$13,Sales_Data!$H$2:$H$3520,Dashboard!$C$14,Sales_Data!$I$2:$I$3520,Dashboard!$C$15,Sales_Data!$AE$2:$AE$3520,1)) -> 70 | M6: =M5-(COUNTIFS(Agent_Summary!$T$5:$T$254,1,Agent_Summary!$N$5:$N$254,">0")) -> 31
A7: Ops Manager | C7: All | E7: vs prior period | G7: vs prior period | I7: vs prior period | K7: vs prior period | M7: vs prior period
A8: Team Leader | C8: All
A9: Exclude Duplicates? | C9: Yes | E9: Units / Active Seller | G9: Participation % (of HC in scope) | I9: XMC Attach % | K9: E-SIM Activation % | M9: Avg Units / Day
A10: Days in Period | C10: =C6-C5+1 -> 7 | E10: =IFERROR(SUMIFS(Sales_Data!$O$2:$O$3520,Sales_Data!$C$2:$C$3520,">="&Dashboard!$C$5,Sales_Data!$C$2:$C$3520,"<="&Dashboard!$C$6,Sales_Data!$H$2:$H$3520,Dashboard!$C$14,Sales_Data!$I$2:$I$3520,Dashboard!$C$15,Sales_Data!$AE$2:$AE$3520,1)/COUNTIFS(Agent_Summary!$T$5:$T$254,1,Agent_Summary!$K$5:$K$254,">0"),0) -> 4.0942029 | G10: =IFERROR(COUNTIFS(Agent_Summary!$T$5:$T$254,1,Agent_Summary!$K$5:$K$254,">0")/COUNTIF(Agent_Summary!$T$5:$T$254,1),0) -> 0.552 | I10: =IFERROR(COUNTIFS(Sales_Data!$C$2:$C$3520,">="&Dashboard!$C$5,Sales_Data!$C$2:$C$3520,"<="&Dashboard!$C$6,Sales_Data!$H$2:$H$3520,Dashboard!$C$14,Sales_Data!$I$2:$I$3520,Dashboard!$C$15,Sales_Data!$AE$2:$AE$3520,1,Sales_Data!$U$2:$U$3520,"Yes")/(COUNTIFS(Sales_Data!$C$2:$C$3520,">="&Dashboard!$C$5,Sales_Data!$C$2:$C$3520,"<="&Dashboard!$C$6,Sales_Data!$H$2:$H$3520,Dashboard!$C$14,Sales_Data!$I$2:$I$3520,Dashboard!$C$15,Sales_Data!$AE$2:$AE$3520,1,Sales_Data!$U$2:$U$3520,"Yes")+COUNTIFS(Sales_Data!$C$2:$C$3520,">="&Dashboard!$C$5,Sales_Data!$C$2:$C$3520,"<="&Dashboard!$C$6,Sales_Data!$H$2:$H$3520,Dashboard!$C$14,Sales_Data!$I$2:$I$3520,Dashboard!$C$15,Sales_Data!$AE$2:$AE$3520,1,Sales_Data!$U$2:$U$3520,"No")),0) -> 0.21969697 | K10: =IFERROR(COUNTIFS(Sales_Data!$C$2:$C$3520,">="&Dashboard!$C$5,Sales_Data!$C$2:$C$3520,"<="&Dashboard!$C$6,Sales_Data!$H$2:$H$3520,Dashboard!$C$14,Sales_Data!$I$2:$I$3520,Dashboard!$C$15,Sales_Data!$AE$2:$AE$3520,1,Sales_Data!$W$2:$W$3520,"Yes")/(COUNTIFS(Sales_Data!$C$2:$C$3520,">="&Dashboard!$C$5,Sales_Data!$C$2:$C$3520,"<="&Dashboard!$C$6,Sales_Data!$H$2:$H$3520,Dashboard!$C$14,Sales_Data!$I$2:$I$3520,Dashboard!$C$15,Sales_Data!$AE$2:$AE$3520,1,Sales_Data!$W$2:$W$3520,"Yes")+COUNTIFS(Sales_Data!$C$2:$C$3520,">="&Dashboard!$C$5,Sales_Data!$C$2:$C$3520,"<="&Dashboard!$C$6,Sales_Data!$H$2:$H$3520,Dashboard!$C$14,Sales_Data!$I$2:$I$3520,Dashboard!$C$15,Sales_Data!$AE$2:$AE$3520,1,Sales_Data!$W$2:$W$3520,"No")),0) -> 0.68 | M10: =IFERROR(SUMIFS(Sales_Data!$O$2:$O$3520,Sales_Data!$C$2:$C$3520,">="&Dashboard!$C$5,Sales_Data!$C$2:$C$3520,"<="&Dashboard!$C$6,Sales_Data!$H$2:$H$3520,Dashboard!$C$14,Sales_Data!$I$2:$I$3520,Dashboard!$C$15,Sales_Data!$AE$2:$AE$3520,1)/Dashboard!$C$10,0) -> 80.714286
A11: Prior Period (same length) | C11: =TEXT(C12,"dd-mmm")&" → "&TEXT(C13,"dd-mmm") -> 25-Sep → 01-Oct | E11: =E10-(IFERROR(SUMIFS(Sales_Data!$O$2:$O$3520,Sales_Data!$C$2:$C$3520,">="&Dashboard!$C$12,Sales_Data!$C$2:$C$3520,"<="&Dashboard!$C$13,Sales_Data!$H$2:$H$3520,Dashboard!$C$14,Sales_Data!$I$2:$I$3520,Dashboard!$C$15,Sales_Data!$AE$2:$AE$3520,1)/COUNTIFS(Agent_Summary!$T$5:$T$254,1,Agent_Summary!$N$5:$N$254,">0"),0)) -> -0.15813355 | G11: =G10-(IFERROR(COUNTIFS(Agent_Summary!$T$5:$T$254,1,Agent_Summary!$N$5:$N$254,">0")/COUNTIF(Agent_Summary!$T$5:$T$254,1),0)) -> 0.124 | I11: =I10-(IFERROR(COUNTIFS(Sales_Data!$C$2:$C$3520,">="&Dashboard!$C$12,Sales_Data!$C$2:$C$3520,"<="&Dashboard!$C$13,Sales_Data!$H$2:$H$3520,Dashboard!$C$14,Sales_Data!$I$2:$I$3520,Dashboard!$C$15,Sales_Data!$AE$2:$AE$3520,1,Sales_Data!$U$2:$U$3520,"Yes")/(COUNTIFS(Sales_Data!$C$2:$C$3520,">="&Dashboard!$C$12,Sales_Data!$C$2:$C$3520,"<="&Dashboard!$C$13,Sales_Data!$H$2:$H$3520,Dashboard!$C$14,Sales_Data!$I$2:$I$3520,Dashboard!$C$15,Sales_Data!$AE$2:$AE$3520,1,Sales_Data!$U$2:$U$3520,"Yes")+COUNTIFS(Sales_Data!$C$2:$C$3520,">="&Dashboard!$C$12,Sales_Data!$C$2:$C$3520,"<="&Dashboard!$C$13,Sales_Data!$H$2:$H$3520,Dashboard!$C$14,Sales_Data!$I$2:$I$3520,Dashboard!$C$15,Sales_Data!$AE$2:$AE$3520,1,Sales_Data!$U$2:$U$3520,"No")),0)) -> 0.071870883 | K11: =K10-(IFERROR(COUNTIFS(Sales_Data!$C$2:$C$3520,">="&Dashboard!$C$12,Sales_Data!$C$2:$C$3520,"<="&Dashboard!$C$13,Sales_Data!$H$2:$H$3520,Dashboard!$C$14,Sales_Data!$I$2:$I$3520,Dashboard!$C$15,Sales_Data!$AE$2:$AE$3520,1,Sales_Data!$W$2:$W$3520,"Yes")/(COUNTIFS(Sales_Data!$C$2:$C$3520,">="&Dashboard!$C$12,Sales_Data!$C$2:$C$3520,"<="&Dashboard!$C$13,Sales_Data!$H$2:$H$3520,Dashboard!$C$14,Sales_Data!$I$2:$I$3520,Dashboard!$C$15,Sales_Data!$AE$2:$AE$3520,1,Sales_Data!$W$2:$W$3520,"Yes")+COUNTIFS(Sales_Data!$C$2:$C$3520,">="&Dashboard!$C$12,Sales_Data!$C$2:$C$3520,"<="&Dashboard!$C$13,Sales_Data!$H$2:$H$3520,Dashboard!$C$14,Sales_Data!$I$2:$I$3520,Dashboard!$C$15,Sales_Data!$AE$2:$AE$3520,1,Sales_Data!$W$2:$W$3520,"No")),0)) -> -0.086990291 | M11: =M10-(IFERROR(SUMIFS(Sales_Data!$O$2:$O$3520,Sales_Data!$C$2:$C$3520,">="&Dashboard!$C$12,Sales_Data!$C$2:$C$3520,"<="&Dashboard!$C$13,Sales_Data!$H$2:$H$3520,Dashboard!$C$14,Sales_Data!$I$2:$I$3520,Dashboard!$C$15,Sales_Data!$AE$2:$AE$3520,1)/Dashboard!$C$10,0)) -> 15.714286
A12: Prior From | C12: =C5-C10 -> 46290 | E12: vs prior period | G12: vs prior period | I12: vs prior period | K12: vs prior period | M12: vs prior period
A13: Prior To | C13: =C5-1 -> 46296
A14: TL criterion | C14: =IF(C8="All","*",C8) -> *
A15: OM criterion | C15: =IF(C7="All","*",C7) -> *
A17: ACCOUNT LEVEL – LAST 8 DAYS DAY-OVER-DAY (whole account, ending at To Date)
A18: Date | B18: Weekday | C18: Submissions | D18: XM Lines | E18: GSR Units | F18: Total Units | G18: DoD Δ | H18: DoD % | I18: 7-Day Avg | J18: WoW % | K18: Active Sellers | L18: Units / Seller | M18: XMC Attach % | N18: E-SIM Act. %
A19: =$C$6-7 -> 46296 | B19: =IFERROR(INDEX(Daily_Account!$B$4:$B$82,MATCH($A19,Daily_Account!$A$4:$A$82,0)),"-") -> Thu | C19: =IFERROR(INDEX(Daily_Account!$C$4:$C$82,MATCH($A19,Daily_Account!$A$4:$A$82,0)),"-") -> 47 | D19: =IFERROR(INDEX(Daily_Account!$D$4:$D$82,MATCH($A19,Daily_Account!$A$4:$A$82,0)),"-") -> 14 | E19: =IFERROR(INDEX(Daily_Account!$E$4:$E$82,MATCH($A19,Daily_Account!$A$4:$A$82,0)),"-") -> 38 | F19: =IFERROR(INDEX(Daily_Account!$F$4:$F$82,MATCH($A19,Daily_Account!$A$4:$A$82,0)),"-") -> 52 | G19: =IFERROR(INDEX(Daily_Account!$G$4:$G$82,MATCH($A19,Daily_Account!$A$4:$A$82,0)),"-") -> -19 | H19: =IFERROR(INDEX(Daily_Account!$H$4:$H$82,MATCH($A19,Daily_Account!$A$4:$A$82,0)),"-") -> -0.26760563 | I19: =IFERROR(INDEX(Daily_Account!$I$4:$I$82,MATCH($A19,Daily_Account!$A$4:$A$82,0)),"-") -> 65 | J19: =IFERROR(INDEX(Daily_Account!$J$4:$J$82,MATCH($A19,Daily_Account!$A$4:$A$82,0)),"-") -> -0.37349398 | K19: =IFERROR(INDEX(Daily_Account!$K$4:$K$82,MATCH($A19,Daily_Account!$A$4:$A$82,0)),"-") -> 28 | L19: =IFERROR(INDEX(Daily_Account!$L$4:$L$82,MATCH($A19,Daily_Account!$A$4:$A$82,0)),"-") -> 1.8571429 | M19: =IFERROR(INDEX(Daily_Account!$O$4:$O$82,MATCH($A19,Daily_Account!$A$4:$A$82,0)),"-") -> 0.15384615 | N19: =IFERROR(INDEX(Daily_Account!$R$4:$R$82,MATCH($A19,Daily_Account!$A$4:$A$82,0)),"-") -> 0.5
A20: =$C$6-6 -> 46297 | B20: =IFERROR(INDEX(Daily_Account!$B$4:$B$82,MATCH($A20,Daily_Account!$A$4:$A$82,0)),"-") -> Fri | C20: =IFERROR(INDEX(Daily_Account!$C$4:$C$82,MATCH($A20,Daily_Account!$A$4:$A$82,0)),"-") -> 52 | D20: =IFERROR(INDEX(Daily_Account!$D$4:$D$82,MATCH($A20,Daily_Account!$A$4:$A$82,0)),"-") -> 14 | E20: =IFERROR(INDEX(Daily_Account!$E$4:$E$82,MATCH($A20,Daily_Account!$A$4:$A$82,0)),"-") -> 45 | F20: =IFERROR(INDEX(Daily_Account!$F$4:$F$82,MATCH($A20,Daily_Account!$A$4:$A$82,0)),"-") -> 59 | G20: =IFERROR(INDEX(Daily_Account!$G$4:$G$82,MATCH($A20,Daily_Account!$A$4:$A$82,0)),"-") -> 7 | H20: =IFERROR(INDEX(Daily_Account!$H$4:$H$82,MATCH($A20,Daily_Account!$A$4:$A$82,0)),"-") -> 0.13461538 | I20: =IFERROR(INDEX(Daily_Account!$I$4:$I$82,MATCH($A20,Daily_Account!$A$4:$A$82,0)),"-") -> 63.571429 | J20: =IFERROR(INDEX(Daily_Account!$J$4:$J$82,MATCH($A20,Daily_Account!$A$4:$A$82,0)),"-") -> -0.14492754 | K20: =IFERROR(INDEX(Daily_Account!$K$4:$K$82,MATCH($A20,Daily_Account!$A$4:$A$82,0)),"-") -> 40 | L20: =IFERROR(INDEX(Daily_Account!$L$4:$L$82,MATCH($A20,Daily_Account!$A$4:$A$82,0)),"-") -> 1.475 | M20: =IFERROR(INDEX(Daily_Account!$O$4:$O$82,MATCH($A20,Daily_Account!$A$4:$A$82,0)),"-") -> 0.071428571 | N20: =IFERROR(INDEX(Daily_Account!$R$4:$R$82,MATCH($A20,Daily_Account!$A$4:$A$82,0)),"-") -> 1
A21: =$C$6-5 -> 46298 | B21: =IFERROR(INDEX(Daily_Account!$B$4:$B$82,MATCH($A21,Daily_Account!$A$4:$A$82,0)),"-") -> Sat | C21: =IFERROR(INDEX(Daily_Account!$C$4:$C$82,MATCH($A21,Daily_Account!$A$4:$A$82,0)),"-") -> 61 | D21: =IFERROR(INDEX(Daily_Account!$D$4:$D$82,MATCH($A21,Daily_Account!$A$4:$A$82,0)),"-") -> 31 | E21: =IFERROR(INDEX(Daily_Account!$E$4:$E$82,MATCH($A21,Daily_Account!$A$4:$A$82,0)),"-") -> 56 | F21: =IFERROR(INDEX(Daily_Account!$F$4:$F$82,MATCH($A21,Daily_Account!$A$4:$A$82,0)),"-") -> 87 | G21: =IFERROR(INDEX(Daily_Account!$G$4:$G$82,MATCH($A21,Daily_Account!$A$4:$A$82,0)),"-") -> 28 | H21: =IFERROR(INDEX(Daily_Account!$H$4:$H$82,MATCH($A21,Daily_Account!$A$4:$A$82,0)),"-") -> 0.47457627 | I21: =IFERROR(INDEX(Daily_Account!$I$4:$I$82,MATCH($A21,Daily_Account!$A$4:$A$82,0)),"-") -> 67.285714 | J21: =IFERROR(INDEX(Daily_Account!$J$4:$J$82,MATCH($A21,Daily_Account!$A$4:$A$82,0)),"-") -> 0.42622951 | K21: =IFERROR(INDEX(Daily_Account!$K$4:$K$82,MATCH($A21,Daily_Account!$A$4:$A$82,0)),"-") -> 33 | L21: =IFERROR(INDEX(Daily_Account!$L$4:$L$82,MATCH($A21,Daily_Account!$A$4:$A$82,0)),"-") -> 2.6363636 | M21: =IFERROR(INDEX(Daily_Account!$O$4:$O$82,MATCH($A21,Daily_Account!$A$4:$A$82,0)),"-") -> 0.33333333 | N21: =IFERROR(INDEX(Daily_Account!$R$4:$R$82,MATCH($A21,Daily_Account!$A$4:$A$82,0)),"-") -> 0.85
A22: =$C$6-4 -> 46299 | B22: =IFERROR(INDEX(Daily_Account!$B$4:$B$82,MATCH($A22,Daily_Account!$A$4:$A$82,0)),"-") -> Sun | C22: =IFERROR(INDEX(Daily_Account!$C$4:$C$82,MATCH($A22,Daily_Account!$A$4:$A$82,0)),"-") -> 43 | D22: =IFERROR(INDEX(Daily_Account!$D$4:$D$82,MATCH($A22,Daily_Account!$A$4:$A$82,0)),"-") -> 15 | E22: =IFERROR(INDEX(Daily_Account!$E$4:$E$82,MATCH($A22,Daily_Account!$A$4:$A$82,0)),"-") -> 34 | F22: =IFERROR(INDEX(Daily_Account!$F$4:$F$82,MATCH($A22,Daily_Account!$A$4:$A$82,0)),"-") -> 49 | G22: =IFERROR(INDEX(Daily_Account!$G$4:$G$82,MATCH($A22,Daily_Account!$A$4:$A$82,0)),"-") -> -38 | H22: =IFERROR(INDEX(Daily_Account!$H$4:$H$82,MATCH($A22,Daily_Account!$A$4:$A$82,0)),"-") -> -0.43678161 | I22: =IFERROR(INDEX(Daily_Account!$I$4:$I$82,MATCH($A22,Daily_Account!$A$4:$A$82,0)),"-") -> 67 | J22: =IFERROR(INDEX(Daily_Account!$J$4:$J$82,MATCH($A22,Daily_Account!$A$4:$A$82,0)),"-") -> -0.039215686 | K22: =IFERROR(INDEX(Daily_Account!$K$4:$K$82,MATCH($A22,Daily_Account!$A$4:$A$82,0)),"-") -> 23 | L22: =IFERROR(INDEX(Daily_Account!$L$4:$L$82,MATCH($A22,Daily_Account!$A$4:$A$82,0)),"-") -> 2.1304348 | M22: =IFERROR(INDEX(Daily_Account!$O$4:$O$82,MATCH($A22,Daily_Account!$A$4:$A$82,0)),"-") -> 0.071428571 | N22: =IFERROR(INDEX(Daily_Account!$R$4:$R$82,MATCH($A22,Daily_Account!$A$4:$A$82,0)),"-") -> 0.83333333
A23: =$C$6-3 -> 46300 | B23: =IFERROR(INDEX(Daily_Account!$B$4:$B$82,MATCH($A23,Daily_Account!$A$4:$A$82,0)),"-") -> Mon | C23: =IFERROR(INDEX(Daily_Account!$C$4:$C$82,MATCH($A23,Daily_Account!$A$4:$A$82,0)),"-") -> 58 | D23: =IFERROR(INDEX(Daily_Account!$D$4:$D$82,MATCH($A23,Daily_Account!$A$4:$A$82,0)),"-") -> 18 | E23: =IFERROR(INDEX(Daily_Account!$E$4:$E$82,MATCH($A23,Daily_Account!$A$4:$A$82,0)),"-") -> 51 | F23: =IFERROR(INDEX(Daily_Account!$F$4:$F$82,MATCH($A23,Daily_Account!$A$4:$A$82,0)),"-") -> 69 | G23: =IFERROR(INDEX(Daily_Account!$G$4:$G$82,MATCH($A23,Daily_Account!$A$4:$A$82,0)),"-") -> 20 | H23: =IFERROR(INDEX(Daily_Account!$H$4:$H$82,MATCH($A23,Daily_Account!$A$4:$A$82,0)),"-") -> 0.40816327 | I23: =IFERROR(INDEX(Daily_Account!$I$4:$I$82,MATCH($A23,Daily_Account!$A$4:$A$82,0)),"-") -> 66.571429 | J23: =IFERROR(INDEX(Daily_Account!$J$4:$J$82,MATCH($A23,Daily_Account!$A$4:$A$82,0)),"-") -> -0.041666667 | K23: =IFERROR(INDEX(Daily_Account!$K$4:$K$82,MATCH($A23,Daily_Account!$A$4:$A$82,0)),"-") -> 40 | L23: =IFERROR(INDEX(Daily_Account!$L$4:$L$82,MATCH($A23,Daily_Account!$A$4:$A$82,0)),"-") -> 1.725 | M23: =IFERROR(INDEX(Daily_Account!$O$4:$O$82,MATCH($A23,Daily_Account!$A$4:$A$82,0)),"-") -> 0.4 | N23: =IFERROR(INDEX(Daily_Account!$R$4:$R$82,MATCH($A23,Daily_Account!$A$4:$A$82,0)),"-") -> 0.73333333
A24: =$C$6-2 -> 46301 | B24: =IFERROR(INDEX(Daily_Account!$B$4:$B$82,MATCH($A24,Daily_Account!$A$4:$A$82,0)),"-") -> Tue | C24: =IFERROR(INDEX(Daily_Account!$C$4:$C$82,MATCH($A24,Daily_Account!$A$4:$A$82,0)),"-") -> 51 | D24: =IFERROR(INDEX(Daily_Account!$D$4:$D$82,MATCH($A24,Daily_Account!$A$4:$A$82,0)),"-") -> 19 | E24: =IFERROR(INDEX(Daily_Account!$E$4:$E$82,MATCH($A24,Daily_Account!$A$4:$A$82,0)),"-") -> 34 | F24: =IFERROR(INDEX(Daily_Account!$F$4:$F$82,MATCH($A24,Daily_Account!$A$4:$A$82,0)),"-") -> 53 | G24: =IFERROR(INDEX(Daily_Account!$G$4:$G$82,MATCH($A24,Daily_Account!$A$4:$A$82,0)),"-") -> -16 | H24: =IFERROR(INDEX(Daily_Account!$H$4:$H$82,MATCH($A24,Daily_Account!$A$4:$A$82,0)),"-") -> -0.23188406 | I24: =IFERROR(INDEX(Daily_Account!$I$4:$I$82,MATCH($A24,Daily_Account!$A$4:$A$82,0)),"-") -> 62.857143 | J24: =IFERROR(INDEX(Daily_Account!$J$4:$J$82,MATCH($A24,Daily_Account!$A$4:$A$82,0)),"-") -> -0.32911392 | K24: =IFERROR(INDEX(Daily_Account!$K$4:$K$82,MATCH($A24,Daily_Account!$A$4:$A$82,0)),"-") -> 38 | L24: =IFERROR(INDEX(Daily_Account!$L$4:$L$82,MATCH($A24,Daily_Account!$A$4:$A$82,0)),"-") -> 1.3947368 | M24: =IFERROR(INDEX(Daily_Account!$O$4:$O$82,MATCH($A24,Daily_Account!$A$4:$A$82,0)),"-") -> 0.10526316 | N24: =IFERROR(INDEX(Daily_Account!$R$4:$R$82,MATCH($A24,Daily_Account!$A$4:$A$82,0)),"-") -> 0.5
A25: =$C$6-1 -> 46302 | B25: =IFERROR(INDEX(Daily_Account!$B$4:$B$82,MATCH($A25,Daily_Account!$A$4:$A$82,0)),"-") -> Wed | C25: =IFERROR(INDEX(Daily_Account!$C$4:$C$82,MATCH($A25,Daily_Account!$A$4:$A$82,0)),"-") -> 108 | D25: =IFERROR(INDEX(Daily_Account!$D$4:$D$82,MATCH($A25,Daily_Account!$A$4:$A$82,0)),"-") -> 28 | E25: =IFERROR(INDEX(Daily_Account!$E$4:$E$82,MATCH($A25,Daily_Account!$A$4:$A$82,0)),"-") -> 97 | F25: =IFERROR(INDEX(Daily_Account!$F$4:$F$82,MATCH($A25,Daily_Account!$A$4:$A$82,0)),"-") -> 125 | G25: =IFERROR(INDEX(Daily_Account!$G$4:$G$82,MATCH($A25,Daily_Account!$A$4:$A$82,0)),"-") -> 72 | H25: =IFERROR(INDEX(Daily_Account!$H$4:$H$82,MATCH($A25,Daily_Account!$A$4:$A$82,0)),"-") -> 1.3584906 | I25: =IFERROR(INDEX(Daily_Account!$I$4:$I$82,MATCH($A25,Daily_Account!$A$4:$A$82,0)),"-") -> 70.571429 | J25: =IFERROR(INDEX(Daily_Account!$J$4:$J$82,MATCH($A25,Daily_Account!$A$4:$A$82,0)),"-") -> 0.76056338 | K25: =IFERROR(INDEX(Daily_Account!$K$4:$K$82,MATCH($A25,Daily_Account!$A$4:$A$82,0)),"-") -> 69 | L25: =IFERROR(INDEX(Daily_Account!$L$4:$L$82,MATCH($A25,Daily_Account!$A$4:$A$82,0)),"-") -> 1.8115942 | M25: =IFERROR(INDEX(Daily_Account!$O$4:$O$82,MATCH($A25,Daily_Account!$A$4:$A$82,0)),"-") -> 0.26923077 | N25: =IFERROR(INDEX(Daily_Account!$R$4:$R$82,MATCH($A25,Daily_Account!$A$4:$A$82,0)),"-") -> 0.57692308
A26: =$C$6-0 -> 46303 | B26: =IFERROR(INDEX(Daily_Account!$B$4:$B$82,MATCH($A26,Daily_Account!$A$4:$A$82,0)),"-") -> Thu | C26: =IFERROR(INDEX(Daily_Account!$C$4:$C$82,MATCH($A26,Daily_Account!$A$4:$A$82,0)),"-") -> 105 | D26: =IFERROR(INDEX(Daily_Account!$D$4:$D$82,MATCH($A26,Daily_Account!$A$4:$A$82,0)),"-") -> 24 | E26: =IFERROR(INDEX(Daily_Account!$E$4:$E$82,MATCH($A26,Daily_Account!$A$4:$A$82,0)),"-") -> 99 | F26: =IFERROR(INDEX(Daily_Account!$F$4:$F$82,MATCH($A26,Daily_Account!$A$4:$A$82,0)),"-") -> 123 | G26: =IFERROR(INDEX(Daily_Account!$G$4:$G$82,MATCH($A26,Daily_Account!$A$4:$A$82,0)),"-") -> -2 | H26: =IFERROR(INDEX(Daily_Account!$H$4:$H$82,MATCH($A26,Daily_Account!$A$4:$A$82,0)),"-") -> -0.016 | I26: =IFERROR(INDEX(Daily_Account!$I$4:$I$82,MATCH($A26,Daily_Account!$A$4:$A$82,0)),"-") -> 80.714286 | J26: =IFERROR(INDEX(Daily_Account!$J$4:$J$82,MATCH($A26,Daily_Account!$A$4:$A$82,0)),"-") -> 1.3653846 | K26: =IFERROR(INDEX(Daily_Account!$K$4:$K$82,MATCH($A26,Daily_Account!$A$4:$A$82,0)),"-") -> 68 | L26: =IFERROR(INDEX(Daily_Account!$L$4:$L$82,MATCH($A26,Daily_Account!$A$4:$A$82,0)),"-") -> 1.8088235 | M26: =IFERROR(INDEX(Daily_Account!$O$4:$O$82,MATCH($A26,Daily_Account!$A$4:$A$82,0)),"-") -> 0.2173913 | N26: =IFERROR(INDEX(Daily_Account!$R$4:$R$82,MATCH($A26,Daily_Account!$A$4:$A$82,0)),"-") -> 0.45454545
A28: LEADER SCORECARD – selected period (Ops Manager filter applies; Team Leader filter ignored here so leaders stay comparable)
A29: Rank | B29: Team Leader | C29: Ops Manager | D29: HC | E29: Submissions | F29: XM Lines | G29: GSR Units | H29: Total Units | I29: Units / HC | J29: Active Sellers | K29: Participation % | L29: Prior Period Units | M29: Δ vs Prior | N29: Δ %
A30: =IF(H30=0,"-",RANK(H30,$H$30:$H$43)) -> 3 | B30: Ahmed Aboelgoud | C30: Ramadan Gamal / Mohamed Radwan | D30: =COUNTIF(Roster!$D$2:$D$251,$B30) -> 23 | E30: =SUMIFS(Sales_Data!$AE$2:$AE$3520,Sales_Data!$C$2:$C$3520,">="&$C$5,Sales_Data!$C$2:$C$3520,"<="&$C$6,Sales_Data!$H$2:$H$3520,$B30,Sales_Data!$I$2:$I$3520,$C$15) -> 67 | F30: =SUMIFS(Sales_Data!$M$2:$M$3520,Sales_Data!$C$2:$C$3520,">="&$C$5,Sales_Data!$C$2:$C$3520,"<="&$C$6,Sales_Data!$H$2:$H$3520,$B30,Sales_Data!$I$2:$I$3520,$C$15,Sales_Data!$AE$2:$AE$3520,1) -> 17 | G30: =SUMIFS(Sales_Data!$N$2:$N$3520,Sales_Data!$C$2:$C$3520,">="&$C$5,Sales_Data!$C$2:$C$3520,"<="&$C$6,Sales_Data!$H$2:$H$3520,$B30,Sales_Data!$I$2:$I$3520,$C$15,Sales_Data!$AE$2:$AE$3520,1) -> 58 | H30: =F30+G30 -> 75 | I30: =IFERROR(H30/D30,0) -> 3.2608696 | J30: =COUNTIFS(Agent_Summary!$C$5:$C$254,$B30,Agent_Summary!$D$5:$D$254,$C$15,Agent_Summary!$K$5:$K$254,">0") -> 18 | K30: =IFERROR(J30/D30,0) -> 0.7826087 | L30: =SUMIFS(Sales_Data!$O$2:$O$3520,Sales_Data!$C$2:$C$3520,">="&$C$12,Sales_Data!$C$2:$C$3520,"<="&$C$13,Sales_Data!$H$2:$H$3520,$B30,Sales_Data!$I$2:$I$3520,$C$15,Sales_Data!$AE$2:$AE$3520,1) -> 78 | M30: =H30-L30 -> -3 | N30: =IF(L30=0,"-",(H30-L30)/L30) -> -0.038461538
A31: =IF(H31=0,"-",RANK(H31,$H$30:$H$43)) -> 7 | B31: Anas Sami | C31: Bishoy Mourad | D31: =COUNTIF(Roster!$D$2:$D$251,$B31) -> 16 | E31: =SUMIFS(Sales_Data!$AE$2:$AE$3520,Sales_Data!$C$2:$C$3520,">="&$C$5,Sales_Data!$C$2:$C$3520,"<="&$C$6,Sales_Data!$H$2:$H$3520,$B31,Sales_Data!$I$2:$I$3520,$C$15) -> 31 | F31: =SUMIFS(Sales_Data!$M$2:$M$3520,Sales_Data!$C$2:$C$3520,">="&$C$5,Sales_Data!$C$2:$C$3520,"<="&$C$6,Sales_Data!$H$2:$H$3520,$B31,Sales_Data!$I$2:$I$3520,$C$15,Sales_Data!$AE$2:$AE$3520,1) -> 8 | G31: =SUMIFS(Sales_Data!$N$2:$N$3520,Sales_Data!$C$2:$C$3520,">="&$C$5,Sales_Data!$C$2:$C$3520,"<="&$C$6,Sales_Data!$H$2:$H$3520,$B31,Sales_Data!$I$2:$I$3520,$C$15,Sales_Data!$AE$2:$AE$3520,1) -> 34 | H31: =F31+G31 -> 42 | I31: =IFERROR(H31/D31,0) -> 2.625 | J31: =COUNTIFS(Agent_Summary!$C$5:$C$254,$B31,Agent_Summary!$D$5:$D$254,$C$15,Agent_Summary!$K$5:$K$254,">0") -> 13 | K31: =IFERROR(J31/D31,0) -> 0.8125 | L31: =SUMIFS(Sales_Data!$O$2:$O$3520,Sales_Data!$C$2:$C$3520,">="&$C$12,Sales_Data!$C$2:$C$3520,"<="&$C$13,Sales_Data!$H$2:$H$3520,$B31,Sales_Data!$I$2:$I$3520,$C$15,Sales_Data!$AE$2:$AE$3520,1) -> 36 | M31: =H31-L31 -> 6 | N31: =IF(L31=0,"-",(H31-L31)/L31) -> 0.16666667
A32: =IF(H32=0,"-",RANK(H32,$H$30:$H$43)) -> 8 | B32: Essam Medhat | C32: Ramadan Gamal | D32: =COUNTIF(Roster!$D$2:$D$251,$B32) -> 13 | E32: =SUMIFS(Sales_Data!$AE$2:$AE$3520,Sales_Data!$C$2:$C$3520,">="&$C$5,Sales_Data!$C$2:$C$3520,"<="&$C$6,Sales_Data!$H$2:$H$3520,$B32,Sales_Data!$I$2:$I$3520,$C$15) -> 25 | F32: =SUMIFS(Sales_Data!$M$2:$M$3520,Sales_Data!$C$2:$C$3520,">="&$C$5,Sales_Data!$C$2:$C$3520,"<="&$C$6,Sales_Data!$H$2:$H$3520,$B32,Sales_Data!$I$2:$I$3520,$C$15,Sales_Data!$AE$2:$AE$3520,1) -> 10 | G32: =SUMIFS(Sales_Data!$N$2:$N$3520,Sales_Data!$C$2:$C$3520,">="&$C$5,Sales_Data!$C$2:$C$3520,"<="&$C$6,Sales_Data!$H$2:$H$3520,$B32,Sales_Data!$I$2:$I$3520,$C$15,Sales_Data!$AE$2:$AE$3520,1) -> 15 | H32: =F32+G32 -> 25 | I32: =IFERROR(H32/D32,0) -> 1.9230769 | J32: =COUNTIFS(Agent_Summary!$C$5:$C$254,$B32,Agent_Summary!$D$5:$D$254,$C$15,Agent_Summary!$K$5:$K$254,">0") -> 11 | K32: =IFERROR(J32/D32,0) -> 0.84615385 | L32: =SUMIFS(Sales_Data!$O$2:$O$3520,Sales_Data!$C$2:$C$3520,">="&$C$12,Sales_Data!$C$2:$C$3520,"<="&$C$13,Sales_Data!$H$2:$H$3520,$B32,Sales_Data!$I$2:$I$3520,$C$15,Sales_Data!$AE$2:$AE$3520,1) -> 23 | M32: =H32-L32 -> 2 | N32: =IF(L32=0,"-",(H32-L32)/L32) -> 0.086956522
A33: =IF(H33=0,"-",RANK(H33,$H$30:$H$43)) -> 11 | B33: Islam Farouk | C33: Ramadan Gamal | D33: =COUNTIF(Roster!$D$2:$D$251,$B33) -> 15 | E33: =SUMIFS(Sales_Data!$AE$2:$AE$3520,Sales_Data!$C$2:$C$3520,">="&$C$5,Sales_Data!$C$2:$C$3520,"<="&$C$6,Sales_Data!$H$2:$H$3520,$B33,Sales_Data!$I$2:$I$3520,$C$15) -> 14 | F33: =SUMIFS(Sales_Data!$M$2:$M$3520,Sales_Data!$C$2:$C$3520,">="&$C$5,Sales_Data!$C$2:$C$3520,"<="&$C$6,Sales_Data!$H$2:$H$3520,$B33,Sales_Data!$I$2:$I$3520,$C$15,Sales_Data!$AE$2:$AE$3520,1) -> 6 | G33: =SUMIFS(Sales_Data!$N$2:$N$3520,Sales_Data!$C$2:$C$3520,">="&$C$5,Sales_Data!$C$2:$C$3520,"<="&$C$6,Sales_Data!$H$2:$H$3520,$B33,Sales_Data!$I$2:$I$3520,$C$15,Sales_Data!$AE$2:$AE$3520,1) -> 10 | H33: =F33+G33 -> 16 | I33: =IFERROR(H33/D33,0) -> 1.0666667 | J33: =COUNTIFS(Agent_Summary!$C$5:$C$254,$B33,Agent_Summary!$D$5:$D$254,$C$15,Agent_Summary!$K$5:$K$254,">0") -> 6 | K33: =IFERROR(J33/D33,0) -> 0.4 | L33: =SUMIFS(Sales_Data!$O$2:$O$3520,Sales_Data!$C$2:$C$3520,">="&$C$12,Sales_Data!$C$2:$C$3520,"<="&$C$13,Sales_Data!$H$2:$H$3520,$B33,Sales_Data!$I$2:$I$3520,$C$15,Sales_Data!$AE$2:$AE$3520,1) -> 3 | M33: =H33-L33 -> 13 | N33: =IF(L33=0,"-",(H33-L33)/L33) -> 4.3333333
A34: =IF(H34=0,"-",RANK(H34,$H$30:$H$43)) -> 8 | B34: Mina Milad | C34: Bishoy Mourad | D34: =COUNTIF(Roster!$D$2:$D$251,$B34) -> 17 | E34: =SUMIFS(Sales_Data!$AE$2:$AE$3520,Sales_Data!$C$2:$C$3520,">="&$C$5,Sales_Data!$C$2:$C$3520,"<="&$C$6,Sales_Data!$H$2:$H$3520,$B34,Sales_Data!$I$2:$I$3520,$C$15) -> 24 | F34: =SUMIFS(Sales_Data!$M$2:$M$3520,Sales_Data!$C$2:$C$3520,">="&$C$5,Sales_Data!$C$2:$C$3520,"<="&$C$6,Sales_Data!$H$2:$H$3520,$B34,Sales_Data!$I$2:$I$3520,$C$15,Sales_Data!$AE$2:$AE$3520,1) -> 6 | G34: =SUMIFS(Sales_Data!$N$2:$N$3520,Sales_Data!$C$2:$C$3520,">="&$C$5,Sales_Data!$C$2:$C$3520,"<="&$C$6,Sales_Data!$H$2:$H$3520,$B34,Sales_Data!$I$2:$I$3520,$C$15,Sales_Data!$AE$2:$AE$3520,1) -> 19 | H34: =F34+G34 -> 25 | I34: =IFERROR(H34/D34,0) -> 1.4705882 | J34: =COUNTIFS(Agent_Summary!$C$5:$C$254,$B34,Agent_Summary!$D$5:$D$254,$C$15,Agent_Summary!$K$5:$K$254,">0") -> 12 | K34: =IFERROR(J34/D34,0) -> 0.70588235 | L34: =SUMIFS(Sales_Data!$O$2:$O$3520,Sales_Data!$C$2:$C$3520,">="&$C$12,Sales_Data!$C$2:$C$3520,"<="&$C$13,Sales_Data!$H$2:$H$3520,$B34,Sales_Data!$I$2:$I$3520,$C$15,Sales_Data!$AE$2:$AE$3520,1) -> 29 | M34: =H34-L34 -> -4 | N34: =IF(L34=0,"-",(H34-L34)/L34) -> -0.13793103
A35: =IF(H35=0,"-",RANK(H35,$H$30:$H$43)) -> 6 | B35: Mohamed Ashour | C35: Bishoy Mourad | D35: =COUNTIF(Roster!$D$2:$D$251,$B35) -> 15 | E35: =SUMIFS(Sales_Data!$AE$2:$AE$3520,Sales_Data!$C$2:$C$3520,">="&$C$5,Sales_Data!$C$2:$C$3520,"<="&$C$6,Sales_Data!$H$2:$H$3520,$B35,Sales_Data!$I$2:$I$3520,$C$15) -> 41 | F35: =SUMIFS(Sales_Data!$M$2:$M$3520,Sales_Data!$C$2:$C$3520,">="&$C$5,Sales_Data!$C$2:$C$3520,"<="&$C$6,Sales_Data!$H$2:$H$3520,$B35,Sales_Data!$I$2:$I$3520,$C$15,Sales_Data!$AE$2:$AE$3520,1) -> 15 | G35: =SUMIFS(Sales_Data!$N$2:$N$3520,Sales_Data!$C$2:$C$3520,">="&$C$5,Sales_Data!$C$2:$C$3520,"<="&$C$6,Sales_Data!$H$2:$H$3520,$B35,Sales_Data!$I$2:$I$3520,$C$15,Sales_Data!$AE$2:$AE$3520,1) -> 32 | H35: =F35+G35 -> 47 | I35: =IFERROR(H35/D35,0) -> 3.1333333 | J35: =COUNTIFS(Agent_Summary!$C$5:$C$254,$B35,Agent_Summary!$D$5:$D$254,$C$15,Agent_Summary!$K$5:$K$254,">0") -> 10 | K35: =IFERROR(J35/D35,0) -> 0.66666667 | L35: =SUMIFS(Sales_Data!$O$2:$O$3520,Sales_Data!$C$2:$C$3520,">="&$C$12,Sales_Data!$C$2:$C$3520,"<="&$C$13,Sales_Data!$H$2:$H$3520,$B35,Sales_Data!$I$2:$I$3520,$C$15,Sales_Data!$AE$2:$AE$3520,1) -> 46 | M35: =H35-L35 -> 1 | N35: =IF(L35=0,"-",(H35-L35)/L35) -> 0.02173913
A36: =IF(H36=0,"-",RANK(H36,$H$30:$H$43)) -> 10 | B36: Mohamed Kelany | C36: Bishoy Mourad | D36: =COUNTIF(Roster!$D$2:$D$251,$B36) -> 18 | E36: =SUMIFS(Sales_Data!$AE$2:$AE$3520,Sales_Data!$C$2:$C$3520,">="&$C$5,Sales_Data!$C$2:$C$3520,"<="&$C$6,Sales_Data!$H$2:$H$3520,$B36,Sales_Data!$I$2:$I$3520,$C$15) -> 17 | F36: =SUMIFS(Sales_Data!$M$2:$M$3520,Sales_Data!$C$2:$C$3520,">="&$C$5,Sales_Data!$C$2:$C$3520,"<="&$C$6,Sales_Data!$H$2:$H$3520,$B36,Sales_Data!$I$2:$I$3520,$C$15,Sales_Data!$AE$2:$AE$3520,1) -> 7 | G36: =SUMIFS(Sales_Data!$N$2:$N$3520,Sales_Data!$C$2:$C$3520,">="&$C$5,Sales_Data!$C$2:$C$3520,"<="&$C$6,Sales_Data!$H$2:$H$3520,$B36,Sales_Data!$I$2:$I$3520,$C$15,Sales_Data!$AE$2:$AE$3520,1) -> 11 | H36: =F36+G36 -> 18 | I36: =IFERROR(H36/D36,0) -> 1 | J36: =COUNTIFS(Agent_Summary!$C$5:$C$254,$B36,Agent_Summary!$D$5:$D$254,$C$15,Agent_Summary!$K$5:$K$254,">0") -> 8 | K36: =IFERROR(J36/D36,0) -> 0.44444444 | L36: =SUMIFS(Sales_Data!$O$2:$O$3520,Sales_Data!$C$2:$C$3520,">="&$C$12,Sales_Data!$C$2:$C$3520,"<="&$C$13,Sales_Data!$H$2:$H$3520,$B36,Sales_Data!$I$2:$I$3520,$C$15,Sales_Data!$AE$2:$AE$3520,1) -> 4 | M36: =H36-L36 -> 14 | N36: =IF(L36=0,"-",(H36-L36)/L36) -> 3.5
A37: =IF(H37=0,"-",RANK(H37,$H$30:$H$43)) -> 12 | B37: Mostafa Mokhtar | C37: Ramadan Gamal | D37: =COUNTIF(Roster!$D$2:$D$251,$B37) -> 19 | E37: =SUMIFS(Sales_Data!$AE$2:$AE$3520,Sales_Data!$C$2:$C$3520,">="&$C$5,Sales_Data!$C$2:$C$3520,"<="&$C$6,Sales_Data!$H$2:$H$3520,$B37,Sales_Data!$I$2:$I$3520,$C$15) -> 9 | F37: =SUMIFS(Sales_Data!$M$2:$M$3520,Sales_Data!$C$2:$C$3520,">="&$C$5,Sales_Data!$C$2:$C$3520,"<="&$C$6,Sales_Data!$H$2:$H$3520,$B37,Sales_Data!$I$2:$I$3520,$C$15,Sales_Data!$AE$2:$AE$3520,1) -> 5 | G37: =SUMIFS(Sales_Data!$N$2:$N$3520,Sales_Data!$C$2:$C$3520,">="&$C$5,Sales_Data!$C$2:$C$3520,"<="&$C$6,Sales_Data!$H$2:$H$3520,$B37,Sales_Data!$I$2:$I$3520,$C$15,Sales_Data!$AE$2:$AE$3520,1) -> 6 | H37: =F37+G37 -> 11 | I37: =IFERROR(H37/D37,0) -> 0.57894737 | J37: =COUNTIFS(Agent_Summary!$C$5:$C$254,$B37,Agent_Summary!$D$5:$D$254,$C$15,Agent_Summary!$K$5:$K$254,">0") -> 5 | K37: =IFERROR(J37/D37,0) -> 0.26315789 | L37: =SUMIFS(Sales_Data!$O$2:$O$3520,Sales_Data!$C$2:$C$3520,">="&$C$12,Sales_Data!$C$2:$C$3520,"<="&$C$13,Sales_Data!$H$2:$H$3520,$B37,Sales_Data!$I$2:$I$3520,$C$15,Sales_Data!$AE$2:$AE$3520,1) -> 0 | M37: =H37-L37 -> 11 | N37: =IF(L37=0,"-",(H37-L37)/L37) -> -
A38: =IF(H38=0,"-",RANK(H38,$H$30:$H$43)) -> 2 | B38: Omar Mansour | C38: Ramadan Gamal | D38: =COUNTIF(Roster!$D$2:$D$251,$B38) -> 18 | E38: =SUMIFS(Sales_Data!$AE$2:$AE$3520,Sales_Data!$C$2:$C$3520,">="&$C$5,Sales_Data!$C$2:$C$3520,"<="&$C$6,Sales_Data!$H$2:$H$3520,$B38,Sales_Data!$I$2:$I$3520,$C$15) -> 65 | F38: =SUMIFS(Sales_Data!$M$2:$M$3520,Sales_Data!$C$2:$C$3520,">="&$C$5,Sales_Data!$C$2:$C$3520,"<="&$C$6,Sales_Data!$H$2:$H$3520,$B38,Sales_Data!$I$2:$I$3520,$C$15,Sales_Data!$AE$2:$AE$3520,1) -> 10 | G38: =SUMIFS(Sales_Data!$N$2:$N$3520,Sales_Data!$C$2:$C$3520,">="&$C$5,Sales_Data!$C$2:$C$3520,"<="&$C$6,Sales_Data!$H$2:$H$3520,$B38,Sales_Data!$I$2:$I$3520,$C$15,Sales_Data!$AE$2:$AE$3520,1) -> 66 | H38: =F38+G38 -> 76 | I38: =IFERROR(H38/D38,0) -> 4.2222222 | J38: =COUNTIFS(Agent_Summary!$C$5:$C$254,$B38,Agent_Summary!$D$5:$D$254,$C$15,Agent_Summary!$K$5:$K$254,">0") -> 16 | K38: =IFERROR(J38/D38,0) -> 0.88888889 | L38: =SUMIFS(Sales_Data!$O$2:$O$3520,Sales_Data!$C$2:$C$3520,">="&$C$12,Sales_Data!$C$2:$C$3520,"<="&$C$13,Sales_Data!$H$2:$H$3520,$B38,Sales_Data!$I$2:$I$3520,$C$15,Sales_Data!$AE$2:$AE$3520,1) -> 28 | M38: =H38-L38 -> 48 | N38: =IF(L38=0,"-",(H38-L38)/L38) -> 1.7142857
A39: =IF(H39=0,"-",RANK(H39,$H$30:$H$43)) -> 13 | B39: Omar Osama | C39: Ramadan Gamal | D39: =COUNTIF(Roster!$D$2:$D$251,$B39) -> 22 | E39: =SUMIFS(Sales_Data!$AE$2:$AE$3520,Sales_Data!$C$2:$C$3520,">="&$C$5,Sales_Data!$C$2:$C$3520,"<="&$C$6,Sales_Data!$H$2:$H$3520,$B39,Sales_Data!$I$2:$I$3520,$C$15) -> 1 | F39: =SUMIFS(Sales_Data!$M$2:$M$3520,Sales_Data!$C$2:$C$3520,">="&$C$5,Sales_Data!$C$2:$C$3520,"<="&$C$6,Sales_Data!$H$2:$H$3520,$B39,Sales_Data!$I$2:$I$3520,$C$15,Sales_Data!$AE$2:$AE$3520,1) -> 0 | G39: =SUMIFS(Sales_Data!$N$2:$N$3520,Sales_Data!$C$2:$C$3520,">="&$C$5,Sales_Data!$C$2:$C$3520,"<="&$C$6,Sales_Data!$H$2:$H$3520,$B39,Sales_Data!$I$2:$I$3520,$C$15,Sales_Data!$AE$2:$AE$3520,1) -> 1 | H39: =F39+G39 -> 1 | I39: =IFERROR(H39/D39,0) -> 0.045454545 | J39: =COUNTIFS(Agent_Summary!$C$5:$C$254,$B39,Agent_Summary!$D$5:$D$254,$C$15,Agent_Summary!$K$5:$K$254,">0") -> 1 | K39: =IFERROR(J39/D39,0) -> 0.045454545 | L39: =SUMIFS(Sales_Data!$O$2:$O$3520,Sales_Data!$C$2:$C$3520,">="&$C$12,Sales_Data!$C$2:$C$3520,"<="&$C$13,Sales_Data!$H$2:$H$3520,$B39,Sales_Data!$I$2:$I$3520,$C$15,Sales_Data!$AE$2:$AE$3520,1) -> 3 | M39: =H39-L39 -> -2 | N39: =IF(L39=0,"-",(H39-L39)/L39) -> -0.66666667
A40: =IF(H40=0,"-",RANK(H40,$H$30:$H$43)) -> 5 | B40: Rahma Samir | C40: Bishoy Mourad | D40: =COUNTIF(Roster!$D$2:$D$251,$B40) -> 22 | E40: =SUMIFS(Sales_Data!$AE$2:$AE$3520,Sales_Data!$C$2:$C$3520,">="&$C$5,Sales_Data!$C$2:$C$3520,"<="&$C$6,Sales_Data!$H$2:$H$3520,$B40,Sales_Data!$I$2:$I$3520,$C$15) -> 43 | F40: =SUMIFS(Sales_Data!$M$2:$M$3520,Sales_Data!$C$2:$C$3520,">="&$C$5,Sales_Data!$C$2:$C$3520,"<="&$C$6,Sales_Data!$H$2:$H$3520,$B40,Sales_Data!$I$2:$I$3520,$C$15,Sales_Data!$AE$2:$AE$3520,1) -> 11 | G40: =SUMIFS(Sales_Data!$N$2:$N$3520,Sales_Data!$C$2:$C$3520,">="&$C$5,Sales_Data!$C$2:$C$3520,"<="&$C$6,Sales_Data!$H$2:$H$3520,$B40,Sales_Data!$I$2:$I$3520,$C$15,Sales_Data!$AE$2:$AE$3520,1) -> 43 | H40: =F40+G40 -> 54 | I40: =IFERROR(H40/D40,0) -> 2.4545455 | J40: =COUNTIFS(Agent_Summary!$C$5:$C$254,$B40,Agent_Summary!$D$5:$D$254,$C$15,Agent_Summary!$K$5:$K$254,">0") -> 13 | K40: =IFERROR(J40/D40,0) -> 0.59090909 | L40: =SUMIFS(Sales_Data!$O$2:$O$3520,Sales_Data!$C$2:$C$3520,">="&$C$12,Sales_Data!$C$2:$C$3520,"<="&$C$13,Sales_Data!$H$2:$H$3520,$B40,Sales_Data!$I$2:$I$3520,$C$15,Sales_Data!$AE$2:$AE$3520,1) -> 31 | M40: =H40-L40 -> 23 | N40: =IF(L40=0,"-",(H40-L40)/L40) -> 0.74193548
A41: =IF(H41=0,"-",RANK(H41,$H$30:$H$43)) -> 1 | B41: Salma Ahmed | C41: Ramadan Gamal | D41: =COUNTIF(Roster!$D$2:$D$251,$B41) -> 17 | E41: =SUMIFS(Sales_Data!$AE$2:$AE$3520,Sales_Data!$C$2:$C$3520,">="&$C$5,Sales_Data!$C$2:$C$3520,"<="&$C$6,Sales_Data!$H$2:$H$3520,$B41,Sales_Data!$I$2:$I$3520,$C$15) -> 61 | F41: =SUMIFS(Sales_Data!$M$2:$M$3520,Sales_Data!$C$2:$C$3520,">="&$C$5,Sales_Data!$C$2:$C$3520,"<="&$C$6,Sales_Data!$H$2:$H$3520,$B41,Sales_Data!$I$2:$I$3520,$C$15,Sales_Data!$AE$2:$AE$3520,1) -> 31 | G41: =SUMIFS(Sales_Data!$N$2:$N$3520,Sales_Data!$C$2:$C$3520,">="&$C$5,Sales_Data!$C$2:$C$3520,"<="&$C$6,Sales_Data!$H$2:$H$3520,$B41,Sales_Data!$I$2:$I$3520,$C$15,Sales_Data!$AE$2:$AE$3520,1) -> 54 | H41: =F41+G41 -> 85 | I41: =IFERROR(H41/D41,0) -> 5 | J41: =COUNTIFS(Agent_Summary!$C$5:$C$254,$B41,Agent_Summary!$D$5:$D$254,$C$15,Agent_Summary!$K$5:$K$254,">0") -> 13 | K41: =IFERROR(J41/D41,0) -> 0.76470588 | L41: =SUMIFS(Sales_Data!$O$2:$O$3520,Sales_Data!$C$2:$C$3520,">="&$C$12,Sales_Data!$C$2:$C$3520,"<="&$C$13,Sales_Data!$H$2:$H$3520,$B41,Sales_Data!$I$2:$I$3520,$C$15,Sales_Data!$AE$2:$AE$3520,1) -> 75 | M41: =H41-L41 -> 10 | N41: =IF(L41=0,"-",(H41-L41)/L41) -> 0.13333333
... A43: =IF(H43=0,"-",RANK(H43,$H$30:$H$43)) -> - | B43: Taher Yehia | C43: Mohamed Radwan | D43: =COUNTIF(Roster!$D$2:$D$251,$B43) -> 19 | E43: =SUMIFS(Sales_Data!$AE$2:$AE$3520,Sales_Data!$C$2:$C$3520,">="&$C$5,Sales_Data!$C$2:$C$3520,"<="&$C$6,Sales_Data!$H$2:$H$3520,$B43,Sales_Data!$I$2:$I$3520,$C$15) -> 0 | F43: =SUMIFS(Sales_Data!$M$2:$M$3520,Sales_Data!$C$2:$C$3520,">="&$C$5,Sales_Data!$C$2:$C$3520,"<="&$C$6,Sales_Data!$H$2:$H$3520,$B43,Sales_Data!$I$2:$I$3520,$C$15,Sales_Data!$AE$2:$AE$3520,1) -> 0 | G43: =SUMIFS(Sales_Data!$N$2:$N$3520,Sales_Data!$C$2:$C$3520,">="&$C$5,Sales_Data!$C$2:$C$3520,"<="&$C$6,Sales_Data!$H$2:$H$3520,$B43,Sales_Data!$I$2:$I$3520,$C$15,Sales_Data!$AE$2:$AE$3520,1) -> 0 | H43: =F43+G43 -> 0 | I43: =IFERROR(H43/D43,0) -> 0 | J43: =COUNTIFS(Agent_Summary!$C$5:$C$254,$B43,Agent_Summary!$D$5:$D$254,$C$15,Agent_Summary!$K$5:$K$254,">0") -> 0 | K43: =IFERROR(J43/D43,0) -> 0 | L43: =SUMIFS(Sales_Data!$O$2:$O$3520,Sales_Data!$C$2:$C$3520,">="&$C$12,Sales_Data!$C$2:$C$3520,"<="&$C$13,Sales_Data!$H$2:$H$3520,$B43,Sales_Data!$I$2:$I$3520,$C$15,Sales_Data!$AE$2:$AE$3520,1) -> 0 | M43: =H43-L43 -> 0 | N43: =IF(L43=0,"-",(H43-L43)/L43) -> -
B44: ACCOUNT TOTAL (roster teams) | D44: =SUM(D30:D43) -> 250 | E44: =SUM(E30:E43) -> 449 | F44: =SUM(F30:F43) -> 140 | G44: =SUM(G30:G43) -> 394 | H44: =SUM(H30:H43) -> 534 | I44: =IFERROR(H44/D44,0) -> 2.136 | J44: =SUM(J30:J43) -> 138 | K44: =IFERROR(J44/D44,0) -> 0.552 | L44: =SUM(L30:L43) -> 432 | M44: =SUM(M30:M43) -> 102 | N44: =IF(L44=0,"-",(H44-L44)/L44) -> 0.23611111
...

Sheet Insights
A1: Insights & Recommendations
A2: Static insights computed from the full tracker history (as of 08 Oct 2026); the live block at the top follows the Dashboard selection.
B4: LIVE – follows the Dashboard selection (dates / Ops Manager / Team Leader)
A5: ● | B5: ="Selected period "&TEXT(Dashboard!$C$5,"dd-mmm")&" to "&TEXT(Dashboard!$C$6,"dd-mmm")&": "&TEXT(Dashboard!E5,"#,##0")&" units ("&TEXT(Dashboard!E6,"+#,##0;-#,##0;0")&" vs prior period), "&TEXT(Dashboard!M5,"#,##0")&" active sellers out of "&COUNTIF(Agent_Summary!$T$5:$T$254,1)&" agents in scope ("&TEXT(Dashboard!G10,"0%")&" participation)." -> Selected period 02-Oct to 08-Oct: 565 units (+110 vs prior period), 138 active sellers out of 250 agents in scope (55% participation).
A6: ● | B6: ="Best leader in the period: "&INDEX(Dashboard!$B$30:$B$43,MATCH(MAX(Dashboard!$H$30:$H$43),Dashboard!$H$30:$H$43,0))&" with "&TEXT(MAX(Dashboard!$H$30:$H$43),"#,##0")&" units ("&TEXT(INDEX(Dashboard!$I$30:$I$43,MATCH(MAX(Dashboard!$H$30:$H$43),Dashboard!$H$30:$H$43,0)),"0.00")&" per head). Lowest: "&INDEX(Dashboard!$B$30:$B$43,MATCH(MIN(Dashboard!$H$30:$H$43),Dashboard!$H$30:$H$43,0))&" with "&TEXT(MIN(Dashboard!$H$30:$H$43),"#,##0")&" units." -> Best leader in the period: Salma Ahmed with 85 units (5.00 per head). Lowest: Taher Yehia with 0 units.
A7: ● | B7: ="Top agent in scope: "&Dashboard!B73&" ("&Dashboard!C73&") with "&TEXT(Dashboard!D73,"#,##0")&" units. Production agents in scope with zero units: "&COUNTIFS(Agent_Summary!$T$5:$T$254,1,Agent_Summary!$E$5:$E$254,"Production",Agent_Summary!$K$5:$K$254,0)&"." -> Top agent in scope: Samuel Wadie Morgan Tawfik (Salma Ahmed) with 32 units. Production agents in scope with zero units: 33.
A8: ● | B8: ="Mix in period: "&TEXT(IFERROR(Dashboard!I5/Dashboard!E5,0),"0%")&" GSR / "&TEXT(IFERROR(Dashboard!G5/Dashboard!E5,0),"0%")&" XM Lines. XMC attach "&TEXT(Dashboard!I10,"0.0%")&" ("&TEXT(Dashboard!I11,"+0.0%;-0.0%")&" vs prior), E-SIM activation "&TEXT(Dashboard!K10,"0.0%")&"." -> Mix in period: 74% GSR / 26% XM Lines. XMC attach 22.0% (+7.2% vs prior), E-SIM activation 68.0%.
B10: 1. ACCOUNT TREND (day-over-day)
A11: • | B11: Volume has stepped up every month: average units per day went Jul 35.9 → Aug 32.1 → Sep 61.2 → Oct 77.1. The tracker started on 22 Jul, so July is a partial month.
A12: • | B12: Last 7 days (02 Oct–08 Oct): 565 units vs 455 the 7 days before (+24%). Peak day so far: Wed 07 Oct with 125 units; 08 Oct closed at 123.
A13: • | B13: Weekday pattern (avg units per day): strongest Monday (55), weakest Sunday (41). Use the Daily_Account WoW % column to compare like-for-like weekdays instead of raw DoD on weekends.
A14: • | B14: Dates in this file are business days: the shift runs 15:00 Cairo to 07:00 the next morning (US hours), so a sale logged at 02:00 on 5 Oct counts toward the 4 Oct business day. Day-over-day figures therefore compare full shifts, not calendar days.
B16: 2. PRODUCT MIX & QUALITY OF SALE
A17: • | B17: GSRs are 72% of all units (2,735) vs XM Lines 28% (1,072). GSR type mix: Speed Upgrade 1,472, X-PRO 740, Adding LOB (Internet-TV) 312, XMC 106, Mobile Plus Plan 98. Speed Upgrade alone is 54% of GSR type counts.
A18: • | B18: XMC attach on XM Line sales is only 14.3% overall (100 of 699 answered) and 15.5% in the last 30 days – the single biggest upsell gap. E-SIM activation on e-SIM sales is 78.8% overall and 75.9% in the last 30 days.
A19: • | B19: Device attach: iPhone 407, Samsung 81, Apple Watch 54, BYOD 37, Motorola 13, iPad 10, Samsung Watch 9. 'Free Line for 1 Year' is the dominant promotion (427 entries).
B21: 3. LEADER LEVEL (last 30 days, units per head so team sizes are comparable)
A22: • | B22: Top 3 leaders by units per head: Salma Ahmed 18.9 (HC 17, participation 88%), Shereen Kamal 16.6 (HC 16, participation 94%), Mohamed Ashour 13.9 (HC 15, participation 87%).
A23: • | B23: Bottom 3 leaders by units per head: Mostafa Mokhtar 0.6 (HC 19, participation 26%), Omar Osama 0.2 (HC 22, participation 14%), Taher Yehia 0.0 (HC 19, participation 0%). Note: teams with Training-phase agents will naturally sit lower – check the Phase column in Agent_Summary before comparing.
A24: • | B24: Biggest 30-day movers vs the prior 30 days – up: Ahmed Aboelgoud +228, Salma Ahmed +157, Mohamed Ashour +156. Down: Rahma Samir -50, Mina Milad -45.
A25: • | B25: Ops Managers (units per head, last 30 days): Bishoy Mourad 9.5 (HC 104), Ramadan Gamal 7.0 (HC 120), Mohamed Radwan 1.1 (HC 26).
A26: • | B26: Tenure effect (units per head, last 30 days): 60-120: 11.8, 120+: 6.3, 30-60: 6.3. Newer agents (30-60 days) are the largest group on the roster – ramp coaching has the biggest leverage.
B28: 4. AGENT LEVEL
A29: • | B29: Output is well spread: the top 10 agents produced 19% of all units in the last 30 days. #1 is Samuel Wadie Morgan Tawfik (Salma Ahmed) with 50 units – 3% of the roster total alone.
A30: • | B30: 11 of 133 Production-phase agents logged zero units in the last 30 days (Rahma Samir: 4, Mina Milad: 2, Mohamed Ashour: 2, Salma Ahmed: 2, Shereen Kamal: 1 …). These are the first names to pull into the Bottom-10 coaching list on the Dashboard.
A31: • | B31: Training-phase agents (117 on roster) already contributed 186 units in the last 30 days – track them separately so early wins are recognised and tracker discipline is built from day one.
B33: 5. DATA QUALITY (fix these to make the numbers trustworthy)
A34: • | B34: 419 entries (12%) carry an HRID that is not on the roster (89 distinct values, 488 units). Most are 9-digit IDs that look valid (likely attrited or transferred agents) – e.g. HRID 100071916 alone has 79 entries. Add these agents to the roster (or a 'Leavers' tab) to attribute them to leaders.
A35: • | B35: 207 entries are exact duplicates (same HRID + account + order number + type) and are excluded by default (toggle on the Dashboard). 507 entries have an unusable order number (e.g. '1', '0', '.', 'N/A', pasted work-order text). Make the Order Number field numeric-only in the Form.
A36: • | B36: The 'Count of GSR' field only exists since 24 Aug; before that GSR units are inferred from the number of GSR types ticked. 8-digit / 10-digit HRID typos were auto-corrected where a unique roster match existed; make HRID a validated 9-digit field in the Form.
B38: 6. RECOMMENDED ACTIONS FOR THE 3 NEWLY-PROMOTED LEADERS
A39: • | B39: Daily (10 min): open Leader_Trend and Daily_Agent with your team selected, read the DoD Δ row and the Rank-in-Team row; message every agent with 0 units by mid-shift and recognise the top mover publicly.
A40: • | B40: Weekly: use the Dashboard with From/To set to the week and Team Leader set to your name – review Participation %, Units / Active Seller and the Bottom-10 list; pair each bottom-10 agent with a top-10 agent for a side-by-side on XMC attach and e-SIM activation.
A41: • | B41: Pitch focus: XMC attach is below 15% – build a one-line XMC offer into every XM Line close; e-SIM activation misses should be followed up the same shift, since an unactivated e-SIM is a sale at risk.
A42: • | B42: Hygiene: every agent submits the form before closing the interaction, HRID copied from the roster, order number from the system – one wrong HRID removes the sale from your scorecard.

Sheet Sales_Data
A1: ID | B1: Completion Time | C1: Business Date | D1: Weekday | E1: HRID (Raw) | F1: HRID (Mapped) | G1: Agent Name | H1: Team Leader | I1: Ops Manager | J1: Phase | K1: Tenure Bucket | L1: Entry Type | M1: XM Lines | N1: GSR Units | O1: Total Units | P1: Speed Upgrade | Q1: X-PRO | R1: Adding LOB | S1: Mobile Plus Plan | T1: XMC (GSR) | U1: Added XMC? | V1: SIM Type | W1: E-SIM Activated? | X1: Device Sold | Y1: Promotion | Z1: Account Number | AA1: Order Number | AB1: Order Valid | AC1: Duplicate Flag | AD1: In Roster | AE1: Include | AF1: Agent-Day First
A2: 1 | B2: 46225.843 | C2: 46225 | D2: Wed | E2: 100071936 | F2: 100071936 | G2: Omar Sayed Mohammed Abdelhamid | H2: Shereen Kamal | I2: Bishoy Mourad | J2: Production | K2: 60-120 | L2: GSRs | M2: 0 | N2: 2 | O2: 2 | P2: 1 | Q2: 1 | R2: 0 | S2: 0 | T2: 0 | Z2: 8499053500233291 | AA2: i don't know | AB2: 0 | AC2: 0 | AD2: 1 | AE2: =IF(AND(Dashboard!$C$9="Yes",AC2=1),0,1) -> 1 | AF2: 1
A3: 2 | B3: 46225.853 | C3: 46225 | D3: Wed | E3: 100049049 | F3: UNMAPPED:100049049 | G3: Not in Roster | H3: Not in Roster | I3: Not in Roster | J3: - | K3: - | L3: XM Lines | M3: 1 | N3: 0 | O3: 1 | P3: 0 | Q3: 0 | R3: 0 | S3: 0 | T3: 0 | Z3: 8773100771535297 | AA3: 3726419292339260853 | AB3: 1 | AC3: 0 | AD3: 0 | AE3: =IF(AND(Dashboard!$C$9="Yes",AC3=1),0,1) -> 1 | AF3: 1
A4: 3 | B4: 46225.911 | C4: 46225 | D4: Wed | E4: 100071351 | F4: 100071351 | G4: Sama Abdelqawy | H4: Mina Milad | I4: Bishoy Mourad | J4: Production | K4: 60-120 | L4: GSRs | M4: 0 | N4: 1 | O4: 1 | P4: 1 | Q4: 0 | R4: 0 | S4: 0 | T4: 0 | Z4: 8535101720179558 | AA4: 1002501601592036 | AB4: 1 | AC4: 0 | AD4: 1 | AE4: =IF(AND(Dashboard!$C$9="Yes",AC4=1),0,1) -> 1 | AF4: 1
A5: 4 | B5: 46225.925 | C5: 46225 | D5: Wed | E5: 100071364 | F5: 100071364 | G5: Omar Elmeniawy | H5: Mina Milad | I5: Bishoy Mourad | J5: Production | K5: 60-120 | L5: GSRs | M5: 0 | N5: 1 | O5: 1 | P5: 0 | Q5: 0 | R5: 1 | S5: 0 | T5: 0 | Z5: 8155400397121334 | AA5: 1002149798172020 | AB5: 1 | AC5: 0 | AD5: 1 | AE5: =IF(AND(Dashboard!$C$9="Yes",AC5=1),0,1) -> 1 | AF5: 1
A6: 5 | B6: 46225.985 | C6: 46225 | D6: Wed | E6: 100071354 | F6: 100071354 | G6: Ehab Elsawah | H6: Mina Milad | I6: Bishoy Mourad | J6: Production | K6: 60-120 | L6: GSRs | M6: 0 | N6: 1 | O6: 1 | P6: 1 | Q6: 0 | R6: 0 | S6: 0 | T6: 0 | Z6: 8299420260228963 | AA6: 1002130695102096 | AB6: 1 | AC6: 0 | AD6: 1 | AE6: =IF(AND(Dashboard!$C$9="Yes",AC6=1),0,1) -> 1 | AF6: 1
A7: 6 | B7: 46225.99 | C7: 46225 | D7: Wed | E7: 100071359 | F7: UNMAPPED:100071359 | G7: Not in Roster | H7: Not in Roster | I7: Not in Roster | J7: - | K7: - | L7: XM Lines | M7: 1 | N7: 0 | O7: 1 | P7: 0 | Q7: 0 | R7: 0 | S7: 0 | T7: 0 | Z7: 8771100820009387 | AA7: 3721673292348439607 | AB7: 1 | AC7: 0 | AD7: 0 | AE7: =IF(AND(Dashboard!$C$9="Yes",AC7=1),0,1) -> 1 | AF7: 1
A8: 7 | B8: 46225.99 | C8: 46225 | D8: Wed | E8: 100071359 | F8: UNMAPPED:100071359 | G8: Not in Roster | H8: Not in Roster | I8: Not in Roster | J8: - | K8: - | L8: XM Lines | M8: 1 | N8: 0 | O8: 1 | P8: 0 | Q8: 0 | R8: 0 | S8: 0 | T8: 0 | Z8: 8771100820009387 | AA8: 3721678292345414436 | AB8: 1 | AC8: 0 | AD8: 0 | AE8: =IF(AND(Dashboard!$C$9="Yes",AC8=1),0,1) -> 1 | AF8: 0
A9: 8 | B9: 46225.992 | C9: 46225 | D9: Wed | E9: 100066493 | F9: 100066493 | G9: Muhammad Gamal Metwally Muhammad Alsharkawy | H9: Salma Ahmed | I9: Ramadan Gamal | J9: Production | K9: 120+ | L9: GSRs | M9: 0 | N9: 1 | O9: 1 | P9: 1 | Q9: 0 | R9: 0 | S9: 0 | T9: 0 | Z9: 8396500034348767 | AA9: 1001306933502104 | AB9: 1 | AC9: 0 | AD9: 1 | AE9: =IF(AND(Dashboard!$C$9="Yes",AC9=1),0,1) -> 1 | AF9: 1
A10: 9 | B10: 46226.008 | C10: 46225 | D10: Wed | E10: 100066493 | F10: 100066493 | G10: Muhammad Gamal Metwally Muhammad Alsharkawy | H10: Salma Ahmed | I10: Ramadan Gamal | J10: Production | K10: 120+ | L10: XM Lines | M10: 1 | N10: 0 | O10: 1 | P10: 0 | Q10: 0 | R10: 0 | S10: 0 | T10: 0 | Z10: 8499100227085924 | AA10: 3726422292352394090 | AB10: 1 | AC10: 0 | AD10: 1 | AE10: =IF(AND(Dashboard!$C$9="Yes",AC10=1),0,1) -> 1 | AF10: 0
A11: 10 | B11: 46226.04 | C11: 46225 | D11: Wed | E11: 100055944 | F11: 100055944 | G11: Mohamed Ahmed | H11: Salma Ahmed | I11: Ramadan Gamal | J11: Production | K11: 120+ | L11: GSRs | M11: 0 | N11: 1 | O11: 1 | P11: 1 | Q11: 0 | R11: 0 | S11: 0 | T11: 0 | Z11: 8155100120019561 | AA11: 187153 | AB11: 1 | AC11: 0 | AD11: 1 | AE11: =IF(AND(Dashboard!$C$9="Yes",AC11=1),0,1) -> 1 | AF11: 1
A12: 11 | B12: 46226.06 | C12: 46225 | D12: Wed | E12: 100071936 | F12: 100071936 | G12: Omar Sayed Mohammed Abdelhamid | H12: Shereen Kamal | I12: Bishoy Mourad | J12: Production | K12: 60-120 | L12: GSRs | M12: 0 | N12: 2 | O12: 2 | P12: 1 | Q12: 1 | R12: 0 | S12: 0 | T12: 0 | Z12: 8778101011898144 | AA12: GETTING STARTED KIT 1001433148142045 ORDERED Created: July 2 | AB12: 0 | AC12: 0 | AD12: 1 | AE12: =IF(AND(Dashboard!$C$9="Yes",AC12=1),0,1) -> 1 | AF12: 0
A13: 12 | B13: 46226.062 | C13: 46225 | D13: Wed | E13: 100070314 | F13: UNMAPPED:100070314 | G13: Not in Roster | H13: Not in Roster | I13: Not in Roster | J13: - | K13: - | L13: GSRs | M13: 0 | N13: 1 | O13: 1 | P13: 1 | Q13: 0 | R13: 0 | S13: 0 | T13: 0 | Z13: 8773402000017562 | AA13: 1001955552352066 | AB13: 1 | AC13: 0 | AD13: 0 | AE13: =IF(AND(Dashboard!$C$9="Yes",AC13=1),0,1) -> 1 | AF13: 1
... A461: 460 | B461: 46239.862 | C461: 46239 | D461: Wed | E461: 100049049 | F461: UNMAPPED:100049049 | G461: Not in Roster | H461: Not in Roster | I461: Not in Roster | J461: - | K461: - | L461: XM Lines | M461: 1 | N461: 0 | O461: 1 | P461: 0 | Q461: 0 | R461: 0 | S461: 0 | T461: 0 | Z461: 8299400121475342 | AA461: 3729618293549797742 | AB461: 1 | AC461: 0 | AD461: 0 | AE461: =IF(AND(Dashboard!$C$9="Yes",AC461=1),0,1) -> 1 | AF461: 1
A462: 461 | B462: 46239.872 | C462: 46239 | D462: Wed | E462: 100075068 | F462: 100075068 | G462: Seif Abdellah | H462: Anas Sami | I462: Bishoy Mourad | J462: Production | K462: 30-60 | L462: GSRs | M462: 0 | N462: 1 | O462: 1 | P462: 0 | Q462: 1 | R462: 0 | S462: 0 | T462: 0 | Z462: 8993116130294339 | AB462: 0 | AC462: 0 | AD462: 1 | AE462: =IF(AND(Dashboard!$C$9="Yes",AC462=1),0,1) -> 1 | AF462: 1
A463: 462 | B463: 46239.901 | C463: 46239 | D463: Wed | E463: 100071352 | F463: 100071352 | G463: Mohamed Hafez | H463: Mina Milad | I463: Bishoy Mourad | J463: Production | K463: 60-120 | L463: GSRs | M463: 0 | N463: 2 | O463: 2 | P463: 1 | Q463: 0 | R463: 1 | S463: 0 | T463: 0 | Z463: 8155500521307780 | AA463: 1002154275862028 | AB463: 1 | AC463: 0 | AD463: 1 | AE463: =IF(AND(Dashboard!$C$9="Yes",AC463=1),0,1) -> 1 | AF463: 1
A464: 463 | B464: 46239.924 | C464: 46239 | D464: Wed | E464: 100071352 | F464: 100071352 | G464: Mohamed Hafez | H464: Mina Milad | I464: Bishoy Mourad | J464: Production | K464: 60-120 | L464: GSRs | M464: 0 | N464: 1 | O464: 1 | P464: 0 | Q464: 0 | R464: 1 | S464: 0 | T464: 0 | Z464: 8155500521307780 | AA464: 1 | AB464: 0 | AC464: 0 | AD464: 1 | AE464: =IF(AND(Dashboard!$C$9="Yes",AC464=1),0,1) -> 1 | AF464: 0
A465: 464 | B465: 46240.006 | C465: 46239 | D465: Wed | E465: 100071356 | F465: 100071356 | G465: Khaled Hassanen | H465: Mina Milad | I465: Bishoy Mourad | J465: Production | K465: 60-120 | L465: XM Lines | M465: 2 | N465: 0 | O465: 2 | P465: 0 | Q465: 0 | R465: 0 | S465: 0 | T465: 0 | Z465: 8535100601773695 | AA465: 3721672293561691210 | AB465: 1 | AC465: 0 | AD465: 1 | AE465: =IF(AND(Dashboard!$C$9="Yes",AC465=1),0,1) -> 1 | AF465: 0
A466: 465 | B466: 46240.016 | C466: 46239 | D466: Wed | E466: 100071916 | F466: UNMAPPED:100071916 | G466: Not in Roster | H466: Not in Roster | I466: Not in Roster | J466: - | K466: - | L466: GSRs | M466: 0 | N466: 1 | O466: 1 | P466: 1 | Q466: 0 | R466: 0 | S466: 0 | T466: 0 | Z466: 8495600011421940 | AA466: 1002506605302035 | AB466: 1 | AC466: 0 | AD466: 0 | AE466: =IF(AND(Dashboard!$C$9="Yes",AC466=1),0,1) -> 1 | AF466: 1
A467: 466 | B467: 46240.03 | C467: 46239 | D467: Wed | E467: 100071936 | F467: 100071936 | G467: Omar Sayed Mohammed Abdelhamid | H467: Shereen Kamal | I467: Bishoy Mourad | J467: Production | K467: 60-120 | L467: GSRs | M467: 0 | N467: 2 | O467: 2 | P467: 1 | Q467: 1 | R467: 0 | S467: 0 | T467: 0 | Z467: 8499100250089884 | AA467: GETTING STARTED KIT 1002136577012097 ORDERED Created: August | AB467: 0 | AC467: 0 | AD467: 1 | AE467: =IF(AND(Dashboard!$C$9="Yes",AC467=1),0,1) -> 1 | AF467: 1
A468: 467 | B468: 46240.032 | C468: 46239 | D468: Wed | E468: 100070307 | F468: 100070307 | G468: Mohamed Abdulghany Mohamed Elshafey | H468: Essam Medhat | I468: Ramadan Gamal | J468: Production | K468: 30-60 | L468: GSRs | M468: 0 | N468: 1 | O468: 1 | P468: 1 | Q468: 0 | R468: 0 | S468: 0 | T468: 0 | Z468: 8535115061139112 | AA468: 1002506615262039 | AB468: 1 | AC468: 0 | AD468: 1 | AE468: =IF(AND(Dashboard!$C$9="Yes",AC468=1),0,1) -> 1 | AF468: 1
A469: 468 | B469: 46240.06 | C469: 46239 | D469: Wed | E469: 100071916 | F469: UNMAPPED:100071916 | G469: Not in Roster | H469: Not in Roster | I469: Not in Roster | J469: - | K469: - | L469: GSRs | M469: 0 | N469: 1 | O469: 1 | P469: 1 | Q469: 0 | R469: 0 | S469: 0 | T469: 0 | Z469: 8495753921257555 | AA469: 1002506628852032 | AB469: 1 | AC469: 0 | AD469: 0 | AE469: =IF(AND(Dashboard!$C$9="Yes",AC469=1),0,1) -> 1 | AF469: 0
A470: 469 | B470: 46240.09 | C470: 46239 | D470: Wed | E470: 100071354 | F470: 100071354 | G470: Ehab Elsawah | H470: Mina Milad | I470: Bishoy Mourad | J470: Production | K470: 60-120 | L470: GSRs | M470: 0 | N470: 1 | O470: 1 | P470: 1 | Q470: 0 | R470: 0 | S470: 0 | T470: 0 | Z470: 8220199130752618 | AA470: 1002315458022074 | AB470: 1 | AC470: 0 | AD470: 1 | AE470: =IF(AND(Dashboard!$C$9="Yes",AC470=1),0,1) -> 1 | AF470: 1
A471: 470 | B471: 46240.092 | C471: 46239 | D471: Wed | E471: 100071916 | F471: UNMAPPED:100071916 | G471: Not in Roster | H471: Not in Roster | I471: Not in Roster | J471: - | K471: - | L471: GSRs | M471: 0 | N471: 1 | O471: 1 | P471: 1 | Q471: 0 | R471: 0 | S471: 0 | T471: 0 | Z471: 8771201670005234 | AA471: 1002299268132051 | AB471: 1 | AC471: 0 | AD471: 0 | AE471: =IF(AND(Dashboard!$C$9="Yes",AC471=1),0,1) -> 1 | AF471: 0
A472: 471 | B472: 46240.092 | C472: 46239 | D472: Wed | E472: 100071916 | F472: UNMAPPED:100071916 | G472: Not in Roster | H472: Not in Roster | I472: Not in Roster | J472: - | K472: - | L472: XM Lines | M472: 1 | N472: 0 | O472: 1 | P472: 0 | Q472: 0 | R472: 0 | S472: 0 | T472: 0 | Z472: 8495600011421940 | AA472: 3729606293564394293 | AB472: 1 | AC472: 0 | AD472: 0 | AE472: =IF(AND(Dashboard!$C$9="Yes",AC472=1),0,1) -> 1 | AF472: 0
A473: 472 | B473: 46240.133 | C473: 46239 | D473: Wed | E473: 100071611 | F473: 100071611 | G473: Shahd Hanfi | H473: Mina Milad | I473: Bishoy Mourad | J473: Production | K473: 60-120 | L473: GSRs | M473: 0 | N473: 1 | O473: 1 | P473: 1 | Q473: 0 | R473: 0 | S473: 0 | T473: 0 | Z473: 8299610370416918 | AA473: 1002136694642099 | AB473: 1 | AC473: 0 | AD473: 1 | AE473: =IF(AND(Dashboard!$C$9="Yes",AC473=1),0,1) -> 1 | AF473: 1
A474: 473 | B474: 46240.148 | C474: 46239 | D474: Wed | E474: 100075068 | F474: 100075068 | G474: Seif Abdellah | H474: Anas Sami | I474: Bishoy Mourad | J474: Production | K474: 30-60 | L474: GSRs | M474: 0 | N474: 1 | O474: 1 | P474: 1 | Q474: 0 | R474: 0 | S474: 0 | T474: 0 | Z474: 8535100190433156 | AA474: nnn | AB474: 0 | AC474: 0 | AD474: 1 | AE474: =IF(AND(Dashboard!$C$9="Yes",AC474=1),0,1) -> 1 | AF474: 0
... A1054: 1053 | B1054: 46262.018 | C1054: 46261 | D1054: Thu | E1054: 100075067 | F1054: 100075067 | G1054: Ahmed Saeed | H1054: Anas Sami | I1054: Bishoy Mourad | J1054: Production | K1054: 30-60 | L1054: GSRs | M1054: 0 | N1054: 1 | O1054: 1 | P1054: 1 | Q1054: 0 | R1054: 0 | S1054: 0 | T1054: 0 | Z1054: 8396522031443169 | AA1054: . | AB1054: 0 | AC1054: 0 | AD1054: 1 | AE1054: =IF(AND(Dashboard!$C$9="Yes",AC1054=1),0,1) -> 1 | AF1054: 0
A1055: 1054 | B1055: 46262.039 | C1055: 46261 | D1055: Thu | E1055: 100075055 | F1055: 100075055 | G1055: Ahmed Mohamed | H1055: Anas Sami | I1055: Bishoy Mourad | J1055: Production | K1055: 30-60 | L1055: XM Lines | M1055: 1 | N1055: 0 | O1055: 1 | P1055: 0 | Q1055: 0 | R1055: 0 | S1055: 0 | T1055: 0 | U1055: No | V1055: E-sim | W1055: Yes | X1055: iPhone | Y1055: Free Line for 1 Year | Z1055: 8396800100118692 | AA1055: 3731226295459644396 | AB1055: 1 | AC1055: 0 | AD1055: 1 | AE1055: =IF(AND(Dashboard!$C$9="Yes",AC1055=1),0,1) -> 1 | AF1055: 1
A1056: 1055 | B1056: 46262.065 | C1056: 46261 | D1056: Thu | E1056: 100066502 | F1056: 100066502 | G1056: Ahmad Abdelftah Hanafy Etman | H1056: Salma Ahmed | I1056: Ramadan Gamal | J1056: Production | K1056: 120+ | L1056: XM Lines | M1056: 1 | N1056: 0 | O1056: 1 | P1056: 0 | Q1056: 0 | R1056: 0 | S1056: 0 | T1056: 0 | Z1056: 8529201210011630 | AA1056: 3729623295467985968 | AB1056: 1 | AC1056: 0 | AD1056: 1 | AE1056: =IF(AND(Dashboard!$C$9="Yes",AC1056=1),0,1) -> 1 | AF1056: 0
A1057: 1056 | B1057: 46262.073 | C1057: 46261 | D1057: Thu | E1057: 100062651 | F1057: 100062651 | G1057: Germen Shohdy | H1057: Rahma Samir | I1057: Bishoy Mourad | J1057: Production | K1057: 120+ | L1057: XM Lines | M1057: 1 | N1057: 0 | O1057: 1 | P1057: 0 | Q1057: 0 | R1057: 0 | S1057: 0 | T1057: 0 | U1057: Yes | V1057: E-sim | W1057: No | X1057: iPhone | Y1057: New Line with no promotions | Z1057: 8777701741289166 | AA1057: 8777701741289166 | AB1057: 1 | AC1057: 0 | AD1057: 1 | AE1057: =IF(AND(Dashboard!$C$9="Yes",AC1057=1),0,1) -> 1 | AF1057: 1
A1058: 1057 | B1058: 46262.075 | C1058: 46261 | D1058: Thu | E1058: 100075057 | F1058: 100075057 | G1058: Mahmoud Mohamed | H1058: Anas Sami | I1058: Bishoy Mourad | J1058: Production | K1058: 30-60 | L1058: GSRs | M1058: 0 | N1058: 5 | O1058: 5 | P1058: 0 | Q1058: 0 | R1058: 0 | S1058: 1 | T1058: 1 | Z1058: 8497202301098500 | AA1058: 202301098500 | AB1058: 1 | AC1058: 0 | AD1058: 1 | AE1058: =IF(AND(Dashboard!$C$9="Yes",AC1058=1),0,1) -> 1 | AF1058: 1
A1059: 1058 | B1059: 46262.076 | C1059: 46261 | D1059: Thu | E1059: 100075057 | F1059: 100075057 | G1059: Mahmoud Mohamed | H1059: Anas Sami | I1059: Bishoy Mourad | J1059: Production | K1059: 30-60 | L1059: XM Lines | M1059: 1 | N1059: 0 | O1059: 1 | P1059: 0 | Q1059: 0 | R1059: 0 | S1059: 0 | T1059: 0 | U1059: Yes | V1059: Physical SIM | X1059: iPad | Y1059: New Line with no promotions | Z1059: 8497202301098500 | AA1059: 11111111111 | AB1059: 1 | AC1059: 0 | AD1059: 1 | AE1059: =IF(AND(Dashboard!$C$9="Yes",AC1059=1),0,1) -> 1 | AF1059: 0
A1060: 1059 | B1060: 46262.087 | C1060: 46261 | D1060: Thu | E1060: 100062650 | F1060: 100062650 | G1060: Mohamed Ashraf Hassan Al-Elemy | H1060: Salma Ahmed | I1060: Ramadan Gamal | J1060: Production | K1060: 120+ | L1060: XM Lines | M1060: 1 | N1060: 0 | O1060: 1 | P1060: 0 | Q1060: 0 | R1060: 0 | S1060: 0 | T1060: 0 | U1060: No | V1060: E-sim | W1060: Yes | X1060: iPhone | Y1060: Free Line for 1 Year | Z1060: 8499100226604006 | AA1060: 357240430108036 | AB1060: 1 | AC1060: 0 | AD1060: 1 | AE1060: =IF(AND(Dashboard!$C$9="Yes",AC1060=1),0,1) -> 1 | AF1060: 1
A1061: 1060 | B1061: 46262.111 | C1061: 46261 | D1061: Thu | E1061: 100075074 | F1061: 100075074 | G1061: Radwa Ahmed | H1061: Anas Sami | I1061: Bishoy Mourad | J1061: Production | K1061: 30-60 | L1061: GSRs | M1061: 0 | N1061: 2 | O1061: 2 | P1061: 1 | Q1061: 1 | R1061: 0 | S1061: 0 | T1061: 0 | Z1061: 8155400530270048 | AA1061: N\A | AB1061: 0 | AC1061: 0 | AD1061: 1 | AE1061: =IF(AND(Dashboard!$C$9="Yes",AC1061=1),0,1) -> 1 | AF1061: 0
A1062: 1061 | B1062: 46262.115 | C1062: 46261 | D1062: Thu | E1062: 100077674 | F1062: 100077674 | G1062: Seif Eldin Maged Saeed Mattar | H1062: Mohamed Ashour | I1062: Bishoy Mourad | J1062: Production | K1062: 60-120 | L1062: GSRs | M1062: 0 | N1062: 1 | O1062: 1 | P1062: 1 | Q1062: 0 | R1062: 0 | S1062: 0 | T1062: 0 | Z1062: 8220160191681120 | AA1062: 1002322579042072 | AB1062: 1 | AC1062: 0 | AD1062: 1 | AE1062: =IF(AND(Dashboard!$C$9="Yes",AC1062=1),0,1) -> 1 | AF1062: 1
A1063: 1062 | B1063: 46262.12 | C1063: 46261 | D1063: Thu | E1063: 100077683 | F1063: 100077683 | G1063: Mahmoud Hamdi Mansour Haridi | H1063: Rahma Samir | I1063: Bishoy Mourad | J1063: Production | K1063: 60-120 | L1063: GSRs | M1063: 0 | N1063: 1 | O1063: 1 | P1063: 1 | Q1063: 0 | R1063: 0 | S1063: 0 | T1063: 0 | Z1063: 8495741235139007 | AA1063: 530490045 | AB1063: 1 | AC1063: 0 | AD1063: 1 | AE1063: =IF(AND(Dashboard!$C$9="Yes",AC1063=1),0,1) -> 1 | AF1063: 1
A1064: 1063 | B1064: 46262.123 | C1064: 46261 | D1064: Thu | E1064: 100075074 | F1064: 100075074 | G1064: Radwa Ahmed | H1064: Anas Sami | I1064: Bishoy Mourad | J1064: Production | K1064: 30-60 | L1064: XM Lines | M1064: 1 | N1064: 0 | O1064: 1 | P1064: 0 | Q1064: 0 | R1064: 0 | S1064: 0 | T1064: 0 | U1064: No | V1064: E-sim | W1064: Yes | X1064: iPhone | Y1064: Free Line for 1 Year | Z1064: 8155400530270048 | AA1064: N\A | AB1064: 0 | AC1064: 0 | AD1064: 1 | AE1064: =IF(AND(Dashboard!$C$9="Yes",AC1064=1),0,1) -> 1 | AF1064: 0
A1065: 1064 | B1065: 46262.194 | C1065: 46261 | D1065: Thu | E1065: 100072759 | F1065: 100072759 | G1065: Abdelrhman Yasser Kamel Nail | H1065: Mohamed Ashour | I1065: Bishoy Mourad | J1065: Production | K1065: 30-60 | L1065: XM Lines | M1065: 1 | N1065: 0 | O1065: 1 | P1065: 0 | Q1065: 0 | R1065: 0 | S1065: 0 | T1065: 0 | Z1065: 8499100570126622 | AA1065: 3729650295478435953 | AB1065: 1 | AC1065: 0 | AD1065: 1 | AE1065: =IF(AND(Dashboard!$C$9="Yes",AC1065=1),0,1) -> 1 | AF1065: 0
